Workbook
Name cellx: #REF!
Name TOTAL_A: #REF!
Name TOTAL_B: #REF!
Name TOTAL_C: #REF!
Name TOTAL_D: #REF!
Name TOTAL_E: #REF!
Name TOTAL_F: #REF!
Name TOTAL_G: #REF!
Name TOTAL_H: #REF!
Name TOTAL_I: #REF!
Name TOTAL_J: #REF!
Name TOTAL_K: #REF!
Name TOTAL_L: #REF!

Sheet Boreholes
A1: Hole Number | B1: Type of drilling | C1: Over Barrier/ Wall/ Fence | D1: Slope > 20% | E1: Scheduled | F1: Total Schedule Depth | G1: Tests P/S/EV | H1: Total Depth | I1: CP Completed | K1: CP Drilling Total Depth | L1: START | M1: END | N1: 0-10 | O1: 10 to 20 | P1: 20-30 | Q1: 30-40 | T1: Rotary Drilling WITH CORE in HARD strata | U1: START | V1: END | W1: 0-10 | X1: 10 to 20 | Y1: 20-30 | Z1: 30-40 | AB1: RC Completed | AD1: Rotary Drilling WITHOUT CORE in HARD strata | AE1: START | AF1: END | AG1: 0-10 | AH1: 10 to 20 | AI1: 20-30 | AJ1: 30-40 | AL1: RC Completed | AN1: Rotary Drilling WITH CORE in SOFT strata | AO1: START | AP1: END | AQ1: 0-10 | AR1: 10 to 20 | AS1: 20-30 | AT1: 30-40 | AV1: RC Completed | AX1: Rotary Drilling WITHOUT CORE in SOFT strata | AY1: START | AZ1: END | BA1: 0-10 | BB1: 10 to 20 | BC1: 20-30 | BD1: 30-40 | BF1: RC Completed | BH1: ROAD | BI1: Pizezometer | BJ1: Plain Depth (m) | BL1: Standpipe (mm) | BM1: Plain Depth (m) | BN1: Slotted Depth (m) | BP1: PIE/SP Complete | BR1: Draft Log Received CP/RC or N/A | BT1: Log Comments Sent CP/RC | BU1: Lab Schedule Received CP/RC or N/A | BW1: Lab Schedule Sent CP/RC or N/A
E2: =IF(A2= "","",1) | I2: =IF(K2>0, 1, 0) -> 0 | N2: =IF(AND(L2<=10,M2<=10),M2-L2,MAX(0,10-L2)) -> 0 | O2: =IF(AND(L2<=10,M2>=20),10,IF(AND(L2>=10,M2<=20),M2-L2,IF(AND(L2<=10,M2<=20,M2>=10),M2-10,IF(AND(L2>=10,M2>=20),MAX(0,20-L2),0)))) -> 0 | P2: =IF(AND(L2<=20,M2>=30),10,IF(AND(L2>=20,M2<=30),M2-L2,IF(AND(L2<=20,M2<=30,M2>=20),M2-20,IF(AND(L2>=20,M2>=30),30-L2,0)))) -> 0 | Q2: =IF(AND(L2<=30,M2>=40),10,IF(AND(L2>=30,M2<=40),M2-L2,IF(AND(L2<=30,M2<=40,M2>=30),M2-30,IF(AND(L2>=30,M2>=40),40-L2,0)))) -> 0 | W2: =IF(AND(U2<=10,V2<=10),V2-U2,MAX(0,10-U2)) -> 0 | X2: =IF(AND(U2<=10,V2>=20),10,IF(AND(U2>=10,V2<=20),V2-U2,IF(AND(U2<=10,V2<=20,V2>=10),V2-10,IF(AND(U2>=10,V2>=20),MAX(0,20-U2),0)))) -> 0 | Y2: =IF(AND(U2<=20,V2>=30),10,IF(AND(U2>=20,V2<=30),V2-U2,IF(AND(U2<=20,V2<=30,V2>=20),V2-20,IF(AND(U2>=20,V2>=30),MAX(0,30-U2),0)))) -> 0 | Z2: =IF(AND(U2<=30,V2>=40),10,IF(AND(U2>=30,V2<=40),V2-U2,IF(AND(U2<=30,V2<=40,V2>=30),V2-30,IF(AND(U2>=30,V2>=40),40-U2,0)))) -> 0 | AB2: =IF(T2>0, 1, 0) -> 0 | AG2: =IF(AND(AE2<=10,AF2<=10),AF2-AE2,MAX(0,10-AE2)) -> 0 | AH2: =IF(AND(AE2<=10,AF2>=20),10,IF(AND(AE2>=10,AF2<=20),AF2-AE2,IF(AND(AE2<=10,AF2<=20,AF2>=10),AF2-10,IF(AND(AE2>=10,AF2>=20),MAX(0,20-AE2),0)))) -> 0 | AI2: =IF(AND(AE2<=20,AF2>=30),10,IF(AND(AE2>=20,AF2<=30),AF2-AE2,IF(AND(AE2<=20,AF2<=30,AF2>=20),AF2-20,IF(AND(AE2>=20,AF2>=30),MAX(0,30-AE2),0)))) -> 0 | AJ2: =IF(AND(AE2<=30,AF2>=40),10,IF(AND(AE2>=30,AF2<=40),AF2-AE2,IF(AND(AE2<=30,AF2<=40,AF2>=30),AF2-30,IF(AND(AE2>=30,AF2>=40),40-AE2,0)))) -> 0 | AL2: =IF(AD2>0, 1, 0) -> 0 | AQ2: =IF(AND(AO2<=10,AP2<=10),AP2-AO2,MAX(0,10-AO2)) -> 0 | AR2: =IF(AND(AO2<=10,AP2>=20),10,IF(AND(AO2>=10,AP2<=20),AP2-AO2,IF(AND(AO2<=10,AP2<=20,AP2>=10),AP2-10,IF(AND(AO2>=10,AP2>=20),MAX(0,20-AO2),0)))) -> 0 | AS2: =IF(AND(AO2<=20,AP2>=30),10,IF(AND(AO2>=20,AP2<=30),AP2-AO2,IF(AND(AO2<=20,AP2<=30,AP2>=20),AP2-20,IF(AND(AO2>=20,AP2>=30),MAX(0,30-AO2),0)))) -> 0 | AT2: =IF(AND(AO2<=30,AP2>=40),10,IF(AND(AO2>=30,AP2<=40),AP2-AO2,IF(AND(AO2<=30,AP2<=40,AP2>=30),AP2-30,IF(AND(AO2>=30,AP2>=40),40-AO2,0)))) -> 0 | AV2: =IF(AN2>0, 1, 0) -> 0 | BA2: =IF(AND(AY2<=10,AZ2<=10),AZ2-AY2,MAX(0,10-AY2)) -> 0 | BB2: =IF(AND(AY2<=10,AZ2>=20),10,IF(AND(AY2>=10,AZ2<=20),AZ2-AY2,IF(AND(AY2<=10,AZ2<=20,AZ2>=10),AZ2-10,IF(AND(AY2>=10,AZ2>=20),MAX(0,20-AY2),0)))) -> 0 | BC2: =IF(AND(AY2<=20,AZ2>=30),10,IF(AND(AY2>=20,AZ2<=30),AZ2-AY2,IF(AND(AY2<=20,AZ2<=30,AZ2>=20),AZ2-20,IF(AND(AY2>=20,AZ2>=30),MAX(0,30-AY2),0)))) -> 0 | BD2: =IF(AND(AY2<=30,AZ2>=40),10,IF(AND(AY2>=30,AZ2<=40),AZ2-AY2,IF(AND(AY2<=30,AZ2<=40,AZ2>=30),AZ2-30,IF(AND(AY2>=30,AZ2>=40),40-AY2,0)))) -> 0 | BF2: =IF(AX2>0, 1, 0) -> 0 | BP2: =IF(OR(BI2="YES",BL2="YES"), 1, 0) -> 0
E3: =IF(A3= "","",1) | I3: =IF(K3>0, 1, 0) -> 0 | N3: =IF(AND(L3<=10,M3<=10),M3-L3,MAX(0,10-L3)) -> 0 | O3: =IF(AND(L3<=10,M3>=20),10,IF(AND(L3>=10,M3<=20),M3-L3,IF(AND(L3<=10,M3<=20,M3>=10),M3-10,IF(AND(L3>=10,M3>=20),MAX(0,20-L3),0)))) -> 0 | P3: =IF(AND(L3<=20,M3>=30),10,IF(AND(L3>=20,M3<=30),M3-L3,IF(AND(L3<=20,M3<=30,M3>=20),M3-20,IF(AND(L3>=20,M3>=30),30-L3,0)))) -> 0 | Q3: =IF(AND(L3<=30,M3>=40),10,IF(AND(L3>=30,M3<=40),M3-L3,IF(AND(L3<=30,M3<=40,M3>=30),M3-30,IF(AND(L3>=30,M3>=40),40-L3,0)))) -> 0 | W3: =IF(AND(U3<=10,V3<=10),V3-U3,MAX(0,10-U3)) -> 0 | X3: =IF(AND(U3<=10,V3>=20),10,IF(AND(U3>=10,V3<=20),V3-U3,IF(AND(U3<=10,V3<=20,V3>=10),V3-10,IF(AND(U3>=10,V3>=20),MAX(0,20-U3),0)))) -> 0 | Y3: =IF(AND(U3<=20,V3>=30),10,IF(AND(U3>=20,V3<=30),V3-U3,IF(AND(U3<=20,V3<=30,V3>=20),V3-20,IF(AND(U3>=20,V3>=30),30-U3,0)))) -> 0 | Z3: =IF(AND(U3<=30,V3>=40),10,IF(AND(U3>=30,V3<=40),V3-U3,IF(AND(U3<=30,V3<=40,V3>=30),V3-30,IF(AND(U3>=30,V3>=40),40-U3,0)))) -> 0 | AB3: =IF(T3>0, 1, 0) -> 0 | AG3: =IF(AND(AE3<=10,AF3<=10),AF3-AE3,MAX(0,10-AE3)) -> 0 | AH3: =IF(AND(AE3<=10,AF3>=20),10,IF(AND(AE3>=10,AF3<=20),AF3-AE3,IF(AND(AE3<=10,AF3<=20,AF3>=10),AF3-10,IF(AND(AE3>=10,AF3>=20),MAX(0,20-AE3),0)))) -> 0 | AI3: =IF(AND(AE3<=20,AF3>=30),10,IF(AND(AE3>=20,AF3<=30),AF3-AE3,IF(AND(AE3<=20,AF3<=30,AF3>=20),AF3-20,IF(AND(AE3>=20,AF3>=30),30-AE3,0)))) -> 0 | AJ3: =IF(AND(AE3<=30,AF3>=40),10,IF(AND(AE3>=30,AF3<=40),AF3-AE3,IF(AND(AE3<=30,AF3<=40,AF3>=30),AF3-30,IF(AND(AE3>=30,AF3>=40),40-AE3,0)))) -> 0 | AL3: =IF(AD3>0, 1, 0) -> 0 | AQ3: =IF(AND(AO3<=10,AP3<=10),AP3-AO3,MAX(0,10-AO3)) -> 0 | AR3: =IF(AND(AO3<=10,AP3>=20),10,IF(AND(AO3>=10,AP3<=20),AP3-AO3,IF(AND(AO3<=10,AP3<=20,AP3>=10),AP3-10,IF(AND(AO3>=10,AP3>=20),MAX(0,20-AO3),0)))) -> 0 | AS3: =IF(AND(AO3<=20,AP3>=30),10,IF(AND(AO3>=20,AP3<=30),AP3-AO3,IF(AND(AO3<=20,AP3<=30,AP3>=20),AP3-20,IF(AND(AO3>=20,AP3>=30),30-AO3,0)))) -> 0 | AT3: =IF(AND(AO3<=30,AP3>=40),10,IF(AND(AO3>=30,AP3<=40),AP3-AO3,IF(AND(AO3<=30,AP3<=40,AP3>=30),AP3-30,IF(AND(AO3>=30,AP3>=40),40-AO3,0)))) -> 0 | AV3: =IF(AN3>0, 1, 0) -> 0 | BA3: =IF(AND(AY3<=10,AZ3<=10),AZ3-AY3,MAX(0,10-AY3)) -> 0 | BB3: =IF(AND(AY3<=10,AZ3>=20),10,IF(AND(AY3>=10,AZ3<=20),AZ3-AY3,IF(AND(AY3<=10,AZ3<=20,AZ3>=10),AZ3-10,IF(AND(AY3>=10,AZ3>=20),MAX(0,20-AY3),0)))) -> 0 | BC3: =IF(AND(AY3<=20,AZ3>=30),10,IF(AND(AY3>=20,AZ3<=30),AZ3-AY3,IF(AND(AY3<=20,AZ3<=30,AZ3>=20),AZ3-20,IF(AND(AY3>=20,AZ3>=30),30-AY3,0)))) -> 0 | BD3: =IF(AND(AY3<=30,AZ3>=40),10,IF(AND(AY3>=30,AZ3<=40),AZ3-AY3,IF(AND(AY3<=30,AZ3<=40,AZ3>=30),AZ3-30,IF(AND(AY3>=30,AZ3>=40),40-AY3,0)))) -> 0 | BF3: =IF(AX3>0, 1, 0) -> 0 | BP3: =IF(OR(BI3="YES",BL3="YES"), 1, 0) -> 0
E4: =IF(A4= "","",1) | I4: =IF(K4>0, 1, 0) -> 0 | N4: =IF(AND(L4<=10,M4<=10),M4-L4,MAX(0,10-L4)) -> 0 | O4: =IF(AND(L4<=10,M4>=20),10,IF(AND(L4>=10,M4<=20),M4-L4,IF(AND(L4<=10,M4<=20,M4>=10),M4-10,IF(AND(L4>=10,M4>=20),MAX(0,20-L4),0)))) -> 0 | P4: =IF(AND(L4<=20,M4>=30),10,IF(AND(L4>=20,M4<=30),M4-L4,IF(AND(L4<=20,M4<=30,M4>=20),M4-20,IF(AND(L4>=20,M4>=30),30-L4,0)))) -> 0 | Q4: =IF(AND(L4<=30,M4>=40),10,IF(AND(L4>=30,M4<=40),M4-L4,IF(AND(L4<=30,M4<=40,M4>=30),M4-30,IF(AND(L4>=30,M4>=40),40-L4,0)))) -> 0 | W4: =IF(AND(U4<=10,V4<=10),V4-U4,MAX(0,10-U4)) -> 0 | X4: =IF(AND(U4<=10,V4>=20),10,IF(AND(U4>=10,V4<=20),V4-U4,IF(AND(U4<=10,V4<=20,V4>=10),V4-10,IF(AND(U4>=10,V4>=20),MAX(0,20-U4),0)))) -> 0 | Y4: =IF(AND(U4<=20,V4>=30),10,IF(AND(U4>=20,V4<=30),V4-U4,IF(AND(U4<=20,V4<=30,V4>=20),V4-20,IF(AND(U4>=20,V4>=30),30-U4,0)))) -> 0 | Z4: =IF(AND(U4<=30,V4>=40),10,IF(AND(U4>=30,V4<=40),V4-U4,IF(AND(U4<=30,V4<=40,V4>=30),V4-30,IF(AND(U4>=30,V4>=40),40-U4,0)))) -> 0 | AB4: =IF(T4>0, 1, 0) -> 0 | AG4: =IF(AND(AE4<=10,AF4<=10),AF4-AE4,MAX(0,10-AE4)) -> 0 | AH4: =IF(AND(AE4<=10,AF4>=20),10,IF(AND(AE4>=10,AF4<=20),AF4-AE4,IF(AND(AE4<=10,AF4<=20,AF4>=10),AF4-10,IF(AND(AE4>=10,AF4>=20),MAX(0,20-AE4),0)))) -> 0 | AI4: =IF(AND(AE4<=20,AF4>=30),10,IF(AND(AE4>=20,AF4<=30),AF4-AE4,IF(AND(AE4<=20,AF4<=30,AF4>=20),AF4-20,IF(AND(AE4>=20,AF4>=30),30-AE4,0)))) -> 0 | AJ4: =IF(AND(AE4<=30,AF4>=40),10,IF(AND(AE4>=30,AF4<=40),AF4-AE4,IF(AND(AE4<=30,AF4<=40,AF4>=30),AF4-30,IF(AND(AE4>=30,AF4>=40),40-AE4,0)))) -> 0 | AL4: =IF(AD4>0, 1, 0) -> 0 | AQ4: =IF(AND(AO4<=10,AP4<=10),AP4-AO4,MAX(0,10-AO4)) -> 0 | AR4: =IF(AND(AO4<=10,AP4>=20),10,IF(AND(AO4>=10,AP4<=20),AP4-AO4,IF(AND(AO4<=10,AP4<=20,AP4>=10),AP4-10,IF(AND(AO4>=10,AP4>=20),MAX(0,20-AO4),0)))) -> 0 | AS4: =IF(AND(AO4<=20,AP4>=30),10,IF(AND(AO4>=20,AP4<=30),AP4-AO4,IF(AND(AO4<=20,AP4<=30,AP4>=20),AP4-20,IF(AND(AO4>=20,AP4>=30),30-AO4,0)))) -> 0 | AT4: =IF(AND(AO4<=30,AP4>=40),10,IF(AND(AO4>=30,AP4<=40),AP4-AO4,IF(AND(AO4<=30,AP4<=40,AP4>=30),AP4-30,IF(AND(AO4>=30,AP4>=40),40-AO4,0)))) -> 0 | AV4: =IF(AN4>0, 1, 0) -> 0 | BA4: =IF(AND(AY4<=10,AZ4<=10),AZ4-AY4,MAX(0,10-AY4)) -> 0 | BB4: =IF(AND(AY4<=10,AZ4>=20),10,IF(AND(AY4>=10,AZ4<=20),AZ4-AY4,IF(AND(AY4<=10,AZ4<=20,AZ4>=10),AZ4-10,IF(AND(AY4>=10,AZ4>=20),MAX(0,20-AY4),0)))) -> 0 | BC4: =IF(AND(AY4<=20,AZ4>=30),10,IF(AND(AY4>=20,AZ4<=30),AZ4-AY4,IF(AND(AY4<=20,AZ4<=30,AZ4>=20),AZ4-20,IF(AND(AY4>=20,AZ4>=30),30-AY4,0)))) -> 0 | BD4: =IF(AND(AY4<=30,AZ4>=40),10,IF(AND(AY4>=30,AZ4<=40),AZ4-AY4,IF(AND(AY4<=30,AZ4<=40,AZ4>=30),AZ4-30,IF(AND(AY4>=30,AZ4>=40),40-AY4,0)))) -> 0 | BF4: =IF(AX4>0, 1, 0) -> 0 | BP4: =IF(OR(BI4="YES",BL4="YES"), 1, 0) -> 0
E5: =IF(A5= "","",1) | I5: =IF(K5>0, 1, 0) -> 0 | N5: =IF(AND(L5<=10,M5<=10),M5-L5,MAX(0,10-L5)) -> 0 | O5: =IF(AND(L5<=10,M5>=20),10,IF(AND(L5>=10,M5<=20),M5-L5,IF(AND(L5<=10,M5<=20,M5>=10),M5-10,IF(AND(L5>=10,M5>=20),MAX(0,20-L5),0)))) -> 0 | P5: =IF(AND(L5<=20,M5>=30),10,IF(AND(L5>=20,M5<=30),M5-L5,IF(AND(L5<=20,M5<=30,M5>=20),M5-20,IF(AND(L5>=20,M5>=30),30-L5,0)))) -> 0 | Q5: =IF(AND(L5<=30,M5>=40),10,IF(AND(L5>=30,M5<=40),M5-L5,IF(AND(L5<=30,M5<=40,M5>=30),M5-30,IF(AND(L5>=30,M5>=40),40-L5,0)))) -> 0 | W5: =IF(AND(U5<=10,V5<=10),V5-U5,MAX(0,10-U5)) -> 0 | X5: =IF(AND(U5<=10,V5>=20),10,IF(AND(U5>=10,V5<=20),V5-U5,IF(AND(U5<=10,V5<=20,V5>=10),V5-10,IF(AND(U5>=10,V5>=20),MAX(0,20-U5),0)))) -> 0 | Y5: =IF(AND(U5<=20,V5>=30),10,IF(AND(U5>=20,V5<=30),V5-U5,IF(AND(U5<=20,V5<=30,V5>=20),V5-20,IF(AND(U5>=20,V5>=30),30-U5,0)))) -> 0 | Z5: =IF(AND(U5<=30,V5>=40),10,IF(AND(U5>=30,V5<=40),V5-U5,IF(AND(U5<=30,V5<=40,V5>=30),V5-30,IF(AND(U5>=30,V5>=40),40-U5,0)))) -> 0 | AB5: =IF(T5>0, 1, 0) -> 0 | AG5: =IF(AND(AE5<=10,AF5<=10),AF5-AE5,MAX(0,10-AE5)) -> 0 | AH5: =IF(AND(AE5<=10,AF5>=20),10,IF(AND(AE5>=10,AF5<=20),AF5-AE5,IF(AND(AE5<=10,AF5<=20,AF5>=10),AF5-10,IF(AND(AE5>=10,AF5>=20),MAX(0,20-AE5),0)))) -> 0 | AI5: =IF(AND(AE5<=20,AF5>=30),10,IF(AND(AE5>=20,AF5<=30),AF5-AE5,IF(AND(AE5<=20,AF5<=30,AF5>=20),AF5-20,IF(AND(AE5>=20,AF5>=30),30-AE5,0)))) -> 0 | AJ5: =IF(AND(AE5<=30,AF5>=40),10,IF(AND(AE5>=30,AF5<=40),AF5-AE5,IF(AND(AE5<=30,AF5<=40,AF5>=30),AF5-30,IF(AND(AE5>=30,AF5>=40),40-AE5,0)))) -> 0 | AL5: =IF(AD5>0, 1, 0) -> 0 | AQ5: =IF(AND(AO5<=10,AP5<=10),AP5-AO5,MAX(0,10-AO5)) -> 0 | AR5: =IF(AND(AO5<=10,AP5>=20),10,IF(AND(AO5>=10,AP5<=20),AP5-AO5,IF(AND(AO5<=10,AP5<=20,AP5>=10),AP5-10,IF(AND(AO5>=10,AP5>=20),MAX(0,20-AO5),0)))) -> 0 | AS5: =IF(AND(AO5<=20,AP5>=30),10,IF(AND(AO5>=20,AP5<=30),AP5-AO5,IF(AND(AO5<=20,AP5<=30,AP5>=20),AP5-20,IF(AND(AO5>=20,AP5>=30),30-AO5,0)))) -> 0 | AT5: =IF(AND(AO5<=30,AP5>=40),10,IF(AND(AO5>=30,AP5<=40),AP5-AO5,IF(AND(AO5<=30,AP5<=40,AP5>=30),AP5-30,IF(AND(AO5>=30,AP5>=40),40-AO5,0)))) -> 0 | AV5: =IF(AN5>0, 1, 0) -> 0 | BA5: =IF(AND(AY5<=10,AZ5<=10),AZ5-AY5,MAX(0,10-AY5)) -> 0 | BB5: =IF(AND(AY5<=10,AZ5>=20),10,IF(AND(AY5>=10,AZ5<=20),AZ5-AY5,IF(AND(AY5<=10,AZ5<=20,AZ5>=10),AZ5-10,IF(AND(AY5>=10,AZ5>=20),MAX(0,20-AY5),0)))) -> 0 | BC5: =IF(AND(AY5<=20,AZ5>=30),10,IF(AND(AY5>=20,AZ5<=30),AZ5-AY5,IF(AND(AY5<=20,AZ5<=30,AZ5>=20),AZ5-20,IF(AND(AY5>=20,AZ5>=30),30-AY5,0)))) -> 0 | BD5: =IF(AND(AY5<=30,AZ5>=40),10,IF(AND(AY5>=30,AZ5<=40),AZ5-AY5,IF(AND(AY5<=30,AZ5<=40,AZ5>=30),AZ5-30,IF(AND(AY5>=30,AZ5>=40),40-AY5,0)))) -> 0 | BF5: =IF(AX5>0, 1, 0) -> 0 | BP5: =IF(OR(BI5="YES",BL5="YES"), 1, 0) -> 0
E6: =IF(A6= "","",1) | I6: =IF(K6>0, 1, 0) -> 0 | N6: =IF(AND(L6<=10,M6<=10),M6-L6,MAX(0,10-L6)) -> 0 | O6: =IF(AND(L6<=10,M6>=20),10,IF(AND(L6>=10,M6<=20),M6-L6,IF(AND(L6<=10,M6<=20,M6>=10),M6-10,IF(AND(L6>=10,M6>=20),MAX(0,20-L6),0)))) -> 0 | P6: =IF(AND(L6<=20,M6>=30),10,IF(AND(L6>=20,M6<=30),M6-L6,IF(AND(L6<=20,M6<=30,M6>=20),M6-20,IF(AND(L6>=20,M6>=30),30-L6,0)))) -> 0 | Q6: =IF(AND(L6<=30,M6>=40),10,IF(AND(L6>=30,M6<=40),M6-L6,IF(AND(L6<=30,M6<=40,M6>=30),M6-30,IF(AND(L6>=30,M6>=40),40-L6,0)))) -> 0 | W6: =IF(AND(U6<=10,V6<=10),V6-U6,MAX(0,10-U6)) -> 0 | X6: =IF(AND(U6<=10,V6>=20),10,IF(AND(U6>=10,V6<=20),V6-U6,IF(AND(U6<=10,V6<=20,V6>=10),V6-10,IF(AND(U6>=10,V6>=20),MAX(0,20-U6),0)))) -> 0 | Y6: =IF(AND(U6<=20,V6>=30),10,IF(AND(U6>=20,V6<=30),V6-U6,IF(AND(U6<=20,V6<=30,V6>=20),V6-20,IF(AND(U6>=20,V6>=30),30-U6,0)))) -> 0 | Z6: =IF(AND(U6<=30,V6>=40),10,IF(AND(U6>=30,V6<=40),V6-U6,IF(AND(U6<=30,V6<=40,V6>=30),V6-30,IF(AND(U6>=30,V6>=40),40-U6,0)))) -> 0 | AB6: =IF(T6>0, 1, 0) -> 0 | AG6: =IF(AND(AE6<=10,AF6<=10),AF6-AE6,MAX(0,10-AE6)) -> 0 | AH6: =IF(AND(AE6<=10,AF6>=20),10,IF(AND(AE6>=10,AF6<=20),AF6-AE6,IF(AND(AE6<=10,AF6<=20,AF6>=10),AF6-10,IF(AND(AE6>=10,AF6>=20),MAX(0,20-AE6),0)))) -> 0 | AI6: =IF(AND(AE6<=20,AF6>=30),10,IF(AND(AE6>=20,AF6<=30),AF6-AE6,IF(AND(AE6<=20,AF6<=30,AF6>=20),AF6-20,IF(AND(AE6>=20,AF6>=30),30-AE6,0)))) -> 0 | AJ6: =IF(AND(AE6<=30,AF6>=40),10,IF(AND(AE6>=30,AF6<=40),AF6-AE6,IF(AND(AE6<=30,AF6<=40,AF6>=30),AF6-30,IF(AND(AE6>=30,AF6>=40),40-AE6,0)))) -> 0 | AL6: =IF(AD6>0, 1, 0) -> 0 | AQ6: =IF(AND(AO6<=10,AP6<=10),AP6-AO6,MAX(0,10-AO6)) -> 0 | AR6: =IF(AND(AO6<=10,AP6>=20),10,IF(AND(AO6>=10,AP6<=20),AP6-AO6,IF(AND(AO6<=10,AP6<=20,AP6>=10),AP6-10,IF(AND(AO6>=10,AP6>=20),MAX(0,20-AO6),0)))) -> 0 | AS6: =IF(AND(AO6<=20,AP6>=30),10,IF(AND(AO6>=20,AP6<=30),AP6-AO6,IF(AND(AO6<=20,AP6<=30,AP6>=20),AP6-20,IF(AND(AO6>=20,AP6>=30),30-AO6,0)))) -> 0 | AT6: =IF(AND(AO6<=30,AP6>=40),10,IF(AND(AO6>=30,AP6<=40),AP6-AO6,IF(AND(AO6<=30,AP6<=40,AP6>=30),AP6-30,IF(AND(AO6>=30,AP6>=40),40-AO6,0)))) -> 0 | AV6: =IF(AN6>0, 1, 0) -> 0 | BA6: =IF(AND(AY6<=10,AZ6<=10),AZ6-AY6,MAX(0,10-AY6)) -> 0 | BB6: =IF(AND(AY6<=10,AZ6>=20),10,IF(AND(AY6>=10,AZ6<=20),AZ6-AY6,IF(AND(AY6<=10,AZ6<=20,AZ6>=10),AZ6-10,IF(AND(AY6>=10,AZ6>=20),MAX(0,20-AY6),0)))) -> 0 | BC6: =IF(AND(AY6<=20,AZ6>=30),10,IF(AND(AY6>=20,AZ6<=30),AZ6-AY6,IF(AND(AY6<=20,AZ6<=30,AZ6>=20),AZ6-20,IF(AND(AY6>=20,AZ6>=30),30-AY6,0)))) -> 0 | BD6: =IF(AND(AY6<=30,AZ6>=40),10,IF(AND(AY6>=30,AZ6<=40),AZ6-AY6,IF(AND(AY6<=30,AZ6<=40,AZ6>=30),AZ6-30,IF(AND(AY6>=30,AZ6>=40),40-AY6,0)))) -> 0 | BF6: =IF(AX6>0, 1, 0) -> 0 | BP6: =IF(OR(BI6="YES",BL6="YES"), 1, 0) -> 0
E7: =IF(A7= "","",1) | I7: =IF(K7>0, 1, 0) -> 0 | N7: =IF(AND(L7<=10,M7<=10),M7-L7,MAX(0,10-L7)) -> 0 | O7: =IF(AND(L7<=10,M7>=20),10,IF(AND(L7>=10,M7<=20),M7-L7,IF(AND(L7<=10,M7<=20,M7>=10),M7-10,IF(AND(L7>=10,M7>=20),MAX(0,20-L7),0)))) -> 0 | P7: =IF(AND(L7<=20,M7>=30),10,IF(AND(L7>=20,M7<=30),M7-L7,IF(AND(L7<=20,M7<=30,M7>=20),M7-20,IF(AND(L7>=20,M7>=30),30-L7,0)))) -> 0 | Q7: =IF(AND(L7<=30,M7>=40),10,IF(AND(L7>=30,M7<=40),M7-L7,IF(AND(L7<=30,M7<=40,M7>=30),M7-30,IF(AND(L7>=30,M7>=40),40-L7,0)))) -> 0 | W7: =IF(AND(U7<=10,V7<=10),V7-U7,MAX(0,10-U7)) -> 0 | X7: =IF(AND(U7<=10,V7>=20),10,IF(AND(U7>=10,V7<=20),V7-U7,IF(AND(U7<=10,V7<=20,V7>=10),V7-10,IF(AND(U7>=10,V7>=20),MAX(0,20-U7),0)))) -> 0 | Y7: =IF(AND(U7<=20,V7>=30),10,IF(AND(U7>=20,V7<=30),V7-U7,IF(AND(U7<=20,V7<=30,V7>=20),V7-20,IF(AND(U7>=20,V7>=30),30-U7,0)))) -> 0 | Z7: =IF(AND(U7<=30,V7>=40),10,IF(AND(U7>=30,V7<=40),V7-U7,IF(AND(U7<=30,V7<=40,V7>=30),V7-30,IF(AND(U7>=30,V7>=40),40-U7,0)))) -> 0 | AB7: =IF(T7>0, 1, 0) -> 0 | AG7: =IF(AND(AE7<=10,AF7<=10),AF7-AE7,MAX(0,10-AE7)) -> 0 | AH7: =IF(AND(AE7<=10,AF7>=20),10,IF(AND(AE7>=10,AF7<=20),AF7-AE7,IF(AND(AE7<=10,AF7<=20,AF7>=10),AF7-10,IF(AND(AE7>=10,AF7>=20),MAX(0,20-AE7),0)))) -> 0 | AI7: =IF(AND(AE7<=20,AF7>=30),10,IF(AND(AE7>=20,AF7<=30),AF7-AE7,IF(AND(AE7<=20,AF7<=30,AF7>=20),AF7-20,IF(AND(AE7>=20,AF7>=30),30-AE7,0)))) -> 0 | AJ7: =IF(AND(AE7<=30,AF7>=40),10,IF(AND(AE7>=30,AF7<=40),AF7-AE7,IF(AND(AE7<=30,AF7<=40,AF7>=30),AF7-30,IF(AND(AE7>=30,AF7>=40),40-AE7,0)))) -> 0 | AL7: =IF(AD7>0, 1, 0) -> 0 | AQ7: =IF(AND(AO7<=10,AP7<=10),AP7-AO7,MAX(0,10-AO7)) -> 0 | AR7: =IF(AND(AO7<=10,AP7>=20),10,IF(AND(AO7>=10,AP7<=20),AP7-AO7,IF(AND(AO7<=10,AP7<=20,AP7>=10),AP7-10,IF(AND(AO7>=10,AP7>=20),MAX(0,20-AO7),0)))) -> 0 | AS7: =IF(AND(AO7<=20,AP7>=30),10,IF(AND(AO7>=20,AP7<=30),AP7-AO7,IF(AND(AO7<=20,AP7<=30,AP7>=20),AP7-20,IF(AND(AO7>=20,AP7>=30),30-AO7,0)))) -> 0 | AT7: =IF(AND(AO7<=30,AP7>=40),10,IF(AND(AO7>=30,AP7<=40),AP7-AO7,IF(AND(AO7<=30,AP7<=40,AP7>=30),AP7-30,IF(AND(AO7>=30,AP7>=40),40-AO7,0)))) -> 0 | AV7: =IF(AN7>0, 1, 0) -> 0 | BA7: =IF(AND(AY7<=10,AZ7<=10),AZ7-AY7,MAX(0,10-AY7)) -> 0 | BB7: =IF(AND(AY7<=10,AZ7>=20),10,IF(AND(AY7>=10,AZ7<=20),AZ7-AY7,IF(AND(AY7<=10,AZ7<=20,AZ7>=10),AZ7-10,IF(AND(AY7>=10,AZ7>=20),MAX(0,20-AY7),0)))) -> 0 | BC7: =IF(AND(AY7<=20,AZ7>=30),10,IF(AND(AY7>=20,AZ7<=30),AZ7-AY7,IF(AND(AY7<=20,AZ7<=30,AZ7>=20),AZ7-20,IF(AND(AY7>=20,AZ7>=30),30-AY7,0)))) -> 0 | BD7: =IF(AND(AY7<=30,AZ7>=40),10,IF(AND(AY7>=30,AZ7<=40),AZ7-AY7,IF(AND(AY7<=30,AZ7<=40,AZ7>=30),AZ7-30,IF(AND(AY7>=30,AZ7>=40),40-AY7,0)))) -> 0 | BF7: =IF(AX7>0, 1, 0) -> 0 | BP7: =IF(OR(BI7="YES",BL7="YES"), 1, 0) -> 0
E8: =IF(A8= "","",1) | I8: =IF(K8>0, 1, 0) -> 0 | N8: =IF(AND(L8<=10,M8<=10),M8-L8,MAX(0,10-L8)) -> 0 | O8: =IF(AND(L8<=10,M8>=20),10,IF(AND(L8>=10,M8<=20),M8-L8,IF(AND(L8<=10,M8<=20,M8>=10),M8-10,IF(AND(L8>=10,M8>=20),MAX(0,20-L8),0)))) -> 0 | P8: =IF(AND(L8<=20,M8>=30),10,IF(AND(L8>=20,M8<=30),M8-L8,IF(AND(L8<=20,M8<=30,M8>=20),M8-20,IF(AND(L8>=20,M8>=30),30-L8,0)))) -> 0 | Q8: =IF(AND(L8<=30,M8>=40),10,IF(AND(L8>=30,M8<=40),M8-L8,IF(AND(L8<=30,M8<=40,M8>=30),M8-30,IF(AND(L8>=30,M8>=40),40-L8,0)))) -> 0 | W8: =IF(AND(U8<=10,V8<=10),V8-U8,MAX(0,10-U8)) -> 0 | X8: =IF(AND(U8<=10,V8>=20),10,IF(AND(U8>=10,V8<=20),V8-U8,IF(AND(U8<=10,V8<=20,V8>=10),V8-10,IF(AND(U8>=10,V8>=20),MAX(0,20-U8),0)))) -> 0 | Y8: =IF(AND(U8<=20,V8>=30),10,IF(AND(U8>=20,V8<=30),V8-U8,IF(AND(U8<=20,V8<=30,V8>=20),V8-20,IF(AND(U8>=20,V8>=30),30-U8,0)))) -> 0 | Z8: =IF(AND(U8<=30,V8>=40),10,IF(AND(U8>=30,V8<=40),V8-U8,IF(AND(U8<=30,V8<=40,V8>=30),V8-30,IF(AND(U8>=30,V8>=40),40-U8,0)))) -> 0 | AB8: =IF(T8>0, 1, 0) -> 0 | AG8: =IF(AND(AE8<=10,AF8<=10),AF8-AE8,MAX(0,10-AE8)) -> 0 | AH8: =IF(AND(AE8<=10,AF8>=20),10,IF(AND(AE8>=10,AF8<=20),AF8-AE8,IF(AND(AE8<=10,AF8<=20,AF8>=10),AF8-10,IF(AND(AE8>=10,AF8>=20),MAX(0,20-AE8),0)))) -> 0 | AI8: =IF(AND(AE8<=20,AF8>=30),10,IF(AND(AE8>=20,AF8<=30),AF8-AE8,IF(AND(AE8<=20,AF8<=30,AF8>=20),AF8-20,IF(AND(AE8>=20,AF8>=30),30-AE8,0)))) -> 0 | AJ8: =IF(AND(AE8<=30,AF8>=40),10,IF(AND(AE8>=30,AF8<=40),AF8-AE8,IF(AND(AE8<=30,AF8<=40,AF8>=30),AF8-30,IF(AND(AE8>=30,AF8>=40),40-AE8,0)))) -> 0 | AL8: =IF(AD8>0, 1, 0) -> 0 | AQ8: =IF(AND(AO8<=10,AP8<=10),AP8-AO8,MAX(0,10-AO8)) -> 0 | AR8: =IF(AND(AO8<=10,AP8>=20),10,IF(AND(AO8>=10,AP8<=20),AP8-AO8,IF(AND(AO8<=10,AP8<=20,AP8>=10),AP8-10,IF(AND(AO8>=10,AP8>=20),MAX(0,20-AO8),0)))) -> 0 | AS8: =IF(AND(AO8<=20,AP8>=30),10,IF(AND(AO8>=20,AP8<=30),AP8-AO8,IF(AND(AO8<=20,AP8<=30,AP8>=20),AP8-20,IF(AND(AO8>=20,AP8>=30),30-AO8,0)))) -> 0 | AT8: =IF(AND(AO8<=30,AP8>=40),10,IF(AND(AO8>=30,AP8<=40),AP8-AO8,IF(AND(AO8<=30,AP8<=40,AP8>=30),AP8-30,IF(AND(AO8>=30,AP8>=40),40-AO8,0)))) -> 0 | AV8: =IF(AN8>0, 1, 0) -> 0 | BA8: =IF(AND(AY8<=10,AZ8<=10),AZ8-AY8,MAX(0,10-AY8)) -> 0 | BB8: =IF(AND(AY8<=10,AZ8>=20),10,IF(AND(AY8>=10,AZ8<=20),AZ8-AY8,IF(AND(AY8<=10,AZ8<=20,AZ8>=10),AZ8-10,IF(AND(AY8>=10,AZ8>=20),MAX(0,20-AY8),0)))) -> 0 | BC8: =IF(AND(AY8<=20,AZ8>=30),10,IF(AND(AY8>=20,AZ8<=30),AZ8-AY8,IF(AND(AY8<=20,AZ8<=30,AZ8>=20),AZ8-20,IF(AND(AY8>=20,AZ8>=30),30-AY8,0)))) -> 0 | BD8: =IF(AND(AY8<=30,AZ8>=40),10,IF(AND(AY8>=30,AZ8<=40),AZ8-AY8,IF(AND(AY8<=30,AZ8<=40,AZ8>=30),AZ8-30,IF(AND(AY8>=30,AZ8>=40),40-AY8,0)))) -> 0 | BF8: =IF(AX8>0, 1, 0) -> 0 | BP8: =IF(OR(BI8="YES",BL8="YES"), 1, 0) -> 0
E9: =IF(A9= "","",1) | I9: =IF(K9>0, 1, 0) -> 0 | N9: =IF(AND(L9<=10,M9<=10),M9-L9,MAX(0,10-L9)) -> 0 | O9: =IF(AND(L9<=10,M9>=20),10,IF(AND(L9>=10,M9<=20),M9-L9,IF(AND(L9<=10,M9<=20,M9>=10),M9-10,IF(AND(L9>=10,M9>=20),MAX(0,20-L9),0)))) -> 0 | P9: =IF(AND(L9<=20,M9>=30),10,IF(AND(L9>=20,M9<=30),M9-L9,IF(AND(L9<=20,M9<=30,M9>=20),M9-20,IF(AND(L9>=20,M9>=30),30-L9,0)))) -> 0 | Q9: =IF(AND(L9<=30,M9>=40),10,IF(AND(L9>=30,M9<=40),M9-L9,IF(AND(L9<=30,M9<=40,M9>=30),M9-30,IF(AND(L9>=30,M9>=40),40-L9,0)))) -> 0 | W9: =IF(AND(U9<=10,V9<=10),V9-U9,MAX(0,10-U9)) -> 0 | X9: =IF(AND(U9<=10,V9>=20),10,IF(AND(U9>=10,V9<=20),V9-U9,IF(AND(U9<=10,V9<=20,V9>=10),V9-10,IF(AND(U9>=10,V9>=20),MAX(0,20-U9),0)))) -> 0 | Y9: =IF(AND(U9<=20,V9>=30),10,IF(AND(U9>=20,V9<=30),V9-U9,IF(AND(U9<=20,V9<=30,V9>=20),V9-20,IF(AND(U9>=20,V9>=30),30-U9,0)))) -> 0 | Z9: =IF(AND(U9<=30,V9>=40),10,IF(AND(U9>=30,V9<=40),V9-U9,IF(AND(U9<=30,V9<=40,V9>=30),V9-30,IF(AND(U9>=30,V9>=40),40-U9,0)))) -> 0 | AB9: =IF(T9>0, 1, 0) -> 0 | AG9: =IF(AND(AE9<=10,AF9<=10),AF9-AE9,MAX(0,10-AE9)) -> 0 | AH9: =IF(AND(AE9<=10,AF9>=20),10,IF(AND(AE9>=10,AF9<=20),AF9-AE9,IF(AND(AE9<=10,AF9<=20,AF9>=10),AF9-10,IF(AND(AE9>=10,AF9>=20),MAX(0,20-AE9),0)))) -> 0 | AI9: =IF(AND(AE9<=20,AF9>=30),10,IF(AND(AE9>=20,AF9<=30),AF9-AE9,IF(AND(AE9<=20,AF9<=30,AF9>=20),AF9-20,IF(AND(AE9>=20,AF9>=30),30-AE9,0)))) -> 0 | AJ9: =IF(AND(AE9<=30,AF9>=40),10,IF(AND(AE9>=30,AF9<=40),AF9-AE9,IF(AND(AE9<=30,AF9<=40,AF9>=30),AF9-30,IF(AND(AE9>=30,AF9>=40),40-AE9,0)))) -> 0 | AL9: =IF(AD9>0, 1, 0) -> 0 | AQ9: =IF(AND(AO9<=10,AP9<=10),AP9-AO9,MAX(0,10-AO9)) -> 0 | AR9: =IF(AND(AO9<=10,AP9>=20),10,IF(AND(AO9>=10,AP9<=20),AP9-AO9,IF(AND(AO9<=10,AP9<=20,AP9>=10),AP9-10,IF(AND(AO9>=10,AP9>=20),MAX(0,20-AO9),0)))) -> 0 | AS9: =IF(AND(AO9<=20,AP9>=30),10,IF(AND(AO9>=20,AP9<=30),AP9-AO9,IF(AND(AO9<=20,AP9<=30,AP9>=20),AP9-20,IF(AND(AO9>=20,AP9>=30),30-AO9,0)))) -> 0 | AT9: =IF(AND(AO9<=30,AP9>=40),10,IF(AND(AO9>=30,AP9<=40),AP9-AO9,IF(AND(AO9<=30,AP9<=40,AP9>=30),AP9-30,IF(AND(AO9>=30,AP9>=40),40-AO9,0)))) -> 0 | AV9: =IF(AN9>0, 1, 0) -> 0 | BA9: =IF(AND(AY9<=10,AZ9<=10),AZ9-AY9,MAX(0,10-AY9)) -> 0 | BB9: =IF(AND(AY9<=10,AZ9>=20),10,IF(AND(AY9>=10,AZ9<=20),AZ9-AY9,IF(AND(AY9<=10,AZ9<=20,AZ9>=10),AZ9-10,IF(AND(AY9>=10,AZ9>=20),MAX(0,20-AY9),0)))) -> 0 | BC9: =IF(AND(AY9<=20,AZ9>=30),10,IF(AND(AY9>=20,AZ9<=30),AZ9-AY9,IF(AND(AY9<=20,AZ9<=30,AZ9>=20),AZ9-20,IF(AND(AY9>=20,AZ9>=30),30-AY9,0)))) -> 0 | BD9: =IF(AND(AY9<=30,AZ9>=40),10,IF(AND(AY9>=30,AZ9<=40),AZ9-AY9,IF(AND(AY9<=30,AZ9<=40,AZ9>=30),AZ9-30,IF(AND(AY9>=30,AZ9>=40),40-AY9,0)))) -> 0 | BF9: =IF(AX9>0, 1, 0) -> 0 | BP9: =IF(OR(BI9="YES",BL9="YES"), 1, 0) -> 0
E10: =IF(A10= "","",1) | I10: =IF(K10>0, 1, 0) -> 0 | N10: =IF(AND(L10<=10,M10<=10),M10-L10,MAX(0,10-L10)) -> 0 | O10: =IF(AND(L10<=10,M10>=20),10,IF(AND(L10>=10,M10<=20),M10-L10,IF(AND(L10<=10,M10<=20,M10>=10),M10-10,IF(AND(L10>=10,M10>=20),MAX(0,20-L10),0)))) -> 0 | P10: =IF(AND(L10<=20,M10>=30),10,IF(AND(L10>=20,M10<=30),M10-L10,IF(AND(L10<=20,M10<=30,M10>=20),M10-20,IF(AND(L10>=20,M10>=30),30-L10,0)))) -> 0 | Q10: =IF(AND(L10<=30,M10>=40),10,IF(AND(L10>=30,M10<=40),M10-L10,IF(AND(L10<=30,M10<=40,M10>=30),M10-30,IF(AND(L10>=30,M10>=40),40-L10,0)))) -> 0 | W10: =IF(AND(U10<=10,V10<=10),V10-U10,MAX(0,10-U10)) -> 0 | X10: =IF(AND(U10<=10,V10>=20),10,IF(AND(U10>=10,V10<=20),V10-U10,IF(AND(U10<=10,V10<=20,V10>=10),V10-10,IF(AND(U10>=10,V10>=20),MAX(0,20-U10),0)))) -> 0 | Y10: =IF(AND(U10<=20,V10>=30),10,IF(AND(U10>=20,V10<=30),V10-U10,IF(AND(U10<=20,V10<=30,V10>=20),V10-20,IF(AND(U10>=20,V10>=30),30-U10,0)))) -> 0 | Z10: =IF(AND(U10<=30,V10>=40),10,IF(AND(U10>=30,V10<=40),V10-U10,IF(AND(U10<=30,V10<=40,V10>=30),V10-30,IF(AND(U10>=30,V10>=40),40-U10,0)))) -> 0 | AB10: =IF(T10>0, 1, 0) -> 0 | AG10: =IF(AND(AE10<=10,AF10<=10),AF10-AE10,MAX(0,10-AE10)) -> 0 | AH10: =IF(AND(AE10<=10,AF10>=20),10,IF(AND(AE10>=10,AF10<=20),AF10-AE10,IF(AND(AE10<=10,AF10<=20,AF10>=10),AF10-10,IF(AND(AE10>=10,AF10>=20),MAX(0,20-AE10),0)))) -> 0 | AI10: =IF(AND(AE10<=20,AF10>=30),10,IF(AND(AE10>=20,AF10<=30),AF10-AE10,IF(AND(AE10<=20,AF10<=30,AF10>=20),AF10-20,IF(AND(AE10>=20,AF10>=30),30-AE10,0)))) -> 0 | AJ10: =IF(AND(AE10<=30,AF10>=40),10,IF(AND(AE10>=30,AF10<=40),AF10-AE10,IF(AND(AE10<=30,AF10<=40,AF10>=30),AF10-30,IF(AND(AE10>=30,AF10>=40),40-AE10,0)))) -> 0 | AL10: =IF(AD10>0, 1, 0) -> 0 | AQ10: =IF(AND(AO10<=10,AP10<=10),AP10-AO10,MAX(0,10-AO10)) -> 0 | AR10: =IF(AND(AO10<=10,AP10>=20),10,IF(AND(AO10>=10,AP10<=20),AP10-AO10,IF(AND(AO10<=10,AP10<=20,AP10>=10),AP10-10,IF(AND(AO10>=10,AP10>=20),MAX(0,20-AO10),0)))) -> 0 | AS10: =IF(AND(AO10<=20,AP10>=30),10,IF(AND(AO10>=20,AP10<=30),AP10-AO10,IF(AND(AO10<=20,AP10<=30,AP10>=20),AP10-20,IF(AND(AO10>=20,AP10>=30),30-AO10,0)))) -> 0 | AT10: =IF(AND(AO10<=30,AP10>=40),10,IF(AND(AO10>=30,AP10<=40),AP10-AO10,IF(AND(AO10<=30,AP10<=40,AP10>=30),AP10-30,IF(AND(AO10>=30,AP10>=40),40-AO10,0)))) -> 0 | AV10: =IF(AN10>0, 1, 0) -> 0 | BA10: =IF(AND(AY10<=10,AZ10<=10),AZ10-AY10,MAX(0,10-AY10)) -> 0 | BB10: =IF(AND(AY10<=10,AZ10>=20),10,IF(AND(AY10>=10,AZ10<=20),AZ10-AY10,IF(AND(AY10<=10,AZ10<=20,AZ10>=10),AZ10-10,IF(AND(AY10>=10,AZ10>=20),MAX(0,20-AY10),0)))) -> 0 | BC10: =IF(AND(AY10<=20,AZ10>=30),10,IF(AND(AY10>=20,AZ10<=30),AZ10-AY10,IF(AND(AY10<=20,AZ10<=30,AZ10>=20),AZ10-20,IF(AND(AY10>=20,AZ10>=30),30-AY10,0)))) -> 0 | BD10: =IF(AND(AY10<=30,AZ10>=40),10,IF(AND(AY10>=30,AZ10<=40),AZ10-AY10,IF(AND(AY10<=30,AZ10<=40,AZ10>=30),AZ10-30,IF(AND(AY10>=30,AZ10>=40),40-AY10,0)))) -> 0 | BF10: =IF(AX10>0, 1, 0) -> 0 | BP10: =IF(OR(BI10="YES",BL10="YES"), 1, 0) -> 0
E11: =IF(A11= "","",1) | I11: =IF(K11>0, 1, 0) -> 0 | N11: =IF(AND(L11<=10,M11<=10),M11-L11,MAX(0,10-L11)) -> 0 | O11: =IF(AND(L11<=10,M11>=20),10,IF(AND(L11>=10,M11<=20),M11-L11,IF(AND(L11<=10,M11<=20,M11>=10),M11-10,IF(AND(L11>=10,M11>=20),MAX(0,20-L11),0)))) -> 0 | P11: =IF(AND(L11<=20,M11>=30),10,IF(AND(L11>=20,M11<=30),M11-L11,IF(AND(L11<=20,M11<=30,M11>=20),M11-20,IF(AND(L11>=20,M11>=30),30-L11,0)))) -> 0 | Q11: =IF(AND(L11<=30,M11>=40),10,IF(AND(L11>=30,M11<=40),M11-L11,IF(AND(L11<=30,M11<=40,M11>=30),M11-30,IF(AND(L11>=30,M11>=40),40-L11,0)))) -> 0 | W11: =IF(AND(U11<=10,V11<=10),V11-U11,MAX(0,10-U11)) -> 0 | X11: =IF(AND(U11<=10,V11>=20),10,IF(AND(U11>=10,V11<=20),V11-U11,IF(AND(U11<=10,V11<=20,V11>=10),V11-10,IF(AND(U11>=10,V11>=20),MAX(0,20-U11),0)))) -> 0 | Y11: =IF(AND(U11<=20,V11>=30),10,IF(AND(U11>=20,V11<=30),V11-U11,IF(AND(U11<=20,V11<=30,V11>=20),V11-20,IF(AND(U11>=20,V11>=30),30-U11,0)))) -> 0 | Z11: =IF(AND(U11<=30,V11>=40),10,IF(AND(U11>=30,V11<=40),V11-U11,IF(AND(U11<=30,V11<=40,V11>=30),V11-30,IF(AND(U11>=30,V11>=40),40-U11,0)))) -> 0 | AB11: =IF(T11>0, 1, 0) -> 0 | AG11: =IF(AND(AE11<=10,AF11<=10),AF11-AE11,MAX(0,10-AE11)) -> 0 | AH11: =IF(AND(AE11<=10,AF11>=20),10,IF(AND(AE11>=10,AF11<=20),AF11-AE11,IF(AND(AE11<=10,AF11<=20,AF11>=10),AF11-10,IF(AND(AE11>=10,AF11>=20),MAX(0,20-AE11),0)))) -> 0 | AI11: =IF(AND(AE11<=20,AF11>=30),10,IF(AND(AE11>=20,AF11<=30),AF11-AE11,IF(AND(AE11<=20,AF11<=30,AF11>=20),AF11-20,IF(AND(AE11>=20,AF11>=30),30-AE11,0)))) -> 0 | AJ11: =IF(AND(AE11<=30,AF11>=40),10,IF(AND(AE11>=30,AF11<=40),AF11-AE11,IF(AND(AE11<=30,AF11<=40,AF11>=30),AF11-30,IF(AND(AE11>=30,AF11>=40),40-AE11,0)))) -> 0 | AL11: =IF(AD11>0, 1, 0) -> 0 | AQ11: =IF(AND(AO11<=10,AP11<=10),AP11-AO11,MAX(0,10-AO11)) -> 0 | AR11: =IF(AND(AO11<=10,AP11>=20),10,IF(AND(AO11>=10,AP11<=20),AP11-AO11,IF(AND(AO11<=10,AP11<=20,AP11>=10),AP11-10,IF(AND(AO11>=10,AP11>=20),MAX(0,20-AO11),0)))) -> 0 | AS11: =IF(AND(AO11<=20,AP11>=30),10,IF(AND(AO11>=20,AP11<=30),AP11-AO11,IF(AND(AO11<=20,AP11<=30,AP11>=20),AP11-20,IF(AND(AO11>=20,AP11>=30),30-AO11,0)))) -> 0 | AT11: =IF(AND(AO11<=30,AP11>=40),10,IF(AND(AO11>=30,AP11<=40),AP11-AO11,IF(AND(AO11<=30,AP11<=40,AP11>=30),AP11-30,IF(AND(AO11>=30,AP11>=40),40-AO11,0)))) -> 0 | AV11: =IF(AN11>0, 1, 0) -> 0 | BA11: =IF(AND(AY11<=10,AZ11<=10),AZ11-AY11,MAX(0,10-AY11)) -> 0 | BB11: =IF(AND(AY11<=10,AZ11>=20),10,IF(AND(AY11>=10,AZ11<=20),AZ11-AY11,IF(AND(AY11<=10,AZ11<=20,AZ11>=10),AZ11-10,IF(AND(AY11>=10,AZ11>=20),MAX(0,20-AY11),0)))) -> 0 | BC11: =IF(AND(AY11<=20,AZ11>=30),10,IF(AND(AY11>=20,AZ11<=30),AZ11-AY11,IF(AND(AY11<=20,AZ11<=30,AZ11>=20),AZ11-20,IF(AND(AY11>=20,AZ11>=30),30-AY11,0)))) -> 0 | BD11: =IF(AND(AY11<=30,AZ11>=40),10,IF(AND(AY11>=30,AZ11<=40),AZ11-AY11,IF(AND(AY11<=30,AZ11<=40,AZ11>=30),AZ11-30,IF(AND(AY11>=30,AZ11>=40),40-AY11,0)))) -> 0 | BF11: =IF(AX11>0, 1, 0) -> 0 | BP11: =IF(OR(BI11="YES",BL11="YES"), 1, 0) -> 0
E12: =IF(A12= "","",1) | I12: =IF(K12>0, 1, 0) -> 0 | N12: =IF(AND(L12<=10,M12<=10),M12-L12,MAX(0,10-L12)) -> 0 | O12: =IF(AND(L12<=10,M12>=20),10,IF(AND(L12>=10,M12<=20),M12-L12,IF(AND(L12<=10,M12<=20,M12>=10),M12-10,IF(AND(L12>=10,M12>=20),MAX(0,20-L12),0)))) -> 0 | P12: =IF(AND(L12<=20,M12>=30),10,IF(AND(L12>=20,M12<=30),M12-L12,IF(AND(L12<=20,M12<=30,M12>=20),M12-20,IF(AND(L12>=20,M12>=30),30-L12,0)))) -> 0 | Q12: =IF(AND(L12<=30,M12>=40),10,IF(AND(L12>=30,M12<=40),M12-L12,IF(AND(L12<=30,M12<=40,M12>=30),M12-30,IF(AND(L12>=30,M12>=40),40-L12,0)))) -> 0 | W12: =IF(AND(U12<=10,V12<=10),V12-U12,MAX(0,10-U12)) -> 0 | X12: =IF(AND(U12<=10,V12>=20),10,IF(AND(U12>=10,V12<=20),V12-U12,IF(AND(U12<=10,V12<=20,V12>=10),V12-10,IF(AND(U12>=10,V12>=20),MAX(0,20-U12),0)))) -> 0 | Y12: =IF(AND(U12<=20,V12>=30),10,IF(AND(U12>=20,V12<=30),V12-U12,IF(AND(U12<=20,V12<=30,V12>=20),V12-20,IF(AND(U12>=20,V12>=30),30-U12,0)))) -> 0 | Z12: =IF(AND(U12<=30,V12>=40),10,IF(AND(U12>=30,V12<=40),V12-U12,IF(AND(U12<=30,V12<=40,V12>=30),V12-30,IF(AND(U12>=30,V12>=40),40-U12,0)))) -> 0 | AB12: =IF(T12>0, 1, 0) -> 0 | AG12: =IF(AND(AE12<=10,AF12<=10),AF12-AE12,MAX(0,10-AE12)) -> 0 | AH12: =IF(AND(AE12<=10,AF12>=20),10,IF(AND(AE12>=10,AF12<=20),AF12-AE12,IF(AND(AE12<=10,AF12<=20,AF12>=10),AF12-10,IF(AND(AE12>=10,AF12>=20),MAX(0,20-AE12),0)))) -> 0 | AI12: =IF(AND(AE12<=20,AF12>=30),10,IF(AND(AE12>=20,AF12<=30),AF12-AE12,IF(AND(AE12<=20,AF12<=30,AF12>=20),AF12-20,IF(AND(AE12>=20,AF12>=30),30-AE12,0)))) -> 0 | AJ12: =IF(AND(AE12<=30,AF12>=40),10,IF(AND(AE12>=30,AF12<=40),AF12-AE12,IF(AND(AE12<=30,AF12<=40,AF12>=30),AF12-30,IF(AND(AE12>=30,AF12>=40),40-AE12,0)))) -> 0 | AL12: =IF(AD12>0, 1, 0) -> 0 | AQ12: =IF(AND(AO12<=10,AP12<=10),AP12-AO12,MAX(0,10-AO12)) -> 0 | AR12: =IF(AND(AO12<=10,AP12>=20),10,IF(AND(AO12>=10,AP12<=20),AP12-AO12,IF(AND(AO12<=10,AP12<=20,AP12>=10),AP12-10,IF(AND(AO12>=10,AP12>=20),MAX(0,20-AO12),0)))) -> 0 | AS12: =IF(AND(AO12<=20,AP12>=30),10,IF(AND(AO12>=20,AP12<=30),AP12-AO12,IF(AND(AO12<=20,AP12<=30,AP12>=20),AP12-20,IF(AND(AO12>=20,AP12>=30),30-AO12,0)))) -> 0 | AT12: =IF(AND(AO12<=30,AP12>=40),10,IF(AND(AO12>=30,AP12<=40),AP12-AO12,IF(AND(AO12<=30,AP12<=40,AP12>=30),AP12-30,IF(AND(AO12>=30,AP12>=40),40-AO12,0)))) -> 0 | AV12: =IF(AN12>0, 1, 0) -> 0 | BA12: =IF(AND(AY12<=10,AZ12<=10),AZ12-AY12,MAX(0,10-AY12)) -> 0 | BB12: =IF(AND(AY12<=10,AZ12>=20),10,IF(AND(AY12>=10,AZ12<=20),AZ12-AY12,IF(AND(AY12<=10,AZ12<=20,AZ12>=10),AZ12-10,IF(AND(AY12>=10,AZ12>=20),MAX(0,20-AY12),0)))) -> 0 | BC12: =IF(AND(AY12<=20,AZ12>=30),10,IF(AND(AY12>=20,AZ12<=30),AZ12-AY12,IF(AND(AY12<=20,AZ12<=30,AZ12>=20),AZ12-20,IF(AND(AY12>=20,AZ12>=30),30-AY12,0)))) -> 0 | BD12: =IF(AND(AY12<=30,AZ12>=40),10,IF(AND(AY12>=30,AZ12<=40),AZ12-AY12,IF(AND(AY12<=30,AZ12<=40,AZ12>=30),AZ12-30,IF(AND(AY12>=30,AZ12>=40),40-AY12,0)))) -> 0 | BF12: =IF(AX12>0, 1, 0) -> 0 | BP12: =IF(OR(BI12="YES",BL12="YES"), 1, 0) -> 0
E13: =IF(A13= "","",1) | I13: =IF(K13>0, 1, 0) -> 0 | N13: =IF(AND(L13<=10,M13<=10),M13-L13,MAX(0,10-L13)) -> 0 | O13: =IF(AND(L13<=10,M13>=20),10,IF(AND(L13>=10,M13<=20),M13-L13,IF(AND(L13<=10,M13<=20,M13>=10),M13-10,IF(AND(L13>=10,M13>=20),MAX(0,20-L13),0)))) -> 0 | P13: =IF(AND(L13<=20,M13>=30),10,IF(AND(L13>=20,M13<=30),M13-L13,IF(AND(L13<=20,M13<=30,M13>=20),M13-20,IF(AND(L13>=20,M13>=30),30-L13,0)))) -> 0 | Q13: =IF(AND(L13<=30,M13>=40),10,IF(AND(L13>=30,M13<=40),M13-L13,IF(AND(L13<=30,M13<=40,M13>=30),M13-30,IF(AND(L13>=30,M13>=40),40-L13,0)))) -> 0 | W13: =IF(AND(U13<=10,V13<=10),V13-U13,MAX(0,10-U13)) -> 0 | X13: =IF(AND(U13<=10,V13>=20),10,IF(AND(U13>=10,V13<=20),V13-U13,IF(AND(U13<=10,V13<=20,V13>=10),V13-10,IF(AND(U13>=10,V13>=20),MAX(0,20-U13),0)))) -> 0 | Y13: =IF(AND(U13<=20,V13>=30),10,IF(AND(U13>=20,V13<=30),V13-U13,IF(AND(U13<=20,V13<=30,V13>=20),V13-20,IF(AND(U13>=20,V13>=30),30-U13,0)))) -> 0 | Z13: =IF(AND(U13<=30,V13>=40),10,IF(AND(U13>=30,V13<=40),V13-U13,IF(AND(U13<=30,V13<=40,V13>=30),V13-30,IF(AND(U13>=30,V13>=40),40-U13,0)))) -> 0 | AB13: =IF(T13>0, 1, 0) -> 0 | AG13: =IF(AND(AE13<=10,AF13<=10),AF13-AE13,MAX(0,10-AE13)) -> 0 | AH13: =IF(AND(AE13<=10,AF13>=20),10,IF(AND(AE13>=10,AF13<=20),AF13-AE13,IF(AND(AE13<=10,AF13<=20,AF13>=10),AF13-10,IF(AND(AE13>=10,AF13>=20),MAX(0,20-AE13),0)))) -> 0 | AI13: =IF(AND(AE13<=20,AF13>=30),10,IF(AND(AE13>=20,AF13<=30),AF13-AE13,IF(AND(AE13<=20,AF13<=30,AF13>=20),AF13-20,IF(AND(AE13>=20,AF13>=30),30-AE13,0)))) -> 0 | AJ13: =IF(AND(AE13<=30,AF13>=40),10,IF(AND(AE13>=30,AF13<=40),AF13-AE13,IF(AND(AE13<=30,AF13<=40,AF13>=30),AF13-30,IF(AND(AE13>=30,AF13>=40),40-AE13,0)))) -> 0 | AL13: =IF(AD13>0, 1, 0) -> 0 | AQ13: =IF(AND(AO13<=10,AP13<=10),AP13-AO13,MAX(0,10-AO13)) -> 0 | AR13: =IF(AND(AO13<=10,AP13>=20),10,IF(AND(AO13>=10,AP13<=20),AP13-AO13,IF(AND(AO13<=10,AP13<=20,AP13>=10),AP13-10,IF(AND(AO13>=10,AP13>=20),MAX(0,20-AO13),0)))) -> 0 | AS13: =IF(AND(AO13<=20,AP13>=30),10,IF(AND(AO13>=20,AP13<=30),AP13-AO13,IF(AND(AO13<=20,AP13<=30,AP13>=20),AP13-20,IF(AND(AO13>=20,AP13>=30),30-AO13,0)))) -> 0 | AT13: =IF(AND(AO13<=30,AP13>=40),10,IF(AND(AO13>=30,AP13<=40),AP13-AO13,IF(AND(AO13<=30,AP13<=40,AP13>=30),AP13-30,IF(AND(AO13>=30,AP13>=40),40-AO13,0)))) -> 0 | AV13: =IF(AN13>0, 1, 0) -> 0 | BA13: =IF(AND(AY13<=10,AZ13<=10),AZ13-AY13,MAX(0,10-AY13)) -> 0 | BB13: =IF(AND(AY13<=10,AZ13>=20),10,IF(AND(AY13>=10,AZ13<=20),AZ13-AY13,IF(AND(AY13<=10,AZ13<=20,AZ13>=10),AZ13-10,IF(AND(AY13>=10,AZ13>=20),MAX(0,20-AY13),0)))) -> 0 | BC13: =IF(AND(AY13<=20,AZ13>=30),10,IF(AND(AY13>=20,AZ13<=30),AZ13-AY13,IF(AND(AY13<=20,AZ13<=30,AZ13>=20),AZ13-20,IF(AND(AY13>=20,AZ13>=30),30-AY13,0)))) -> 0 | BD13: =IF(AND(AY13<=30,AZ13>=40),10,IF(AND(AY13>=30,AZ13<=40),AZ13-AY13,IF(AND(AY13<=30,AZ13<=40,AZ13>=30),AZ13-30,IF(AND(AY13>=30,AZ13>=40),40-AY13,0)))) -> 0 | BF13: =IF(AX13>0, 1, 0) -> 0 | BP13: =IF(OR(BI13="YES",BL13="YES"), 1, 0) -> 0
E14: =IF(A14= "","",1) | I14: =IF(K14>0, 1, 0) -> 0 | N14: =IF(AND(L14<=10,M14<=10),M14-L14,MAX(0,10-L14)) -> 0 | O14: =IF(AND(L14<=10,M14>=20),10,IF(AND(L14>=10,M14<=20),M14-L14,IF(AND(L14<=10,M14<=20,M14>=10),M14-10,IF(AND(L14>=10,M14>=20),MAX(0,20-L14),0)))) -> 0 | P14: =IF(AND(L14<=20,M14>=30),10,IF(AND(L14>=20,M14<=30),M14-L14,IF(AND(L14<=20,M14<=30,M14>=20),M14-20,IF(AND(L14>=20,M14>=30),30-L14,0)))) -> 0 | Q14: =IF(AND(L14<=30,M14>=40),10,IF(AND(L14>=30,M14<=40),M14-L14,IF(AND(L14<=30,M14<=40,M14>=30),M14-30,IF(AND(L14>=30,M14>=40),40-L14,0)))) -> 0 | W14: =IF(AND(U14<=10,V14<=10),V14-U14,MAX(0,10-U14)) -> 0 | X14: =IF(AND(U14<=10,V14>=20),10,IF(AND(U14>=10,V14<=20),V14-U14,IF(AND(U14<=10,V14<=20,V14>=10),V14-10,IF(AND(U14>=10,V14>=20),MAX(0,20-U14),0)))) -> 0 | Y14: =IF(AND(U14<=20,V14>=30),10,IF(AND(U14>=20,V14<=30),V14-U14,IF(AND(U14<=20,V14<=30,V14>=20),V14-20,IF(AND(U14>=20,V14>=30),30-U14,0)))) -> 0 | Z14: =IF(AND(U14<=30,V14>=40),10,IF(AND(U14>=30,V14<=40),V14-U14,IF(AND(U14<=30,V14<=40,V14>=30),V14-30,IF(AND(U14>=30,V14>=40),40-U14,0)))) -> 0 | AB14: =IF(T14>0, 1, 0) -> 0 | AG14: =IF(AND(AE14<=10,AF14<=10),AF14-AE14,MAX(0,10-AE14)) -> 0 | AH14: =IF(AND(AE14<=10,AF14>=20),10,IF(AND(AE14>=10,AF14<=20),AF14-AE14,IF(AND(AE14<=10,AF14<=20,AF14>=10),AF14-10,IF(AND(AE14>=10,AF14>=20),MAX(0,20-AE14),0)))) -> 0 | AI14: =IF(AND(AE14<=20,AF14>=30),10,IF(AND(AE14>=20,AF14<=30),AF14-AE14,IF(AND(AE14<=20,AF14<=30,AF14>=20),AF14-20,IF(AND(AE14>=20,AF14>=30),30-AE14,0)))) -> 0 | AJ14: =IF(AND(AE14<=30,AF14>=40),10,IF(AND(AE14>=30,AF14<=40),AF14-AE14,IF(AND(AE14<=30,AF14<=40,AF14>=30),AF14-30,IF(AND(AE14>=30,AF14>=40),40-AE14,0)))) -> 0 | AL14: =IF(AD14>0, 1, 0) -> 0 | AQ14: =IF(AND(AO14<=10,AP14<=10),AP14-AO14,MAX(0,10-AO14)) -> 0 | AR14: =IF(AND(AO14<=10,AP14>=20),10,IF(AND(AO14>=10,AP14<=20),AP14-AO14,IF(AND(AO14<=10,AP14<=20,AP14>=10),AP14-10,IF(AND(AO14>=10,AP14>=20),MAX(0,20-AO14),0)))) -> 0 | AS14: =IF(AND(AO14<=20,AP14>=30),10,IF(AND(AO14>=20,AP14<=30),AP14-AO14,IF(AND(AO14<=20,AP14<=30,AP14>=20),AP14-20,IF(AND(AO14>=20,AP14>=30),30-AO14,0)))) -> 0 | AT14: =IF(AND(AO14<=30,AP14>=40),10,IF(AND(AO14>=30,AP14<=40),AP14-AO14,IF(AND(AO14<=30,AP14<=40,AP14>=30),AP14-30,IF(AND(AO14>=30,AP14>=40),40-AO14,0)))) -> 0 | AV14: =IF(AN14>0, 1, 0) -> 0 | BA14: =IF(AND(AY14<=10,AZ14<=10),AZ14-AY14,MAX(0,10-AY14)) -> 0 | BB14: =IF(AND(AY14<=10,AZ14>=20),10,IF(AND(AY14>=10,AZ14<=20),AZ14-AY14,IF(AND(AY14<=10,AZ14<=20,AZ14>=10),AZ14-10,IF(AND(AY14>=10,AZ14>=20),MAX(0,20-AY14),0)))) -> 0 | BC14: =IF(AND(AY14<=20,AZ14>=30),10,IF(AND(AY14>=20,AZ14<=30),AZ14-AY14,IF(AND(AY14<=20,AZ14<=30,AZ14>=20),AZ14-20,IF(AND(AY14>=20,AZ14>=30),30-AY14,0)))) -> 0 | BD14: =IF(AND(AY14<=30,AZ14>=40),10,IF(AND(AY14>=30,AZ14<=40),AZ14-AY14,IF(AND(AY14<=30,AZ14<=40,AZ14>=30),AZ14-30,IF(AND(AY14>=30,AZ14>=40),40-AY14,0)))) -> 0 | BF14: =IF(AX14>0, 1, 0) -> 0 | BP14: =IF(OR(BI14="YES",BL14="YES"), 1, 0) -> 0
... E27: =IF(A27= "","",1) | I27: =IF(K27>0, 1, 0) -> 0 | N27: =IF(AND(L27<=10,M27<=10),M27-L27,MAX(0,10-L27)) -> 0 | O27: =IF(AND(L27<=10,M27>=20),10,IF(AND(L27>=10,M27<=20),M27-L27,IF(AND(L27<=10,M27<=20,M27>=10),M27-10,IF(AND(L27>=10,M27>=20),MAX(0,20-L27),0)))) -> 0 | P27: =IF(AND(L27<=20,M27>=30),10,IF(AND(L27>=20,M27<=30),M27-L27,IF(AND(L27<=20,M27<=30,M27>=20),M27-20,IF(AND(L27>=20,M27>=30),30-L27,0)))) -> 0 | Q27: =IF(AND(L27<=30,M27>=40),10,IF(AND(L27>=30,M27<=40),M27-L27,IF(AND(L27<=30,M27<=40,M27>=30),M27-30,IF(AND(L27>=30,M27>=40),40-L27,0)))) -> 0 | W27: =IF(AND(U27<=10,V27<=10),V27-U27,MAX(0,10-U27)) -> 0 | X27: =IF(AND(U27<=10,V27>=20),10,IF(AND(U27>=10,V27<=20),V27-U27,IF(AND(U27<=10,V27<=20,V27>=10),V27-10,IF(AND(U27>=10,V27>=20),MAX(0,20-U27),0)))) -> 0 | Y27: =IF(AND(U27<=20,V27>=30),10,IF(AND(U27>=20,V27<=30),V27-U27,IF(AND(U27<=20,V27<=30,V27>=20),V27-20,IF(AND(U27>=20,V27>=30),30-U27,0)))) -> 0 | Z27: =IF(AND(U27<=30,V27>=40),10,IF(AND(U27>=30,V27<=40),V27-U27,IF(AND(U27<=30,V27<=40,V27>=30),V27-30,IF(AND(U27>=30,V27>=40),40-U27,0)))) -> 0 | AB27: =IF(T27>0, 1, 0) -> 0 | AG27: =IF(AND(AE27<=10,AF27<=10),AF27-AE27,MAX(0,10-AE27)) -> 0 | AH27: =IF(AND(AE27<=10,AF27>=20),10,IF(AND(AE27>=10,AF27<=20),AF27-AE27,IF(AND(AE27<=10,AF27<=20,AF27>=10),AF27-10,IF(AND(AE27>=10,AF27>=20),MAX(0,20-AE27),0)))) -> 0 | AI27: =IF(AND(AE27<=20,AF27>=30),10,IF(AND(AE27>=20,AF27<=30),AF27-AE27,IF(AND(AE27<=20,AF27<=30,AF27>=20),AF27-20,IF(AND(AE27>=20,AF27>=30),30-AE27,0)))) -> 0 | AJ27: =IF(AND(AE27<=30,AF27>=40),10,IF(AND(AE27>=30,AF27<=40),AF27-AE27,IF(AND(AE27<=30,AF27<=40,AF27>=30),AF27-30,IF(AND(AE27>=30,AF27>=40),40-AE27,0)))) -> 0 | AL27: =IF(AD27>0, 1, 0) -> 0 | AQ27: =IF(AND(AO27<=10,AP27<=10),AP27-AO27,MAX(0,10-AO27)) -> 0 | AR27: =IF(AND(AO27<=10,AP27>=20),10,IF(AND(AO27>=10,AP27<=20),AP27-AO27,IF(AND(AO27<=10,AP27<=20,AP27>=10),AP27-10,IF(AND(AO27>=10,AP27>=20),MAX(0,20-AO27),0)))) -> 0 | AS27: =IF(AND(AO27<=20,AP27>=30),10,IF(AND(AO27>=20,AP27<=30),AP27-AO27,IF(AND(AO27<=20,AP27<=30,AP27>=20),AP27-20,IF(AND(AO27>=20,AP27>=30),30-AO27,0)))) -> 0 | AT27: =IF(AND(AO27<=30,AP27>=40),10,IF(AND(AO27>=30,AP27<=40),AP27-AO27,IF(AND(AO27<=30,AP27<=40,AP27>=30),AP27-30,IF(AND(AO27>=30,AP27>=40),40-AO27,0)))) -> 0 | AV27: =IF(AN27>0, 1, 0) -> 0 | BA27: =IF(AND(AY27<=10,AZ27<=10),AZ27-AY27,MAX(0,10-AY27)) -> 0 | BB27: =IF(AND(AY27<=10,AZ27>=20),10,IF(AND(AY27>=10,AZ27<=20),AZ27-AY27,IF(AND(AY27<=10,AZ27<=20,AZ27>=10),AZ27-10,IF(AND(AY27>=10,AZ27>=20),MAX(0,20-AY27),0)))) -> 0 | BC27: =IF(AND(AY27<=20,AZ27>=30),10,IF(AND(AY27>=20,AZ27<=30),AZ27-AY27,IF(AND(AY27<=20,AZ27<=30,AZ27>=20),AZ27-20,IF(AND(AY27>=20,AZ27>=30),30-AY27,0)))) -> 0 | BD27: =IF(AND(AY27<=30,AZ27>=40),10,IF(AND(AY27>=30,AZ27<=40),AZ27-AY27,IF(AND(AY27<=30,AZ27<=40,AZ27>=30),AZ27-30,IF(AND(AY27>=30,AZ27>=40),40-AY27,0)))) -> 0 | BF27: =IF(AX27>0, 1, 0) -> 0 | BP27: =IF(OR(BI27="YES",BL27="YES"), 1, 0) -> 0
E28: =IF(A28= "","",1) | I28: =IF(K28>0, 1, 0) -> 0 | N28: =IF(AND(L28<=10,M28<=10),M28-L28,MAX(0,10-L28)) -> 0 | O28: =IF(AND(L28<=10,M28>=20),10,IF(AND(L28>=10,M28<=20),M28-L28,IF(AND(L28<=10,M28<=20,M28>=10),M28-10,IF(AND(L28>=10,M28>=20),MAX(0,20-L28),0)))) -> 0 | P28: =IF(AND(L28<=20,M28>=30),10,IF(AND(L28>=20,M28<=30),M28-L28,IF(AND(L28<=20,M28<=30,M28>=20),M28-20,IF(AND(L28>=20,M28>=30),30-L28,0)))) -> 0 | Q28: =IF(AND(L28<=30,M28>=40),10,IF(AND(L28>=30,M28<=40),M28-L28,IF(AND(L28<=30,M28<=40,M28>=30),M28-30,IF(AND(L28>=30,M28>=40),40-L28,0)))) -> 0 | W28: =IF(AND(U28<=10,V28<=10),V28-U28,MAX(0,10-U28)) -> 0 | X28: =IF(AND(U28<=10,V28>=20),10,IF(AND(U28>=10,V28<=20),V28-U28,IF(AND(U28<=10,V28<=20,V28>=10),V28-10,IF(AND(U28>=10,V28>=20),MAX(0,20-U28),0)))) -> 0 | Y28: =IF(AND(U28<=20,V28>=30),10,IF(AND(U28>=20,V28<=30),V28-U28,IF(AND(U28<=20,V28<=30,V28>=20),V28-20,IF(AND(U28>=20,V28>=30),MAX(0,30-U28),0)))) -> 0 | Z28: =IF(AND(U28<=30,V28>=40),10,IF(AND(U28>=30,V28<=40),V28-U28,IF(AND(U28<=30,V28<=40,V28>=30),V28-30,IF(AND(U28>=30,V28>=40),40-U28,0)))) -> 0 | AB28: =IF(T28>0, 1, 0) -> 0 | AG28: =IF(AND(AE28<=10,AF28<=10),AF28-AE28,MAX(0,10-AE28)) -> 0 | AH28: =IF(AND(AE28<=10,AF28>=20),10,IF(AND(AE28>=10,AF28<=20),AF28-AE28,IF(AND(AE28<=10,AF28<=20,AF28>=10),AF28-10,IF(AND(AE28>=10,AF28>=20),MAX(0,20-AE28),0)))) -> 0 | AI28: =IF(AND(AE28<=20,AF28>=30),10,IF(AND(AE28>=20,AF28<=30),AF28-AE28,IF(AND(AE28<=20,AF28<=30,AF28>=20),AF28-20,IF(AND(AE28>=20,AF28>=30),30-AE28,0)))) -> 0 | AJ28: =IF(AND(AE28<=30,AF28>=40),10,IF(AND(AE28>=30,AF28<=40),AF28-AE28,IF(AND(AE28<=30,AF28<=40,AF28>=30),AF28-30,IF(AND(AE28>=30,AF28>=40),40-AE28,0)))) -> 0 | AL28: =IF(AD28>0, 1, 0) -> 0 | AQ28: =IF(AND(AO28<=10,AP28<=10),AP28-AO28,MAX(0,10-AO28)) -> 0 | AR28: =IF(AND(AO28<=10,AP28>=20),10,IF(AND(AO28>=10,AP28<=20),AP28-AO28,IF(AND(AO28<=10,AP28<=20,AP28>=10),AP28-10,IF(AND(AO28>=10,AP28>=20),MAX(0,20-AO28),0)))) -> 0 | AS28: =IF(AND(AO28<=20,AP28>=30),10,IF(AND(AO28>=20,AP28<=30),AP28-AO28,IF(AND(AO28<=20,AP28<=30,AP28>=20),AP28-20,IF(AND(AO28>=20,AP28>=30),MAX(0,30-AO28),0)))) -> 0 | AT28: =IF(AND(AO28<=30,AP28>=40),10,IF(AND(AO28>=30,AP28<=40),AP28-AO28,IF(AND(AO28<=30,AP28<=40,AP28>=30),AP28-30,IF(AND(AO28>=30,AP28>=40),40-AO28,0)))) -> 0 | AV28: =IF(AN28>0, 1, 0) -> 0 | BA28: =IF(AND(AY28<=10,AZ28<=10),AZ28-AY28,MAX(0,10-AY28)) -> 0 | BB28: =IF(AND(AY28<=10,AZ28>=20),10,IF(AND(AY28>=10,AZ28<=20),AZ28-AY28,IF(AND(AY28<=10,AZ28<=20,AZ28>=10),AZ28-10,IF(AND(AY28>=10,AZ28>=20),MAX(0,20-AY28),0)))) -> 0 | BC28: =IF(AND(AY28<=20,AZ28>=30),10,IF(AND(AY28>=20,AZ28<=30),AZ28-AY28,IF(AND(AY28<=20,AZ28<=30,AZ28>=20),AZ28-20,IF(AND(AY28>=20,AZ28>=30),30-AY28,0)))) -> 0 | BD28: =IF(AND(AY28<=30,AZ28>=40),10,IF(AND(AY28>=30,AZ28<=40),AZ28-AY28,IF(AND(AY28<=30,AZ28<=40,AZ28>=30),AZ28-30,IF(AND(AY28>=30,AZ28>=40),40-AY28,0)))) -> 0 | BF28: =IF(AX28>0, 1, 0) -> 0 | BP28: =IF(OR(BI28="YES",BL28="YES"), 1, 0) -> 0
E29: =IF(A29= "","",1) | I29: =IF(K29>0, 1, 0) -> 0 | N29: =IF(AND(L29<=10,M29<=10),M29-L29,MAX(0,10-L29)) -> 0 | O29: =IF(AND(L29<=10,M29>=20),10,IF(AND(L29>=10,M29<=20),M29-L29,IF(AND(L29<=10,M29<=20,M29>=10),M29-10,IF(AND(L29>=10,M29>=20),MAX(0,20-L29),0)))) -> 0 | P29: =IF(AND(L29<=20,M29>=30),10,IF(AND(L29>=20,M29<=30),M29-L29,IF(AND(L29<=20,M29<=30,M29>=20),M29-20,IF(AND(L29>=20,M29>=30),30-L29,0)))) -> 0 | Q29: =IF(AND(L29<=30,M29>=40),10,IF(AND(L29>=30,M29<=40),M29-L29,IF(AND(L29<=30,M29<=40,M29>=30),M29-30,IF(AND(L29>=30,M29>=40),40-L29,0)))) -> 0 | W29: =IF(AND(U29<=10,V29<=10),V29-U29,MAX(0,10-U29)) -> 0 | X29: =IF(AND(U29<=10,V29>=20),10,IF(AND(U29>=10,V29<=20),V29-U29,IF(AND(U29<=10,V29<=20,V29>=10),V29-10,IF(AND(U29>=10,V29>=20),MAX(0,20-U29),0)))) -> 0 | Y29: =IF(AND(U29<=20,V29>=30),10,IF(AND(U29>=20,V29<=30),V29-U29,IF(AND(U29<=20,V29<=30,V29>=20),V29-20,IF(AND(U29>=20,V29>=30),30-U29,0)))) -> 0 | Z29: =IF(AND(U29<=30,V29>=40),10,IF(AND(U29>=30,V29<=40),V29-U29,IF(AND(U29<=30,V29<=40,V29>=30),V29-30,IF(AND(U29>=30,V29>=40),40-U29,0)))) -> 0 | AB29: =IF(T29>0, 1, 0) -> 0 | AG29: =IF(AND(AE29<=10,AF29<=10),AF29-AE29,MAX(0,10-AE29)) -> 0 | AH29: =IF(AND(AE29<=10,AF29>=20),10,IF(AND(AE29>=10,AF29<=20),AF29-AE29,IF(AND(AE29<=10,AF29<=20,AF29>=10),AF29-10,IF(AND(AE29>=10,AF29>=20),MAX(0,20-AE29),0)))) -> 0 | AI29: =IF(AND(AE29<=20,AF29>=30),10,IF(AND(AE29>=20,AF29<=30),AF29-AE29,IF(AND(AE29<=20,AF29<=30,AF29>=20),AF29-20,IF(AND(AE29>=20,AF29>=30),30-AE29,0)))) -> 0 | AJ29: =IF(AND(AE29<=30,AF29>=40),10,IF(AND(AE29>=30,AF29<=40),AF29-AE29,IF(AND(AE29<=30,AF29<=40,AF29>=30),AF29-30,IF(AND(AE29>=30,AF29>=40),40-AE29,0)))) -> 0 | AL29: =IF(AD29>0, 1, 0) -> 0 | AQ29: =IF(AND(AO29<=10,AP29<=10),AP29-AO29,MAX(0,10-AO29)) -> 0 | AR29: =IF(AND(AO29<=10,AP29>=20),10,IF(AND(AO29>=10,AP29<=20),AP29-AO29,IF(AND(AO29<=10,AP29<=20,AP29>=10),AP29-10,IF(AND(AO29>=10,AP29>=20),MAX(0,20-AO29),0)))) -> 0 | AS29: =IF(AND(AO29<=20,AP29>=30),10,IF(AND(AO29>=20,AP29<=30),AP29-AO29,IF(AND(AO29<=20,AP29<=30,AP29>=20),AP29-20,IF(AND(AO29>=20,AP29>=30),30-AO29,0)))) -> 0 | AT29: =IF(AND(AO29<=30,AP29>=40),10,IF(AND(AO29>=30,AP29<=40),AP29-AO29,IF(AND(AO29<=30,AP29<=40,AP29>=30),AP29-30,IF(AND(AO29>=30,AP29>=40),40-AO29,0)))) -> 0 | AV29: =IF(AN29>0, 1, 0) -> 0 | BA29: =IF(AND(AY29<=10,AZ29<=10),AZ29-AY29,MAX(0,10-AY29)) -> 0 | BB29: =IF(AND(AY29<=10,AZ29>=20),10,IF(AND(AY29>=10,AZ29<=20),AZ29-AY29,IF(AND(AY29<=10,AZ29<=20,AZ29>=10),AZ29-10,IF(AND(AY29>=10,AZ29>=20),MAX(0,20-AY29),0)))) -> 0 | BC29: =IF(AND(AY29<=20,AZ29>=30),10,IF(AND(AY29>=20,AZ29<=30),AZ29-AY29,IF(AND(AY29<=20,AZ29<=30,AZ29>=20),AZ29-20,IF(AND(AY29>=20,AZ29>=30),30-AY29,0)))) -> 0 | BD29: =IF(AND(AY29<=30,AZ29>=40),10,IF(AND(AY29>=30,AZ29<=40),AZ29-AY29,IF(AND(AY29<=30,AZ29<=40,AZ29>=30),AZ29-30,IF(AND(AY29>=30,AZ29>=40),40-AY29,0)))) -> 0 | BF29: =IF(AX29>0, 1, 0) -> 0 | BP29: =IF(OR(BI29="YES",BL29="YES"), 1, 0) -> 0
E30: =IF(A30= "","",1) | I30: =IF(K30>0, 1, 0) -> 0 | N30: =IF(AND(L30<=10,M30<=10),M30-L30,MAX(0,10-L30)) -> 0 | O30: =IF(AND(L30<=10,M30>=20),10,IF(AND(L30>=10,M30<=20),M30-L30,IF(AND(L30<=10,M30<=20,M30>=10),M30-10,IF(AND(L30>=10,M30>=20),MAX(0,20-L30),0)))) -> 0 | P30: =IF(AND(L30<=20,M30>=30),10,IF(AND(L30>=20,M30<=30),M30-L30,IF(AND(L30<=20,M30<=30,M30>=20),M30-20,IF(AND(L30>=20,M30>=30),30-L30,0)))) -> 0 | Q30: =IF(AND(L30<=30,M30>=40),10,IF(AND(L30>=30,M30<=40),M30-L30,IF(AND(L30<=30,M30<=40,M30>=30),M30-30,IF(AND(L30>=30,M30>=40),40-L30,0)))) -> 0 | W30: =IF(AND(U30<=10,V30<=10),V30-U30,MAX(0,10-U30)) -> 0 | X30: =IF(AND(U30<=10,V30>=20),10,IF(AND(U30>=10,V30<=20),V30-U30,IF(AND(U30<=10,V30<=20,V30>=10),V30-10,IF(AND(U30>=10,V30>=20),MAX(0,20-U30),0)))) -> 0 | Y30: =IF(AND(U30<=20,V30>=30),10,IF(AND(U30>=20,V30<=30),V30-U30,IF(AND(U30<=20,V30<=30,V30>=20),V30-20,IF(AND(U30>=20,V30>=30),30-U30,0)))) -> 0 | Z30: =IF(AND(U30<=30,V30>=40),10,IF(AND(U30>=30,V30<=40),V30-U30,IF(AND(U30<=30,V30<=40,V30>=30),V30-30,IF(AND(U30>=30,V30>=40),40-U30,0)))) -> 0 | AB30: =IF(T30>0, 1, 0) -> 0 | AG30: =IF(AND(AE30<=10,AF30<=10),AF30-AE30,MAX(0,10-AE30)) -> 0 | AH30: =IF(AND(AE30<=10,AF30>=20),10,IF(AND(AE30>=10,AF30<=20),AF30-AE30,IF(AND(AE30<=10,AF30<=20,AF30>=10),AF30-10,IF(AND(AE30>=10,AF30>=20),MAX(0,20-AE30),0)))) -> 0 | AI30: =IF(AND(AE30<=20,AF30>=30),10,IF(AND(AE30>=20,AF30<=30),AF30-AE30,IF(AND(AE30<=20,AF30<=30,AF30>=20),AF30-20,IF(AND(AE30>=20,AF30>=30),30-AE30,0)))) -> 0 | AJ30: =IF(AND(AE30<=30,AF30>=40),10,IF(AND(AE30>=30,AF30<=40),AF30-AE30,IF(AND(AE30<=30,AF30<=40,AF30>=30),AF30-30,IF(AND(AE30>=30,AF30>=40),40-AE30,0)))) -> 0 | AL30: =IF(AD30>0, 1, 0) -> 0 | AQ30: =IF(AND(AO30<=10,AP30<=10),AP30-AO30,MAX(0,10-AO30)) -> 0 | AR30: =IF(AND(AO30<=10,AP30>=20),10,IF(AND(AO30>=10,AP30<=20),AP30-AO30,IF(AND(AO30<=10,AP30<=20,AP30>=10),AP30-10,IF(AND(AO30>=10,AP30>=20),MAX(0,20-AO30),0)))) -> 0 | AS30: =IF(AND(AO30<=20,AP30>=30),10,IF(AND(AO30>=20,AP30<=30),AP30-AO30,IF(AND(AO30<=20,AP30<=30,AP30>=20),AP30-20,IF(AND(AO30>=20,AP30>=30),30-AO30,0)))) -> 0 | AT30: =IF(AND(AO30<=30,AP30>=40),10,IF(AND(AO30>=30,AP30<=40),AP30-AO30,IF(AND(AO30<=30,AP30<=40,AP30>=30),AP30-30,IF(AND(AO30>=30,AP30>=40),40-AO30,0)))) -> 0 | AV30: =IF(AN30>0, 1, 0) -> 0 | BA30: =IF(AND(AY30<=10,AZ30<=10),AZ30-AY30,MAX(0,10-AY30)) -> 0 | BB30: =IF(AND(AY30<=10,AZ30>=20),10,IF(AND(AY30>=10,AZ30<=20),AZ30-AY30,IF(AND(AY30<=10,AZ30<=20,AZ30>=10),AZ30-10,IF(AND(AY30>=10,AZ30>=20),MAX(0,20-AY30),0)))) -> 0 | BC30: =IF(AND(AY30<=20,AZ30>=30),10,IF(AND(AY30>=20,AZ30<=30),AZ30-AY30,IF(AND(AY30<=20,AZ30<=30,AZ30>=20),AZ30-20,IF(AND(AY30>=20,AZ30>=30),30-AY30,0)))) -> 0 | BD30: =IF(AND(AY30<=30,AZ30>=40),10,IF(AND(AY30>=30,AZ30<=40),AZ30-AY30,IF(AND(AY30<=30,AZ30<=40,AZ30>=30),AZ30-30,IF(AND(AY30>=30,AZ30>=40),40-AY30,0)))) -> 0 | BF30: =IF(AX30>0, 1, 0) -> 0 | BP30: =IF(OR(BI30="YES",BL30="YES"), 1, 0) -> 0
E31: =IF(A31= "","",1) | I31: =IF(K31>0, 1, 0) -> 0 | N31: =IF(AND(L31<=10,M31<=10),M31-L31,MAX(0,10-L31)) -> 0 | O31: =IF(AND(L31<=10,M31>=20),10,IF(AND(L31>=10,M31<=20),M31-L31,IF(AND(L31<=10,M31<=20,M31>=10),M31-10,IF(AND(L31>=10,M31>=20),MAX(0,20-L31),0)))) -> 0 | P31: =IF(AND(L31<=20,M31>=30),10,IF(AND(L31>=20,M31<=30),M31-L31,IF(AND(L31<=20,M31<=30,M31>=20),M31-20,IF(AND(L31>=20,M31>=30),30-L31,0)))) -> 0 | Q31: =IF(AND(L31<=30,M31>=40),10,IF(AND(L31>=30,M31<=40),M31-L31,IF(AND(L31<=30,M31<=40,M31>=30),M31-30,IF(AND(L31>=30,M31>=40),40-L31,0)))) -> 0 | W31: =IF(AND(U31<=10,V31<=10),V31-U31,MAX(0,10-U31)) -> 0 | X31: =IF(AND(U31<=10,V31>=20),10,IF(AND(U31>=10,V31<=20),V31-U31,IF(AND(U31<=10,V31<=20,V31>=10),V31-10,IF(AND(U31>=10,V31>=20),MAX(0,20-U31),0)))) -> 0 | Y31: =IF(AND(U31<=20,V31>=30),10,IF(AND(U31>=20,V31<=30),V31-U31,IF(AND(U31<=20,V31<=30,V31>=20),V31-20,IF(AND(U31>=20,V31>=30),30-U31,0)))) -> 0 | Z31: =IF(AND(U31<=30,V31>=40),10,IF(AND(U31>=30,V31<=40),V31-U31,IF(AND(U31<=30,V31<=40,V31>=30),V31-30,IF(AND(U31>=30,V31>=40),40-U31,0)))) -> 0 | AB31: =IF(T31>0, 1, 0) -> 0 | AG31: =IF(AND(AE31<=10,AF31<=10),AF31-AE31,MAX(0,10-AE31)) -> 0 | AH31: =IF(AND(AE31<=10,AF31>=20),10,IF(AND(AE31>=10,AF31<=20),AF31-AE31,IF(AND(AE31<=10,AF31<=20,AF31>=10),AF31-10,IF(AND(AE31>=10,AF31>=20),MAX(0,20-AE31),0)))) -> 0 | AI31: =IF(AND(AE31<=20,AF31>=30),10,IF(AND(AE31>=20,AF31<=30),AF31-AE31,IF(AND(AE31<=20,AF31<=30,AF31>=20),AF31-20,IF(AND(AE31>=20,AF31>=30),30-AE31,0)))) -> 0 | AJ31: =IF(AND(AE31<=30,AF31>=40),10,IF(AND(AE31>=30,AF31<=40),AF31-AE31,IF(AND(AE31<=30,AF31<=40,AF31>=30),AF31-30,IF(AND(AE31>=30,AF31>=40),40-AE31,0)))) -> 0 | AL31: =IF(AD31>0, 1, 0) -> 0 | AQ31: =IF(AND(AO31<=10,AP31<=10),AP31-AO31,MAX(0,10-AO31)) -> 0 | AR31: =IF(AND(AO31<=10,AP31>=20),10,IF(AND(AO31>=10,AP31<=20),AP31-AO31,IF(AND(AO31<=10,AP31<=20,AP31>=10),AP31-10,IF(AND(AO31>=10,AP31>=20),MAX(0,20-AO31),0)))) -> 0 | AS31: =IF(AND(AO31<=20,AP31>=30),10,IF(AND(AO31>=20,AP31<=30),AP31-AO31,IF(AND(AO31<=20,AP31<=30,AP31>=20),AP31-20,IF(AND(AO31>=20,AP31>=30),30-AO31,0)))) -> 0 | AT31: =IF(AND(AO31<=30,AP31>=40),10,IF(AND(AO31>=30,AP31<=40),AP31-AO31,IF(AND(AO31<=30,AP31<=40,AP31>=30),AP31-30,IF(AND(AO31>=30,AP31>=40),40-AO31,0)))) -> 0 | AV31: =IF(AN31>0, 1, 0) -> 0 | BA31: =IF(AND(AY31<=10,AZ31<=10),AZ31-AY31,MAX(0,10-AY31)) -> 0 | BB31: =IF(AND(AY31<=10,AZ31>=20),10,IF(AND(AY31>=10,AZ31<=20),AZ31-AY31,IF(AND(AY31<=10,AZ31<=20,AZ31>=10),AZ31-10,IF(AND(AY31>=10,AZ31>=20),MAX(0,20-AY31),0)))) -> 0 | BC31: =IF(AND(AY31<=20,AZ31>=30),10,IF(AND(AY31>=20,AZ31<=30),AZ31-AY31,IF(AND(AY31<=20,AZ31<=30,AZ31>=20),AZ31-20,IF(AND(AY31>=20,AZ31>=30),30-AY31,0)))) -> 0 | BD31: =IF(AND(AY31<=30,AZ31>=40),10,IF(AND(AY31>=30,AZ31<=40),AZ31-AY31,IF(AND(AY31<=30,AZ31<=40,AZ31>=30),AZ31-30,IF(AND(AY31>=30,AZ31>=40),40-AY31,0)))) -> 0 | BF31: =IF(AX31>0, 1, 0) -> 0 | BP31: =IF(OR(BI31="YES",BL31="YES"), 1, 0) -> 0
E32: =IF(A32= "","",1) | I32: =IF(K32>0, 1, 0) -> 0 | N32: =IF(AND(L32<=10,M32<=10),M32-L32,MAX(0,10-L32)) -> 0 | O32: =IF(AND(L32<=10,M32>=20),10,IF(AND(L32>=10,M32<=20),M32-L32,IF(AND(L32<=10,M32<=20,M32>=10),M32-10,IF(AND(L32>=10,M32>=20),MAX(0,20-L32),0)))) -> 0 | P32: =IF(AND(L32<=20,M32>=30),10,IF(AND(L32>=20,M32<=30),M32-L32,IF(AND(L32<=20,M32<=30,M32>=20),M32-20,IF(AND(L32>=20,M32>=30),30-L32,0)))) -> 0 | Q32: =IF(AND(L32<=30,M32>=40),10,IF(AND(L32>=30,M32<=40),M32-L32,IF(AND(L32<=30,M32<=40,M32>=30),M32-30,IF(AND(L32>=30,M32>=40),40-L32,0)))) -> 0 | W32: =IF(AND(U32<=10,V32<=10),V32-U32,MAX(0,10-U32)) -> 0 | X32: =IF(AND(U32<=10,V32>=20),10,IF(AND(U32>=10,V32<=20),V32-U32,IF(AND(U32<=10,V32<=20,V32>=10),V32-10,IF(AND(U32>=10,V32>=20),MAX(0,20-U32),0)))) -> 0 | Y32: =IF(AND(U32<=20,V32>=30),10,IF(AND(U32>=20,V32<=30),V32-U32,IF(AND(U32<=20,V32<=30,V32>=20),V32-20,IF(AND(U32>=20,V32>=30),30-U32,0)))) -> 0 | Z32: =IF(AND(U32<=30,V32>=40),10,IF(AND(U32>=30,V32<=40),V32-U32,IF(AND(U32<=30,V32<=40,V32>=30),V32-30,IF(AND(U32>=30,V32>=40),40-U32,0)))) -> 0 | AB32: =IF(T32>0, 1, 0) -> 0 | AG32: =IF(AND(AE32<=10,AF32<=10),AF32-AE32,MAX(0,10-AE32)) -> 0 | AH32: =IF(AND(AE32<=10,AF32>=20),10,IF(AND(AE32>=10,AF32<=20),AF32-AE32,IF(AND(AE32<=10,AF32<=20,AF32>=10),AF32-10,IF(AND(AE32>=10,AF32>=20),MAX(0,20-AE32),0)))) -> 0 | AI32: =IF(AND(AE32<=20,AF32>=30),10,IF(AND(AE32>=20,AF32<=30),AF32-AE32,IF(AND(AE32<=20,AF32<=30,AF32>=20),AF32-20,IF(AND(AE32>=20,AF32>=30),30-AE32,0)))) -> 0 | AJ32: =IF(AND(AE32<=30,AF32>=40),10,IF(AND(AE32>=30,AF32<=40),AF32-AE32,IF(AND(AE32<=30,AF32<=40,AF32>=30),AF32-30,IF(AND(AE32>=30,AF32>=40),40-AE32,0)))) -> 0 | AL32: =IF(AD32>0, 1, 0) -> 0 | AQ32: =IF(AND(AO32<=10,AP32<=10),AP32-AO32,MAX(0,10-AO32)) -> 0 | AR32: =IF(AND(AO32<=10,AP32>=20),10,IF(AND(AO32>=10,AP32<=20),AP32-AO32,IF(AND(AO32<=10,AP32<=20,AP32>=10),AP32-10,IF(AND(AO32>=10,AP32>=20),MAX(0,20-AO32),0)))) -> 0 | AS32: =IF(AND(AO32<=20,AP32>=30),10,IF(AND(AO32>=20,AP32<=30),AP32-AO32,IF(AND(AO32<=20,AP32<=30,AP32>=20),AP32-20,IF(AND(AO32>=20,AP32>=30),30-AO32,0)))) -> 0 | AT32: =IF(AND(AO32<=30,AP32>=40),10,IF(AND(AO32>=30,AP32<=40),AP32-AO32,IF(AND(AO32<=30,AP32<=40,AP32>=30),AP32-30,IF(AND(AO32>=30,AP32>=40),40-AO32,0)))) -> 0 | AV32: =IF(AN32>0, 1, 0) -> 0 | BA32: =IF(AND(AY32<=10,AZ32<=10),AZ32-AY32,MAX(0,10-AY32)) -> 0 | BB32: =IF(AND(AY32<=10,AZ32>=20),10,IF(AND(AY32>=10,AZ32<=20),AZ32-AY32,IF(AND(AY32<=10,AZ32<=20,AZ32>=10),AZ32-10,IF(AND(AY32>=10,AZ32>=20),MAX(0,20-AY32),0)))) -> 0 | BC32: =IF(AND(AY32<=20,AZ32>=30),10,IF(AND(AY32>=20,AZ32<=30),AZ32-AY32,IF(AND(AY32<=20,AZ32<=30,AZ32>=20),AZ32-20,IF(AND(AY32>=20,AZ32>=30),30-AY32,0)))) -> 0 | BD32: =IF(AND(AY32<=30,AZ32>=40),10,IF(AND(AY32>=30,AZ32<=40),AZ32-AY32,IF(AND(AY32<=30,AZ32<=40,AZ32>=30),AZ32-30,IF(AND(AY32>=30,AZ32>=40),40-AY32,0)))) -> 0 | BF32: =IF(AX32>0, 1, 0) -> 0 | BP32: =IF(OR(BI32="YES",BL32="YES"), 1, 0) -> 0
E33: =IF(A33= "","",1) | I33: =IF(K33>0, 1, 0) -> 0 | N33: =IF(AND(L33<=10,M33<=10),M33-L33,MAX(0,10-L33)) -> 0 | O33: =IF(AND(L33<=10,M33>=20),10,IF(AND(L33>=10,M33<=20),M33-L33,IF(AND(L33<=10,M33<=20,M33>=10),M33-10,IF(AND(L33>=10,M33>=20),MAX(0,20-L33),0)))) -> 0 | P33: =IF(AND(L33<=20,M33>=30),10,IF(AND(L33>=20,M33<=30),M33-L33,IF(AND(L33<=20,M33<=30,M33>=20),M33-20,IF(AND(L33>=20,M33>=30),30-L33,0)))) -> 0 | Q33: =IF(AND(L33<=30,M33>=40),10,IF(AND(L33>=30,M33<=40),M33-L33,IF(AND(L33<=30,M33<=40,M33>=30),M33-30,IF(AND(L33>=30,M33>=40),40-L33,0)))) -> 0 | W33: =IF(AND(U33<=10,V33<=10),V33-U33,MAX(0,10-U33)) -> 0 | X33: =IF(AND(U33<=10,V33>=20),10,IF(AND(U33>=10,V33<=20),V33-U33,IF(AND(U33<=10,V33<=20,V33>=10),V33-10,IF(AND(U33>=10,V33>=20),MAX(0,20-U33),0)))) -> 0 | Y33: =IF(AND(U33<=20,V33>=30),10,IF(AND(U33>=20,V33<=30),V33-U33,IF(AND(U33<=20,V33<=30,V33>=20),V33-20,IF(AND(U33>=20,V33>=30),30-U33,0)))) -> 0 | Z33: =IF(AND(U33<=30,V33>=40),10,IF(AND(U33>=30,V33<=40),V33-U33,IF(AND(U33<=30,V33<=40,V33>=30),V33-30,IF(AND(U33>=30,V33>=40),40-U33,0)))) -> 0 | AB33: =IF(T33>0, 1, 0) -> 0 | AG33: =IF(AND(AE33<=10,AF33<=10),AF33-AE33,MAX(0,10-AE33)) -> 0 | AH33: =IF(AND(AE33<=10,AF33>=20),10,IF(AND(AE33>=10,AF33<=20),AF33-AE33,IF(AND(AE33<=10,AF33<=20,AF33>=10),AF33-10,IF(AND(AE33>=10,AF33>=20),MAX(0,20-AE33),0)))) -> 0 | AI33: =IF(AND(AE33<=20,AF33>=30),10,IF(AND(AE33>=20,AF33<=30),AF33-AE33,IF(AND(AE33<=20,AF33<=30,AF33>=20),AF33-20,IF(AND(AE33>=20,AF33>=30),30-AE33,0)))) -> 0 | AJ33: =IF(AND(AE33<=30,AF33>=40),10,IF(AND(AE33>=30,AF33<=40),AF33-AE33,IF(AND(AE33<=30,AF33<=40,AF33>=30),AF33-30,IF(AND(AE33>=30,AF33>=40),40-AE33,0)))) -> 0 | AL33: =IF(AD33>0, 1, 0) -> 0 | AQ33: =IF(AND(AO33<=10,AP33<=10),AP33-AO33,MAX(0,10-AO33)) -> 0 | AR33: =IF(AND(AO33<=10,AP33>=20),10,IF(AND(AO33>=10,AP33<=20),AP33-AO33,IF(AND(AO33<=10,AP33<=20,AP33>=10),AP33-10,IF(AND(AO33>=10,AP33>=20),MAX(0,20-AO33),0)))) -> 0 | AS33: =IF(AND(AO33<=20,AP33>=30),10,IF(AND(AO33>=20,AP33<=30),AP33-AO33,IF(AND(AO33<=20,AP33<=30,AP33>=20),AP33-20,IF(AND(AO33>=20,AP33>=30),30-AO33,0)))) -> 0 | AT33: =IF(AND(AO33<=30,AP33>=40),10,IF(AND(AO33>=30,AP33<=40),AP33-AO33,IF(AND(AO33<=30,AP33<=40,AP33>=30),AP33-30,IF(AND(AO33>=30,AP33>=40),40-AO33,0)))) -> 0 | AV33: =IF(AN33>0, 1, 0) -> 0 | BA33: =IF(AND(AY33<=10,AZ33<=10),AZ33-AY33,MAX(0,10-AY33)) -> 0 | BB33: =IF(AND(AY33<=10,AZ33>=20),10,IF(AND(AY33>=10,AZ33<=20),AZ33-AY33,IF(AND(AY33<=10,AZ33<=20,AZ33>=10),AZ33-10,IF(AND(AY33>=10,AZ33>=20),MAX(0,20-AY33),0)))) -> 0 | BC33: =IF(AND(AY33<=20,AZ33>=30),10,IF(AND(AY33>=20,AZ33<=30),AZ33-AY33,IF(AND(AY33<=20,AZ33<=30,AZ33>=20),AZ33-20,IF(AND(AY33>=20,AZ33>=30),30-AY33,0)))) -> 0 | BD33: =IF(AND(AY33<=30,AZ33>=40),10,IF(AND(AY33>=30,AZ33<=40),AZ33-AY33,IF(AND(AY33<=30,AZ33<=40,AZ33>=30),AZ33-30,IF(AND(AY33>=30,AZ33>=40),40-AY33,0)))) -> 0 | BF33: =IF(AX33>0, 1, 0) -> 0 | BP33: =IF(OR(BI33="YES",BL33="YES"), 1, 0) -> 0
