Workbook

Sheet Section A
H3: Orange cells need manual inputs. If item is not needed then "Not Required" is to be inserted in cell.
H4: The grey cells w/ orange text/figures are taken from the calculator speadsheet.
H5: Any grey cell with "Not Required" in it, is a result of a quantity of 0 being calculated from log tracker & calculator.
H6: The quantities here are transferred to a final version for the contractor in PART 4 to achieve a simple bill where the contractor just needs to input their rates.
A7: Number | B7: Item description | C7: Unit | D7: Quantity | E7: Rate | F7: Amount
E8: € | F8: € | H8: If Figures are not updating from '2 BOQ Calculator' then go to 'Data' tab, click on 'Edit Links' , then click 'Update Values'.
A9: A | B9: General items, provisional services and additional items
A10: A1 | B10: Offices and stores for the Contractor | C10: sum | D10: 1 | E10: =IF(ISNUMBER(D10),"-","N/A") -> - | F10: =IF(ISNUMBER(D10),"","-") | H10: NOTE: If calculated quantities (grey cells) need to be changed manually, once changed the cell will break it's link to the calculator.
A11: A2 | B11: Establish on site all plant, equipment and services for a Green Category site | C11: sum | D11: Not Required | E11: =IF(ISNUMBER(D11),"","N/A") -> N/A | F11: =IF(ISNUMBER(D11),"","-") -> -
A12: A2.1 | B12: Establish on site cable percussion ('shell l auger') boring plant and equipment for a Green Category site | C12: sum | D12: Not Required | E12: =IF(ISNUMBER(D12),"","N/A") -> N/A | F12: =IF(ISNUMBER(D12),"","-") -> - | K12: Ensure No Blank cells are left when completing
A13: A2.2 | B13: Establish on site rotary drilling plant and equipment for a Green Category site | C13: sum | D13: Not Required | E13: =IF(ISNUMBER(D13),"","N/A") -> N/A | F13: =IF(ISNUMBER(D13),"","-") -> - | K13: Enter a figure into the orange cells manually or paste in "Not Reruired"
A14: A2.3 | B14: Establish on site Geobor S rotary drilling plant and equipment for a Green Category site (Provisional) | C14: sum | D14: Not Required | E14: =IF(ISNUMBER(D14),"","N/A") -> N/A | F14: =IF(ISNUMBER(D14),"","-") -> -
A15: A2.4 | B15: Establish on site trial pitting and trenching plant and equipment for a Green Category site | C15: sum | D15: Not Required | E15: =IF(ISNUMBER(D15),"","N/A") -> N/A | F15: =IF(ISNUMBER(D15),"","-") -> - | K15: READ ABOVE!!!
A16: A2.5 | B16: Establish on site in situ test and sampling equipment for a Green Category site | C16: sum | D16: Not Required | E16: =IF(ISNUMBER(D16),"","N/A") -> N/A | F16: =IF(ISNUMBER(D16),"","-") -> -
A17: A2.6 | B17: Establish on site cone penetration testing (CPT) plant and equipment for a Green Category site | C17: sum | D17: Not Required | E17: =IF(ISNUMBER(D17),"","N/A") -> N/A | F17: =IF(ISNUMBER(D17),"","-") -> -
A18: A2.7 | B18: Establish on site dynamic sampling and probing plant and equipment for a Green Category site | C18: sum | D18: Not Required | E18: =IF(ISNUMBER(D18),"","N/A") -> N/A | F18: =IF(ISNUMBER(D18),"","-") -> -
A19: A2.8 | B19: Establish on site geophysical survey equipment for a Green Category site | C19: sum | D19: Not Required | E19: =IF(ISNUMBER(D19),"","N/A") -> N/A | F19: =IF(ISNUMBER(D19),"","-") -> -
A20: A2.9 | B20: Establish on site instrumentation equipment as required for a Green Category site | C20: sum | D20: Not Required | E20: =IF(ISNUMBER(D20),"","N/A") -> N/A | F20: =IF(ISNUMBER(D20),"","-") -> -
A21: A3.1 | B21: Extra over item A2.1 - A2.9 for a yellow category site | C21: sum | D21: Not Required | E21: =IF(ISNUMBER(D21),"","N/A") -> N/A | F21: =IF(ISNUMBER(D21),"","-") -> -
A22: A3.2 | B22: As Item A3.1 but for a Red Category site | C22: provisional sum | D22: Not Required | E22: =IF(ISNUMBER(D22),"","N/A") -> N/A | F22: =IF(ISNUMBER(D22),"","-") -> -
A23: A4.1 | B23: Maintain on site all site safety equipment for a Yellow Category site | C23: provisional sum | D23: Included in Item 3.1 | E23: =IF(ISNUMBER(D23),"-","N/A") -> N/A | F23: =IF(ISNUMBER(D23),"","-") -> -
A24: A4.2 | B24: Maintain on site all site safety equipment for a Red Category site (PROVISIONAL) | C24: provisional sum | D24: Not Required | E24: =IF(ISNUMBER(D24),"-","N/A") -> N/A | F24: =IF(ISNUMBER(D24),"","-") -> -
A25: A5.1 | B25: Decontamination of equipment during and at end of intrusive investigation for a Yellow Category site | C25: provisional sum | D25: Included in Item 3.1 | E25: =IF(ISNUMBER(D25),"-","N/A") -> N/A | F25: =IF(ISNUMBER(D25),"","-") -> -
A26: A5.2 | B26: Decontamination of equipment during and at end of intrusive investigation for a Red Category site (PROVISIONAL) | C26: provisional sum | D26: Not Required | E26: =IF(ISNUMBER(D26),"","N/A") -> N/A | F26: =IF(ISNUMBER(D26),"","-") -> -
A27: A6 | B27: Appropriate storage, transport and off-site disposal of excess contaminated arising’s from borehole, trial pit or slit trench to EPA regulated landfill site (includes any PPE equipment but excludes laboratory testing on suspected contaminated materials). Note item to be remeasured with delivery dockets and records maintained by the Contractor [PROVISIONAL] | C27: provisional sum | D27: 1 | E27: =IF(ISNUMBER(D27),"-","N/A") -> -
A28: A6.1 | B28: Contractor's uplift on Item A6 | C28: % | D28: Not Required | E28: =IF(ISNUMBER(D28),"-","N/A") -> N/A | F28: =IF(ISNUMBER(D28),"","-") -> -
A29: A7 | B29: Provide professional attendance to meet the contract requirements | C29: sum | D29: 1 | E29: =IF(ISNUMBER(D29),"-","N/A") -> - | F29: =IF(ISNUMBER(D29),"","-")
A30: A7.1 | B30: Provide Technician | C30: per day | D30: Included in A7 | E30: =IF(ISNUMBER(D30),"-","N/A") -> N/A | F30: =IF(ISNUMBER(D30),"","-") -> -
A31: A7.2 | B31: Provide Engineer / Geologist (as per item 2.3 of Specification) | C31: per day | D31: Included in A7 | E31: =IF(ISNUMBER(D31),"-","N/A") -> N/A | F31: =IF(ISNUMBER(D31),"","-") -> -
A32: A7.3 | B32: Provide Chartered Engineer / Professional Geologist (as item 2.3 of Specification) | C32: per day | D32: Included in A7 | E32: =IF(ISNUMBER(D32),"-","N/A") -> N/A | F32: =IF(ISNUMBER(D32),"","-") -> -
A33: A7.4 | B33: Provide Chartered Engineer / Professional Geologist (+10 years experience post charter) | C33: per day | D33: Included in A7 | E33: =IF(ISNUMBER(D33),"-","N/A") -> N/A | F33: =IF(ISNUMBER(D33),"","-") -> -
A34: A7.5 | B34: Provide Chartered Engineer / Professional Geologist (+20 years experience post charter) | C34: per day | D34: Included in A7 | E34: =IF(ISNUMBER(D34),"-","N/A") -> N/A | F34: =IF(ISNUMBER(D34),"","-") -> -
A35: A8 | B35: Set out the location at each exploratory hole or point | C35: Nr | D35: ='[1]Section A'!$D$35 -> 0 | E35: =IF(ISNUMBER(D35),"","N/A") | F35: =IF(ISNUMBER(D35),"","-")
A36: A8.1 | B36: Establish the location and elevation (X, Y, Z) of the ground at each 'as-built' exploratory hole or point | C36: nr | D36: ='[1]Section A'!$D$36 -> 0 | E36: =IF(ISNUMBER(D36),"","N/A") | F36: =IF(ISNUMBER(D36),"","-")
A37: A9 | B37: Preparation of Health and Safety documentation and Safety Risk Assessment | C37: sum | D37: 1 | E37: =IF(ISNUMBER(D37),"","N/A") | F37: =IF(ISNUMBER(D37),"","-")
A38: A10 | B38: Facilities for the Investigation Supervisor | C38: per week | D38: Not Required | E38: =IF(ISNUMBER(D38),"","N/A") -> N/A | F38: =IF(ISNUMBER(D38),"","-") -> -
A39: A11 | B39: Vehicle(s) for the Investigation Supervisor | C39: vehicle wk | D39: Not Required | E39: =IF(ISNUMBER(D39),"","N/A") -> N/A | F39: =IF(ISNUMBER(D39),"","-") -> -
A40: A11.1 | B40: Provision of fuel and tolls for A11 (to be reimbursed under the contract) | C40: provisional sum | D40: Not Required | E40: =IF(ISNUMBER(D40),"","N/A") -> N/A | F40: =IF(ISNUMBER(D40),"","-") -> -
A41: A11.2 | B41: Contractors uplift on item A11 and A11.1 | C41: % uplift | D41: Not Required | E41: =IF(ISNUMBER(D41),"","N/A") -> N/A | F41: =IF(ISNUMBER(D41),"","-") -> -
A42: A12 | B42: Provision of phone and internet for the Investigation Supervisor (to be reimbursed under the contract) | C42: provisional sum | D42: Not Required | E42: =IF(ISNUMBER(D42),"","N/A") -> N/A | F42: =IF(ISNUMBER(D42),"","-") -> -
...

Sheet Section B
A7: Number | B7: Item description | C7: Unit | D7: Quantity | E7: Rate | F7: Amount
E8: € | F8: €
A9: B | B9: Cable Percussion Boring (cable tool or percussive boring using minimum of 200mm diameter casing)
A10: B1 | B10: Move boring plant and equipment to the site of each exploratory hole and set up (cable percussive only) | C10: Refer to items B1.1 and B1.2 | D10: Refer to items B1.1 and B1.2 | E10: =IF(ISNUMBER(D10),"","N/A") -> N/A | F10: -
A11: B1.1.1 | B11: Move boring plant and equipment to the site of each exploratory hole, set up, dismantle on completion and reinstate (cable percussive only) | C11: nr | D11: =IF(AND(ISNUMBER('[2]Section B'!D11),'[2]Section B'!D11>0),'[2]Section B'!D11,"Not Required") -> #VALUE! | E11: =IF(ISNUMBER(D11),"","N/A") -> N/A | F11: =IF(AND(ISNUMBER(D11),D11>0),D11*E11,"-") -> #VALUE!
A12: B1.1.2 | B12: Move boring plant and equipment to the site of each exploratory hole over safety barrier or other fence or wall, set up, dismantle on completion and reinstate (cable percussive only) | C12: nr | D12: =IF(AND(ISNUMBER('[2]Section B'!D12),'[2]Section B'!D12>0),'[2]Section B'!D12,"Not Required") -> #VALUE! | E12: =IF(ISNUMBER(D12),"","N/A") -> N/A | F12: =IF(AND(ISNUMBER(D12),D12>0),D12*E12,"-") -> #VALUE!
A13: B1.2.1 | B13: Move boring plant and equipment to the site of each exploratory hole, set up, dismantle on completion and reinstate (where borehole is to be followed on with rotary drilling) | C13: nr | D13: =IF(AND(ISNUMBER('[2]Section B'!D13),'[2]Section B'!D13>0),'[2]Section B'!D13,"Not Required") -> #VALUE! | E13: =IF(ISNUMBER(D13),"","N/A") -> N/A | F13: =IF(AND(ISNUMBER(D13),D13>0),D13*E13,"-") -> #VALUE!
A14: B1.2.2 | B14: Move boring plant and equipment to the site of each exploratory hole over safety barrier or other fence or wall, set up, dismantle on completion and reinstate (where borehole is to be followed on with rotary drilling) | C14: nr | D14: =IF(AND(ISNUMBER('[2]Section B'!D14),'[2]Section B'!D14>0),'[2]Section B'!D14,"Not Required") -> #VALUE! | E14: =IF(ISNUMBER(D14),"","N/A") -> N/A | F14: =IF(AND(ISNUMBER(D14),D14>0),D14*E14,"-") -> #VALUE!
A15: B2 | B15: Extra over Item B1 for setting up on a slope of gradient greater than 20% | C15: Refer to items B2.1 and B2.2 | D15: Refer to items B2.1 and B2.2 | E15: =IF(ISNUMBER(D15),"","N/A") -> N/A | F15: -
A16: B2.1 | B16: Extra over Item B1.1 for setting up on a slope of gradient greater than 20% | C16: nr | D16: =IF(AND(ISNUMBER('[2]Section B'!D16),'[2]Section B'!D16>0),'[2]Section B'!D16,"Not Required") -> #VALUE! | E16: =IF(ISNUMBER(D16),"","N/A") -> N/A | F16: =IF(AND(ISNUMBER(D16),E16>0),D16*E16,"-") -> -
A17: B2.2 | B17: Extra over Item B1.2 for setting up on a slope of gradient greater than 20% | C17: nr | D17: =IF(AND(ISNUMBER('[2]Section B'!D17),'[2]Section B'!D17>0),'[2]Section B'!D17,"Not Required") -> #VALUE! | E17: =IF(ISNUMBER(D17),"","N/A") -> N/A | F17: =IF(AND(ISNUMBER(D17),E17>0),D17*E17,"-") -> -
A18: B3 | B18: Hand digging and CAT scan at borehole location to confirm absence of utility ducts (maximum depth of 1.2m or lesser if ground is assessed as potentially unstable) | C18: nr | D18: =IF(AND(ISNUMBER('[2]Section B'!D18),'[2]Section B'!D18>0),'[2]Section B'!D18,"Not Required") -> #VALUE! | E18: =IF(ISNUMBER(D18),"","N/A") -> N/A | F18: =IF(AND(ISNUMBER(D18),E18>0),D18*E18,"-") -> -
A19: B3.1 | B19: Break out obstructions where present when hand digging at exploratory hole location for Item B3. | C19: m3 | D19: =IF(AND(ISNUMBER('[2]Section B'!D19),'[2]Section B'!D19>0),'[2]Section B'!D19,"Not Required") -> #VALUE! | E19: =IF(ISNUMBER(D19),"","N/A") -> N/A | F19: =IF(AND(ISNUMBER(D19),E19>0),D19*E19,"-") -> -
A20: B4 | B20: Advance borehole between existing ground level and 10 m depth | C20: m | D20: =IF(AND(ISNUMBER('[2]Section B'!D20),'[2]Section B'!D20>0),'[2]Section B'!D20,"Not Required") -> Not Required | E20: =IF(ISNUMBER(D20),"","N/A") -> N/A | F20: =IF(AND(ISNUMBER(D20),E20>0),D20*E20,"-") -> -
A21: B5 | B21: As Item B4 but between 10 m and 20 m depth (Provisional) | C21: m | D21: =IF(AND(ISNUMBER('[2]Section B'!D21),'[2]Section B'!D21>0),'[2]Section B'!D21,"Not Required") -> Not Required | E21: =IF(ISNUMBER(D21),"","N/A") -> N/A | F21: =IF(AND(ISNUMBER(D21),E21>0),D21*E21,"-") -> -
A22: B6 | B22: As Item B4 but between 20 m and 30 m depth | C22: m | D22: =IF(AND(ISNUMBER('[2]Section B'!D22),'[2]Section B'!D22>0),'[2]Section B'!D22,"Not Required") -> Not Required | E22: =IF(ISNUMBER(D22),"","N/A") -> N/A | F22: =IF(AND(ISNUMBER(D22),E22>0),D22*E22,"-") -> -
A23: B7 | B23: As Item B4 but between 30 m and 40 m depth | C23: m | D23: =IF(AND(ISNUMBER('[2]Section B'!D23),'[2]Section B'!D23>0),'[2]Section B'!D23,"Not Required") -> Not Required | E23: =IF(ISNUMBER(D23),"","N/A") -> N/A | F23: =IF(AND(ISNUMBER(D23),E23>0),D23*E23,"-") -> -
A24: B8 | B24: As Item B4 but between 40 m and 50 m depth | C24: m | D24: =IF(AND(ISNUMBER('[2]Section B'!D24),'[2]Section B'!D24>0),'[2]Section B'!D24,"Not Required") -> Not Required | E24: =IF(ISNUMBER(D24),"","N/A") -> N/A | F24: =IF(AND(ISNUMBER(D24),E24>0),D24*E24,"-") -> -
A25: B9 | B25: Advance borehole through hard stratum or obstruction | C25: h | D25: =IF(AND(ISNUMBER('[2]Section B'!D25),'[2]Section B'!D25>0),'[2]Section B'!D25,"Not Required") -> #VALUE! | E25: =IF(ISNUMBER(D25),"","N/A") -> N/A | F25: =IF(AND(ISNUMBER(D25),E25>0),D25*E25,"-") -> -
A26: B10 | B26: Provide aquifer protection measures at a single aquiclude/aquifer boundary or cross-contamination control measures at a single soil boundary in a borehole | C26: nr | D26: Included in B1 to B1.2.2 | E26: =IF(ISNUMBER(D26),"","N/A") -> N/A | F26: =IF(AND(ISNUMBER(D26),E26>0),D26*E26,"-") -> -
A27: B11 | B27: Backfill borehole with cement/bentonite grout or bentonite pellets (where standpipe piezometer is not installed) | C27: m³ | D27: Included in B1 to B1.2.2 | E27: =IF(ISNUMBER(D27),"","N/A") -> N/A | F27: =IF(AND(ISNUMBER(D27),E27>0),D27*E27,"-") -> -
A28: B12 | B28: Standing time for borehole plant, equipment and crew | C28: h | D28: =IF(AND(ISNUMBER('[2]Section B'!$D$28),'[2]Section B'!$D$28>0),'[2]Section B'!$D$28,"Not Required") -> #VALUE! | E28: =IF(ISNUMBER(D28),"","N/A") -> N/A | F28: =IF(AND(ISNUMBER(D28),D28>0),D28*E28,"-") -> #VALUE!
B29: Dynamic sampling (Window and Windowless Sampling)
A30: B13 | B30: Move dynamic sampling equipment to the site of each exploratory hole and set up | C30: nr | D30: =IF(AND(ISNUMBER('[2]Section B'!D30),'[2]Section B'!D30>0),'[2]Section B'!D30,"Not Required") -> Not Required | E30: =IF(ISNUMBER(D30),"","N/A") -> N/A | F30: =IF(AND(ISNUMBER(D30),D30>0),D30*E30,"-") -> -
A31: B14 | B31: Extra over Item B13 for setting up on a slope of gradient greater than 20% | C31: nr | D31: =IF(AND(ISNUMBER('[2]Section B'!D31),'[2]Section B'!D31>0),'[2]Section B'!D31,"Not Required") -> #VALUE! | E31: =IF(ISNUMBER(D31),"","N/A") -> N/A | F31: =IF(AND(ISNUMBER(D31),D31>0),D31*E31,"-") -> #VALUE!
A32: B15 | B32: Hand digging and CAT scan at dynamic sampling location to confirm absence of utility ducts (maximum depth of 1.2m or lesser if ground is assessed as potentially unstable) | C32: nr | D32: =IF(AND(ISNUMBER('[2]Section B'!D32),'[2]Section B'!D32>0),'[2]Section B'!D32,"Not Required") -> Not Required | E32: =IF(ISNUMBER(D32),"","N/A") -> N/A | F32: =IF(AND(ISNUMBER(D32),D32>0),D32*E32,"-") -> -
A33: B16 | B33: Break out surface obstruction where present | C33: h | D33: =IF(AND(ISNUMBER('[2]Section B'!D33),'[2]Section B'!D33>0),'[2]Section B'!D33,"Not Required") -> Not Required | E33: =IF(ISNUMBER(D33),"","N/A") -> N/A | F33: =IF(AND(ISNUMBER(D33),D33>0),D33*E33,"-") -> -
A34: B17 | B34: Advance dynamic sample hole between existing ground level and 5 m depth | C34: m | D34: =IF(AND(ISNUMBER('[2]Section B'!D34),'[2]Section B'!D34>0),'[2]Section B'!D34,"Not Required") -> Not Required | E34: =IF(ISNUMBER(D34),"","N/A") -> N/A | F34: =IF(AND(ISNUMBER(D34),D34>0),D34*E34,"-") -> -
A35: B18 | B35: As Item B15 but between 5 and 10 m depth | C35: m | D35: =IF(AND(ISNUMBER('[2]Section B'!D35),'[2]Section B'!D35>0),'[2]Section B'!D35,"Not Required") -> Not Required | E35: =IF(ISNUMBER(D35),"","N/A") -> N/A | F35: =IF(AND(ISNUMBER(D35),D35>0),D35*E35,"-") -> -
A36: B19 | B36: Dynamic sampleing >10m as instructed by the Investigation Supervisor | C36: m | D36: =IF(AND(ISNUMBER('[2]Section B'!D36),'[2]Section B'!D36>0),'[2]Section B'!D36,"Not Required") -> Not Required | E36: =IF(ISNUMBER(D36),"","N/A") -> N/A | F36: =IF(AND(ISNUMBER(D36),D36>0),D36*E36,"-") -> -
A37: B20 | B37: Standing time for dynamic sampling equipment and crew | C37: hr | D37: =IF(AND(ISNUMBER('[2]Section B'!D37),'[2]Section B'!D37>0),'[2]Section B'!D37,"Not Required") -> Not Required | E37: =IF(ISNUMBER(D37),"","N/A") -> N/A | F37: =IF(AND(ISNUMBER(D37),D37>0),D37*E37,"-") -> -
A38: B21 | B38: Backfill dynamic sample borehole with cement/bentonite grout or bentonite pellets (where standpipe or piezometer is not installed) | C38: m³ | D38: ='[2]Section B'!$D$38 -> Included in B13 | E38: =IF(ISNUMBER(D38),"","N/A") -> N/A | F38: =IF(AND(ISNUMBER(D38),D38>0),D38*E38,"-") -> -
B39: Reinstatement of Cable Percussive Borehole and Dynamic Sample Borehole
A40: B22 | B40: Reinstatement of gravel hardstanding | C40: m² | D40: Included in B1.1 & B1.2 | E40: =IF(ISNUMBER(D40),"","N/A") -> N/A | F40: =IF(AND(ISNUMBER(D40),D40>0),D40*E40,"-") -> -
A41: B23 | B41: Reinstatement of asphalt / bituminous pavement | C41: m² | D41: Included in D53 | E41: =IF(ISNUMBER(D41),"","N/A") -> N/A | F41: =IF(AND(ISNUMBER(D41),D41>0),D41*E41,"-") -> -
A42: B24 | B42: Reinstatement of grass areas | C42: m² | D42: Included in B1.1, B1.2 & B13 | E42: =IF(ISNUMBER(D42),"","N/A") -> N/A | F42: =IF(AND(ISNUMBER(D42),D42>0),D42*E42,"-") -> -
A43: B25 | B43: Provision of stock proof fencing to borehole or dynamic sample work area | C43: nr | D43: Not Required | E43: =IF(ISNUMBER(D43),"","N/A") -> N/A | F43: =IF(AND(ISNUMBER(D43),D43>0),D43*E43,"-") -> -
A44: B26 | B44: Disposal of excess or surplus inert arisings from cable percussion boring or dynamic sampling (where standpipe or piezometer is not installed) | C44: m³ | D44: Included in B1 to B1.2.2 | E44: =IF(ISNUMBER(D44),"","N/A") -> N/A | F44: =IF(AND(ISNUMBER(D44),D44>0),D44*E44,"-") -> -
B45: Total Section B carried to summary: | F45: =SUM(F10:F44) -> #VALUE!

Sheet Section C
A7: Number | B7: Item description | C7: Unit | D7: Quantity | E7: Rate | F7: Amount
E8: € | F8: €
A9: C | B9: Rotary drilling
B10: Hand augering
A11: C1 | B11: Bring hand auger equipment to the position of each exploratory hole | C11: nr | D11: Not Required | E11: =IF(ISNUMBER(D11),"","N/A") -> N/A | F11: =IF(AND(ISNUMBER(D11),D11>0),D11*E11,"-") -> -
A12: C2 | B12: Bore with hand auger from existing ground level to 2m depth | C12: m | D12: Not Required | E12: =IF(ISNUMBER(D12),"","N/A") -> N/A | F12: =IF(AND(ISNUMBER(D12),D12>0),D12*E12,"-") -> -
A13: C3 | B13: As Item C2 but between 2 and 4m depth | C13: m | D13: Not Required | E13: =IF(ISNUMBER(D13),"","N/A") -> N/A | F13: =IF(AND(ISNUMBER(D13),D13>0),D13*E13,"-") -> -
A14: C4 | B14: Standing time for hand auger equipment and crew | C14: h | D14: Not Required | E14: =IF(ISNUMBER(D14),"","N/A") -> N/A | F14: =IF(AND(ISNUMBER(D14),D14>0),D14*E14,"-") -> -
A15: C5 | B15: Provision of hand augering equipment and crew for augering as directed by the Investigation Supervisor maximum depth 4m | C15: day | D15: Not Required | E15: =IF(ISNUMBER(D15),"","N/A") -> N/A | F15: =IF(AND(ISNUMBER(D15),D15>0),D15*E15,"-") -> -
A16: C6 | B16: Backfill hand auger hole with cement/bentonite grout or bentonite pellets | C16: m | D16: Not Required | E16: =IF(ISNUMBER(D16),"","N/A") -> N/A | F16: =IF(AND(ISNUMBER(D16),D16>0),D16*E16,"-") -> -
B17: Continuous flight and hollow-stem flight augering
A18: C7 | B18: Move mechanical augering plant and equipment to the site of each exploratory hole and set up. | C18: nr | D18: Not Required | E18: =IF(ISNUMBER(D18),"","N/A") -> N/A | F18: =IF(AND(ISNUMBER(D18),D18>0),D18*E18,"-") -> -
A19: C7.1 | B19: Hand digging and CAT scan at rotary drillhole location to confirm absence of utility ducts ( maximum depth of 1.2m or lesser if ground is assessed as potentially unstable). | C19: nr | D19: Not Required | E19: =IF(ISNUMBER(D19),"","N/A") -> N/A | F19: =IF(AND(ISNUMBER(D19),D19>0),D19*E19,"-") -> -
A20: C8 | B20: Extra over Item C7 for setting up on a slope of gradient greater than 20% | C20: nr | D20: Not Required | E20: =IF(ISNUMBER(D20),"","N/A") -> N/A | F20: =IF(AND(ISNUMBER(D20),D20>0),D20*E20,"-") -> -
A21: C9 | B21: Break out obstructions where present when hand digging at auger hole location for Item C7.1. | C21: m3 | D21: Not Required | E21: =IF(ISNUMBER(D21),"","N/A") -> N/A | F21: =IF(AND(ISNUMBER(D21),D21>0),D21*E21,"-") -> -
A22: C10 | B22: Standing time for rotary auger equipment and crew. | C22: h | D22: Not Required | E22: =IF(ISNUMBER(D22),"","N/A") -> N/A | F22: =IF(AND(ISNUMBER(D22),D22>0),D22*E22,"-") -> -
A23: C11 | B23: Auger in materials other than hard strata at the specified diameter between existing ground level and 10m depth. | C23: m | D23: Not Required | E23: =IF(ISNUMBER(D23),"","N/A") -> N/A | F23: =IF(AND(ISNUMBER(D23),D23>0),D23*E23,"-") -> -
A24: C12 | B24: As Item C11 but between 10 and 20m depth. | C24: m | D24: Not Required | E24: =IF(ISNUMBER(D24),"","N/A") -> N/A | F24: =IF(AND(ISNUMBER(D24),D24>0),D24*E24,"-") -> -
A25: C13 | B25: As Item C11 but between 20 and 30m depth. | C25: m | D25: Not Required | E25: =IF(ISNUMBER(D25),"","N/A") -> N/A | F25: =IF(AND(ISNUMBER(D25),D25>0),D25*E25,"-") -> -
A26: C14 | B26: Backfill auger hole with cement/bentonite grout or bentonite pellets (PROVISIONAL) | C26: m | D26: Not Required | E26: =IF(ISNUMBER(D26),"","N/A") -> N/A | F26: =IF(AND(ISNUMBER(D26),D26>0),D26*E26,"-") -> -
B27: Rotary drilling with and without core recovery
A28: C15 | B28: Move rotary drilling plant and equipment to the site of each exploratory drillhole and set up. | C28: nr | D28: Refer to C15.1.1 to C15.2.2 & C15.3 | E28: =IF(ISNUMBER(D28),"","N/A") -> N/A | F28: =IF(AND(ISNUMBER(D28),D28>0),D28*E28,"-") -> -
A29: C15.1.1 | B29: Move rotary drilling plant and equipment to the site of each exploratory drillhole, set up, dismantle on completion and reinstate (rotary follow-on). | C29: nr | D29: =IF(AND(ISNUMBER('[2]Section C'!D29),'[2]Section C'!D29>0),'[2]Section C'!D29,"Not Required") -> #VALUE! | E29: =IF(ISNUMBER(D29),"","N/A") -> N/A | F29: =IF(AND(ISNUMBER(D29),D29>0),D29*E29,"-") -> #VALUE!
A30: C15.1.2 | B30: Move rotary drilling plant and equipment to the site of each exploratory drillhole over safety barrier or other fence or wall, set up, dismantle on completion and reinstate (rotary follow-on). | C30: nr | D30: =IF(AND(ISNUMBER('[2]Section C'!D30),'[2]Section C'!D30>0),'[2]Section C'!D30,"Not Required") -> #VALUE! | E30: =IF(ISNUMBER(D30),"","N/A") -> N/A | F30: =IF(AND(ISNUMBER(D30),D30>0),D30*E30,"-") -> #VALUE!
A31: C15.2.1 | B31: Move rotary drilling plant and equipment to the site of each exploratory drillhole, set up, dismantle on completion and reinstate (rotary only). | C31: nr | D31: =IF(AND(ISNUMBER('[2]Section C'!D31),'[2]Section C'!D31>0),'[2]Section C'!D31,"Not Required") -> #VALUE! | E31: =IF(ISNUMBER(D31),"","N/A") -> N/A | F31: =IF(AND(ISNUMBER(D31),D31>0),D31*E31,"-") -> #VALUE!
A32: C15.2.2 | B32: Move rotary drilling plant and equipment to the site of each exploratory drillhole, over safety barrier or other fence or wall, set up, dismantle on completion and reinstate (rotary only). | C32: nr | D32: =IF(AND(ISNUMBER('[2]Section C'!D32),'[2]Section C'!D32>0),'[2]Section C'!D32,"Not Required") -> #VALUE! | E32: =IF(ISNUMBER(D32),"","N/A") -> N/A | F32: =IF(AND(ISNUMBER(D32),D32>0),D32*E32,"-") -> #VALUE!
A33: C15.3 | B33: Hand digging and CAT scan at rotary drillhole location to confirm absence of utility ducts ( maximum depth of 1.2m or lesser if ground is assessed as potentially unstable) for rotary only borehole | C33: nr | D33: =IF(AND(ISNUMBER('[2]Section C'!D33),'[2]Section C'!D33>0),'[2]Section C'!D33,"Not Required") -> #VALUE! | E33: =IF(ISNUMBER(D33),"","N/A") -> N/A | F33: =IF(AND(ISNUMBER(D33),D33>0),D33*E33,"-") -> #VALUE!
A34: C16 | B34: Extra over Item C15 for setting up on a slope of gradient greater than 20%. | C34: nr | D34: =IF(AND(ISNUMBER('[2]Section C'!D34),'[2]Section C'!D34>0),'[2]Section C'!D34,"Not Required") -> #VALUE! | E34: N/A | F34: =IF(AND(ISNUMBER(D34),D34>0),D34*E34,"-") -> #VALUE!
A35: C17 | B35: Extra over Item C15 for setting up drilling plant for inclined drillhole | C35: nr | D35: =IF(AND(ISNUMBER('[2]Section C'!D35),'[2]Section C'!D35>0),'[2]Section C'!D35,"Not Required") -> Not Required | E35: N/A | F35: =IF(AND(ISNUMBER(D35),D35>0),D35*E35,"-") -> -
A36: C18 | B36: Break out obstructions where present when hand digging at exploratory hole location for C15.3. | C36: m3 | D36: =IF(AND(ISNUMBER('[2]Section C'!D36),'[2]Section C'!D36>0),'[2]Section C'!D36,"Not Required") -> #VALUE! | E36: =IF(ISNUMBER(D36),"","N/A") -> N/A | F36: =IF(AND(ISNUMBER(D36),D36>0),D36*E36,"-") -> #VALUE!
A37: C19 | B37: Standing time for rotary drilling plant, equipment and crew (PROVISIONAL) | C37: h | D37: =IF(AND(ISNUMBER('[2]Section C'!D37),'[2]Section C'!D37>0),'[2]Section C'!D37,"Not Required") -> #VALUE! | E37: =IF(ISNUMBER(D37),"","N/A") -> N/A | F37: =IF(AND(ISNUMBER(D37),D37>0),D37*E37,"-") -> #VALUE!
A38: C20 | B38: Provide aquifer protection measures at a single aquiclude/aquifer boundary in a drillhole | C38: nr | D38: =IF(AND(ISNUMBER('[2]Section C'!D38),'[2]Section C'!D38>0),'[2]Section C'!D38,"Not Required") -> Not Required | E38: N/A | F38: =IF(AND(ISNUMBER(D38),D38>0),D38*E38,"-") -> -
B39: Drilling without cores
A40: C21 | B40: Rotary drill in materials other than hard strata at the specified diameter, from which cores are not required, between existing ground level and 10m depth (Provisional) | C40: m | D40: =IF(AND(ISNUMBER('[2]Section C'!D40),'[2]Section C'!D40>0),'[2]Section C'!D40,"Not Required") -> Not Required
A41: C22 | B41: As Item C21 but between 10 and 20m depth. (Provisional) | C41: m | D41: =IF(AND(ISNUMBER('[2]Section C'!D41),'[2]Section C'!D41>0),'[2]Section C'!D41,"Not Required") -> Not Required
A42: C23 | B42: As Item C21 but between 20 and 30m depth | C42: m | D42: =IF(AND(ISNUMBER('[2]Section C'!D42),'[2]Section C'!D42>0),'[2]Section C'!D42,"Not Required") -> Not Required | E42: =IF(ISNUMBER(D42),"","N/A") -> N/A | F42: =IF(AND(ISNUMBER(D42),D42>0),D42*E42,"-") -> -
A43: C24 | B43: As Item C21 but between 30 and 40m depth | C43: m | D43: =IF(AND(ISNUMBER('[2]Section C'!D43),'[2]Section C'!D43>0),'[2]Section C'!D43,"Not Required") -> Not Required | E43: =IF(ISNUMBER(D43),"","N/A") -> N/A | F43: =IF(AND(ISNUMBER(D43),D43>0),D43*E43,"-") -> -
A44: C25 | B44: As Item C21 but between 40 and 50m depth | C44: m | D44: =IF(AND(ISNUMBER('[2]Section C'!D44),'[2]Section C'!D44>0),'[2]Section C'!D44,"Not Required") -> Not Required | E44: =IF(ISNUMBER(D44),"","N/A") -> N/A | F44: =IF(AND(ISNUMBER(D44),D44>0),D44*E44,"-") -> -
A45: C26 | B45: Extra over Items C21 to C25 for inclined rotary drillhole | C45: m | D45: =IF(AND(ISNUMBER('[2]Section C'!D45),'[2]Section C'!D45>0),'[2]Section C'!D45,"Not Required") -> Not Required | E45: =IF(ISNUMBER(D45),"","N/A") -> N/A | F45: =IF(AND(ISNUMBER(D45),D45>0),D45*E45,"-") -> -
A46: C27 | B46: Rotary drill in hard strata at the specified diameter, from which cores are not required, between existing ground level and 10m depth. (Provisional) | C46: m | D46: =IF(AND(ISNUMBER('[2]Section C'!D46),'[2]Section C'!D46>0),'[2]Section C'!D46,"Not Required") -> Not Required | E46: =IF(ISNUMBER(D46),"","N/A") -> N/A | F46: =IF(AND(ISNUMBER(D46),D46>0),D46*E46,"-") -> -
...

Sheet Section D
A8: Number | B8: Item description | C8: Unit | D8: Quantity | E8: Rate | F8: Amount
E9: € | F9: €
A10: D | B10: Pitting and trenching
B11: Inspection pits Included for each exploratory hole: refer hand digging and CAT scan items at exploratory hole locations
A12: D1 | B12: Excavate inspection pit by hand to 1.2m depth. | C12: nr | D12: =IF(AND(ISNUMBER('[2]Section D'!D12),'[2]Section D'!D12>0),'[2]Section D'!D12,"Not Required") -> Not Required | E12: =IF(ISNUMBER(D12),"","N/A") -> N/A | F12: =IF(AND(ISNUMBER(D12),D12>0),D12*E12,"-") -> -
A13: D2 | B13: Extra over Item D1 for breaking out surface obstructions. | C13: m3 | D13: =IF(AND(ISNUMBER('[2]Section D'!D13),'[2]Section D'!D13>0),'[2]Section D'!D13,"Not Required") -> Not Required | E13: =IF(ISNUMBER(D13),"","N/A") -> N/A | F13: =IF(AND(ISNUMBER(D13),D13>0),D13*E13,"-") -> -
B14: Trial pits and trenches (non paved areas)
A15: D3 | B15: Move equipment to the site of each trial pit or trench dismantle on completion and reinstate. | C15: nr | D15: =IF(AND(ISNUMBER('[2]Section D'!D15),'[2]Section D'!D15>0),'[2]Section D'!D15,"Not Required") -> #VALUE! | E15: =IF(ISNUMBER(D15),"","N/A") -> N/A | F15: =IF(AND(ISNUMBER(D15),D15>0),D15*E15,"-") -> #VALUE!
A16: D3.1 | B16: Extra over item D3 for setting to the site of exploratory hole over safety barrier or other fence or wall, set up, dismantle on completion and reinstate. | C16: nr | D16: =IF(AND(ISNUMBER('[2]Section D'!D16),'[2]Section D'!D16>0),'[2]Section D'!D16,"Not Required") -> #VALUE! | E16: =IF(ISNUMBER(D16),"","N/A") -> N/A | F16: =IF(AND(ISNUMBER(D16),D16>0),D16*E16,"-") -> #VALUE!
A17: D4 | B17: Extra over Item D3 for setting up on a slope of gradient greater than 20% | C17: nr | D17: =IF(AND(ISNUMBER('[2]Section D'!D17),'[2]Section D'!D17>0),'[2]Section D'!D17,"Not Required") -> #VALUE! | E17: =IF(ISNUMBER(D17),"","N/A") -> N/A | F17: =IF(AND(ISNUMBER(D17),D17>0),D17*E17,"-") -> #VALUE!
A18: D5 | B18: Extra over Item D3 for trial pit or trench between 4.5 and 6m depth | C18: nr | D18: Not Required | E18: =IF(ISNUMBER(D18),"","N/A") -> N/A | F18: =IF(AND(ISNUMBER(D18),D18>0),D18*E18,"-") -> -
A19: D6 | B19: Excavate trial pit between existing ground level and 3m depth | C19: m depth | D19: =IF(AND(ISNUMBER('[2]Section D'!D19),'[2]Section D'!D19>0),'[2]Section D'!D19,"Not Required") -> #VALUE! | E19: =IF(ISNUMBER(D19),"","N/A") -> N/A | F19: =IF(AND(ISNUMBER(D19),D19>0),D19*E19,"-") -> #VALUE!
A20: D7 | B20: As Item D6 but between 3.0 and 4.5m depth | C20: m | D20: =IF(AND(ISNUMBER('[2]Section D'!D20),'[2]Section D'!D20>0),'[2]Section D'!D20,"Not Required") -> #VALUE! | E20: =IF(ISNUMBER(D20),"","N/A") -> N/A | F20: =IF(AND(ISNUMBER(D20),D20>0),D20*E20,"-") -> #VALUE!
A21: D8 | B21: As Item D6 but between 4.5 and 6m depth | C21: m | D21: Not Required | E21: =IF(ISNUMBER(D21),"","N/A") -> N/A | F21: =IF(AND(ISNUMBER(D21),D21>0),D21*E21,"-") -> -
A22: D9 | B22: Excavate trial trench between existing ground level and 3.0m depth | C22: m3 | D22: =IF(AND(ISNUMBER('[2]Section D'!D22),'[2]Section D'!D22>0),'[2]Section D'!D22,"Not Required") -> Not Required | E22: =IF(ISNUMBER(D22),"","N/A") -> N/A | F22: =IF(AND(ISNUMBER(D22),D22>0),D22*E22,"-") -> -
A23: D10 | B23: As Item D9 between 3.0 and 4.5m in depth | C23: m3 | D23: =IF(AND(ISNUMBER('[2]Section D'!D23),'[2]Section D'!D23>0),'[2]Section D'!D23,"Not Required") -> Not Required | E23: =IF(ISNUMBER(D23),"","N/A") -> N/A | F23: =IF(AND(ISNUMBER(D23),D23>0),D23*E23,"-") -> -
A24: D11 | B24: As Item D9 between 4.5 and 6m depth | C24: m3 | D24: Not Required | E24: =IF(ISNUMBER(D24),"","N/A") -> N/A | F24: =IF(AND(ISNUMBER(D24),D24>0),D24*E24,"-") -> -
B25: Trial pits and trenches (paved areas)
A26: D12 | B26: Set up trial pit in road area to include erection of traffic management systems (works supervised by Engineer/ Geologist with valid CSCS Card for signing, lighting and guarding at roadworks) | C26: nr | D26: =IF(AND(ISNUMBER('[2]Section D'!D26),'[2]Section D'!D26>0),'[2]Section D'!D26,"Not Required") -> #VALUE! | E26: =IF(ISNUMBER(D26),"","N/A") -> N/A | F26: =IF(AND(ISNUMBER(D26),D26>0),D26*E26,"-") -> #VALUE!
A27: D13 | B27: Set up slit trench in road area to include erection of traffic management systems (works supervised by Engineer/ Geologist with valid CSCS Card for signing, lighting and guarding at roadworks) | C27: nr | D27: =IF(AND(ISNUMBER('[2]Section D'!D27),'[2]Section D'!D27>0),'[2]Section D'!D27,"Not Required") -> #VALUE! | E27: =IF(ISNUMBER(D27),"","N/A") -> N/A | F27: =IF(AND(ISNUMBER(D27),D27>0),D27*E27,"-") -> #VALUE!
A28: D14 | B28: Saw cut paved areas in advance of the works | C28: ln m | D28: =IF(AND(ISNUMBER('[2]Section D'!D28),'[2]Section D'!D28>0),'[2]Section D'!D28,"Not Required") -> #VALUE! | E28: =IF(ISNUMBER(D28),"","N/A") -> N/A | F28: =IF(AND(ISNUMBER(D28),D28>0),D28*E28,"-") -> #VALUE!
A29: D15 | B29: Breaking out hard material or surface obstructions | C29: m3 | D29: =IF(AND(ISNUMBER('[2]Section D'!D29),'[2]Section D'!D29>0),'[2]Section D'!D29,"Not Required") -> Not Required | E29: =IF(ISNUMBER(D29),"","N/A") -> N/A | F29: =IF(AND(ISNUMBER(D29),D29>0),D29*E29,"-") -> -
A30: D16 | B30: Excavate trial pit in paved areas between ground level and 1.20m depth (works by either hand excavation or hand assisted machine excavation) | C30: m depth | D30: =IF(AND(ISNUMBER('[2]Section D'!D30),'[2]Section D'!D30>0),'[2]Section D'!D30,"Not Required") -> Not Required | E30: =IF(ISNUMBER(D30),"","N/A") -> N/A | F30: =IF(AND(ISNUMBER(D30),D30>0),D30*E30,"-") -> -
A31: D17 | B31: As D16 but depth in range 1.2m to 3.0m | C31: ln m | D31: =IF(AND(ISNUMBER('[2]Section D'!D31),'[2]Section D'!D31>0),'[2]Section D'!D31,"Not Required") -> #VALUE! | E31: =IF(ISNUMBER(D31),"","N/A") -> N/A | F31: =IF(AND(ISNUMBER(D31),D31>0),D31*E31,"-") -> #VALUE!
A32: D18 | B32: Excavate slit trench in paved areas between ground level and 1.2m depth (works by either hand excavation or hand assisted machine excavation) | C32: m³ | D32: =IF(AND(ISNUMBER('[2]Section D'!D32),'[2]Section D'!D32>0),'[2]Section D'!D32,"Not Required") -> Not Required | E32: =IF(ISNUMBER(D32),"","N/A") -> N/A | F32: =IF(AND(ISNUMBER(D32),D32>0),D32*E32,"-") -> -
A33: D19 | B33: Excavate slit trench in paved areas between 1.2m to 3.0m depth (works by either hand excavation or hand assisted machine excavation) | C33: m³ | D33: =IF(AND(ISNUMBER('[2]Section D'!D33),'[2]Section D'!D33>0),'[2]Section D'!D33,"Not Required") -> Not Required | E33: =IF(ISNUMBER(D33),"","N/A") -> N/A | F33: =IF(AND(ISNUMBER(D33),D33>0),D33*E33,"-") -> -
A34: D20 | B34: Standing time for excavation plant, equipment and crew for machine dug trial pit or trench | C34: h | D34: =IF(AND(ISNUMBER('[2]Section D'!D34),'[2]Section D'!D34>0),'[2]Section D'!D34,"Not Required") -> #VALUE! | E34: =IF(ISNUMBER(D34),"","N/A") -> N/A | F34: =IF(AND(ISNUMBER(D34),D34>0),D34*E34,"-") -> #VALUE!
B35: Observation pits and trenches
A36: D21 | B36: Move equipment to the site of each observation pit or trench of not greater than 4.5m depth | C36: nr | D36: Not Required | E36: =IF(ISNUMBER(D36),"","N/A") -> N/A | F36: =IF(AND(ISNUMBER(D36),D36>0),D36*E36,"-") -> -
A37: D22 | B37: Extra over Item D21 for setting up on a slope of gradient greater than 20% | C37: nr | D37: Not Required | E37: =IF(ISNUMBER(D37),"","N/A") -> N/A | F37: =IF(AND(ISNUMBER(D37),D37>0),D37*E37,"-") -> -
A38: D23 | B38: Extra over Item D21 for trial pit or trench between 4.5 and 6m depth | C38: nr | D38: Not Required | E38: =IF(ISNUMBER(D38),"","N/A") -> N/A | F38: =IF(AND(ISNUMBER(D38),D38>0),D38*E38,"-") -> -
A39: D24 | B39: Excavate observation pit between existing ground level and 3.0m depth | C39: m | D39: Not Required | E39: =IF(ISNUMBER(D39),"","N/A") -> N/A | F39: =IF(AND(ISNUMBER(D39),D39>0),D39*E39,"-") -> -
A40: D25 | B40: As Item D24 but between 3.0 and 4.5m depth | C40: m | D40: Not Required | E40: =IF(ISNUMBER(D40),"","N/A") -> N/A | F40: =IF(AND(ISNUMBER(D40),D40>0),D40*E40,"-") -> -
A41: D26 | B41: As Item D24 but between 4.5 and 6m depth | C41: m | D41: Not Required | E41: =IF(ISNUMBER(D41),"","N/A") -> N/A | F41: =IF(AND(ISNUMBER(D41),D41>0),D41*E41,"-") -> -
A42: D27 | B42: Extra over Item D24 for hand excavation | C42: m | D42: Not Required | E42: =IF(ISNUMBER(D42),"","N/A") -> N/A | F42: =IF(AND(ISNUMBER(D42),D42>0),D42*E42,"-") -> -
A43: D28 | B43: Excavate observation trench between existing ground level and 3.0m depth | C43: m3 | D43: Not Required | E43: =IF(ISNUMBER(D43),"","N/A") -> N/A | F43: =IF(AND(ISNUMBER(D43),D43>0),D43*E43,"-") -> -
A44: D29 | B44: As Item D28 but between 3.0 and 4.5m depth | C44: m3 | D44: Not Required | E44: =IF(ISNUMBER(D44),"","N/A") -> N/A | F44: =IF(AND(ISNUMBER(D44),D44>0),D44*E44,"-") -> -
A45: D30 | B45: As Item D28 but between 4.5 and 6m depth | C45: m3 | D45: Not Required | E45: =IF(ISNUMBER(D45),"","N/A") -> N/A | F45: =IF(AND(ISNUMBER(D45),D45>0),D45*E45,"-") -> -
A46: D31 | B46: Extra over Item D28 for hand excavation | C46: m3 | D46: Not Required | E46: =IF(ISNUMBER(D46),"","N/A") -> N/A | F46: =IF(AND(ISNUMBER(D46),D46>0),D46*E46,"-") -> -
A47: D32 | B47: Extra over Items D24 to D26 for breaking out hard strata or obstructions | C47: h | D47: Not Required | E47: =IF(ISNUMBER(D47),"","N/A") -> N/A | F47: =IF(AND(ISNUMBER(D47),D47>0),D47*E47,"-") -> -
...

Sheet Section E
A7: Number | B7: Item description | C7: Unit | D7: Quantity | E7: Rate | F7: Amount
E8: € | F8: €
A9: E | B9: Sampling and monitoring during intrusive investigation
B10: Samples for geotechnical purposes
A11: E1 | B11: Jar sample | C11: nr | D11: Not Required | E11: =IF(ISNUMBER(D11),"","N/A") -> N/A | F11: =IF(AND(ISNUMBER(D11),D11>0),D11*E11,"-") -> -
A12: E2 | B12: Tub sample | C12: nr | D12: =IF(AND(ISNUMBER('[2]Section E'!D12),'[2]Section E'!D12>0),'[2]Section E'!D12,"Not Required") -> Not Required | E12: =IF(ISNUMBER(D12),"","N/A") -> N/A | F12: =IF(AND(ISNUMBER(D12),D12>0),D12*E12,"-") -> -
A13: E3 | B13: Bulk sample | C13: nr | D13: =IF(AND(ISNUMBER('[2]Section E'!D13),'[2]Section E'!D13>0),'[2]Section E'!D13,"Not Required") -> Not Required | E13: =IF(ISNUMBER(D13),"","N/A") -> N/A | F13: =IF(AND(ISNUMBER(D13),D13>0),D13*E13,"-") -> -
A14: E4 | B14: Large bulk disturbed sample | C14: nr | D14: =IF(AND(ISNUMBER('[2]Section E'!D14),'[2]Section E'!D14>0),'[2]Section E'!D14,"Not Required") -> Not Required | E14: =IF(ISNUMBER(D14),"","N/A") -> N/A | F14: =IF(AND(ISNUMBER(D14),D14>0),D14*E14,"-") -> -
A15: E5 | B15: Open tube- thick walled sample (0 to 10m depth) | C15: nr | D15: =IF(AND(ISNUMBER('[2]Section E'!D15),'[2]Section E'!D15>0),'[2]Section E'!D15,"Not Required") -> Not Required | E15: =IF(ISNUMBER(D15),"","N/A") -> N/A | F15: =IF(AND(ISNUMBER(D15),D15>0),D15*E15,"-") -> -
A16: E6 | B16: Open tube- thin walled sample (0 to 10m depth) | C16: nr | D16: =IF(AND(ISNUMBER('[2]Section E'!D16),'[2]Section E'!D16>0),'[2]Section E'!D16,"Not Required") -> Not Required | E16: =IF(ISNUMBER(D16),"","N/A") -> N/A | F16: =IF(AND(ISNUMBER(D16),D16>0),D16*E16,"-") -> -
A17: E7 | B17: Piston sample (0 to 10m depth) | C17: nr | D17: Not Required | E17: =IF(ISNUMBER(D17),"","N/A") -> N/A | F17: =IF(AND(ISNUMBER(D17),D17>0),D17*E17,"-") -> -
A18: E8.1 | B18: Extra over rate for item E5 in depth range 10m to 20m | C18: nr | D18: =IF(AND(ISNUMBER('[2]Section E'!D18),'[2]Section E'!D18>0),'[2]Section E'!D18,"Not Required") -> Not Required | E18: =IF(ISNUMBER(D18),"","N/A") -> N/A | F18: =IF(AND(ISNUMBER(D18),D18>0),D18*E18,"-") -> -
A19: E8.2 | B19: Extra over rate for item E6 in depth range 10m to 20m | C19: nr | D19: =IF(AND(ISNUMBER('[2]Section E'!D19),'[2]Section E'!D19>0),'[2]Section E'!D19,"Not Required") -> Not Required | E19: =IF(ISNUMBER(D19),"","N/A") -> N/A | F19: =IF(AND(ISNUMBER(D19),D19>0),D19*E19,"-") -> -
A20: E8.3 | B20: Extra over rate for item E7 in depth range 10m to 20m | C20: nr | D20: Not Required | E20: =IF(ISNUMBER(D20),"","N/A") -> N/A | F20: =IF(AND(ISNUMBER(D20),D20>0),D20*E20,"-") -> -
A21: E9 | B21: Groundwater sample | C21: nr | D21: Not Required | E21: =IF(ISNUMBER(D21),"","N/A") -> N/A | F21: =IF(AND(ISNUMBER(D21),D21>0),D21*E21,"-") -> -
A22: E10 | B22: Ground Gas sample | C22: nr | D22: Not Required | E22: =IF(ISNUMBER(D22),"","N/A") -> N/A | F22: =IF(AND(ISNUMBER(D22),D22>0),D22*E22,"-") -> -
A23: E11 | B23: Cut, prepare and protect core sub-sample | C23: nr | D23: Not Required | E23: =IF(ISNUMBER(D23),"","N/A") -> N/A | F23: =IF(AND(ISNUMBER(D23),D23>0),D23*E23,"-") -> -
B24: Samples for environmental / contamination analysis
A25: E12 | B25: Environmental / contamination sample for Suite E | C25: nr | D25: =IF(AND(ISNUMBER('[2]Section E'!$D$25),'[2]Section E'!$D$25>0),'[2]Section E'!$D$25,"Not Required") -> #VALUE! | E25: =IF(ISNUMBER(D25),"","N/A") -> N/A | F25: =IF(AND(ISNUMBER(D25),D25>0),D25*E25,"-") -> #VALUE!
A26: E13 | B26: Environmental / contamination sample for Suite F | C26: nr | D26: Not Required | E26: =IF(ISNUMBER(D26),"","N/A") -> N/A | F26: =IF(AND(ISNUMBER(D26),D26>0),D26*E26,"-") -> -
A27: E14 | B27: Ground gas sample for Suite G | C27: nr | D27: Not Required | E27: =IF(ISNUMBER(D27),"","N/A") -> N/A | F27: =IF(AND(ISNUMBER(D27),D27>0),D27*E27,"-") -> -
A28: E15 | B28: Environmental / contamination sample for Suite H (PROVISIONAL) | C28: nr | D28: Not required | E28: =IF(ISNUMBER(D28),"","N/A") -> N/A | F28: =IF(AND(ISNUMBER(D28),D28>0),D28*E28,"-") -> -
A29: E16 | B29: Environmental / contamination sample for Suite I | C29: nr | D29: =IF(AND(ISNUMBER('[2]Section E'!$D$29),'[2]Section E'!$D$29>0),'[2]Section E'!$D$29,"Not Required") -> #VALUE! | E29: =IF(ISNUMBER(D29),"","N/A") -> N/A | F29: =IF(AND(ISNUMBER(D29),D29>0),D29*E29,"-") -> #VALUE!
A30: E17 | B30: Other specialist environmental / contamination sampling as specified by Investigation Supervisor (Suite J) | C30: nr | D30: Not required | E30: =IF(ISNUMBER(D30),"","N/A") -> N/A | F30: =IF(AND(ISNUMBER(D30),D30>0),D30*E30,"-") -> -
B32: (Note sample rate includes provision of specialist containers)
B33: Total Section E carried to summary: | F33: =SUM(F11:F30) -> #VALUE!

Sheet Section F
A7: Number | B7: Item description | C7: Unit | D7: Quantity | E7: Rate | F7: Amount
E8: € | F8: €
A9: F | B9: Probing and cone penetration testing
B10: Dynamic probing (DPH)
A11: F1 | B11: Bring dynamic probe (DPH) equipment to the site of each test location | C11: nr | D11: =IF(AND(ISNUMBER('[2]Section F'!D11),'[2]Section F'!D11>0),'[2]Section F'!D11,"Not Required") -> Not Required | E11: =IF(ISNUMBER(D11),"","N/A") -> N/A | F11: =IF(AND(ISNUMBER(D11),D11>0),D11*E11,"-") -> -
A12: F2 | B12: Extra over Item F1 for setting up on a slope of gradient greater than 20% | C12: nr | D12: =IF(AND(ISNUMBER('[2]Section F'!D12),'[2]Section F'!D12>0),'[2]Section F'!D12,"Not Required") -> #VALUE! | E12: =IF(ISNUMBER(D12),"","N/A") -> N/A | F12: =IF(AND(ISNUMBER(D12),D12>0),D12*E12,"-") -> #VALUE!
A13: F3 | B13: Carry out dynamic probe test from existing ground level to 5m depth | C13: m | D13: =IF(AND(ISNUMBER('[2]Section F'!D13),'[2]Section F'!D13>0),'[2]Section F'!D13,"Not Required") -> Not Required | E13: =IF(ISNUMBER(D13),"","N/A") -> N/A | F13: =IF(AND(ISNUMBER(D13),D13>0),D13*E13,"-") -> -
A14: F4 | B14: As Item F3 but between 5 and 10m depth | C14: m | D14: =IF(AND(ISNUMBER('[2]Section F'!D14),'[2]Section F'!D14>0),'[2]Section F'!D14,"Not Required") -> Not Required | E14: =IF(ISNUMBER(D14),"","N/A") -> N/A | F14: =IF(AND(ISNUMBER(D14),D14>0),D14*E14,"-") -> -
A15: F5 | B15: As Item F3 but between 10 and 15m depth | C15: m | D15: =IF(AND(ISNUMBER('[2]Section F'!D15),'[2]Section F'!D15>0),'[2]Section F'!D15,"Not Required") -> Not Required | E15: =IF(ISNUMBER(D15),"","N/A") -> N/A | F15: =IF(AND(ISNUMBER(D15),D15>0),D15*E15,"-") -> -
A16: F6 | B16: Standing time for dynamic probe test equipment and crew | C16: h | D16: =IF(AND(ISNUMBER('[2]Section F'!D16),'[2]Section F'!D16>0),'[2]Section F'!D16,"Not Required") -> Not Required | E16: =IF(ISNUMBER(D16),"","N/A") -> N/A | F16: =IF(AND(ISNUMBER(D16),D16>0),D16*E16,"-") -> -
A17: F7 | B17: Provision of dynamic probing equipment and crew for probing as directed by the Investigation Supervisor; maximum depth 15m | C17: day | D17: Not Required | E17: =IF(ISNUMBER(D17),"","N/A") -> N/A | F17: =IF(AND(ISNUMBER(D17),D17>0),D17*E17,"-") -> -
B18: Cone penetration testing
A19: F8 | B19: Bring static cone penetration test equipment to the site of each test location | C19: nr | D19: =IF(AND(ISNUMBER('[2]Section F'!D19),'[2]Section F'!D19>0),'[2]Section F'!D19,"Not Required") -> Not Required | E19: =IF(ISNUMBER(D19),"","N/A") -> N/A | F19: =IF(AND(ISNUMBER(D19),D19>0),D19*E19,"-") -> -
A20: F9 | B20: Extra over Item F8 for setting up on a slope of gradient greater than 20% | C20: nr | D20: =IF(AND(ISNUMBER('[2]Section F'!D20),'[2]Section F'!D20>0),'[2]Section F'!D20,"Not Required") -> #VALUE! | E20: =IF(ISNUMBER(D20),"","N/A") -> N/A | F20: =IF(AND(ISNUMBER(D20),D20>0),D20*E20,"-") -> #VALUE!
A21: F10 | B21: Carry out static cone penetration test measuring both cone and sleeve resistance from existing ground level to 10m depth | C21: m | D21: =IF(AND(ISNUMBER('[2]Section F'!D21),'[2]Section F'!D21>0),'[2]Section F'!D21,"Not Required") -> Not Required | E21: =IF(ISNUMBER(D21),"","N/A") -> N/A | F21: =IF(AND(ISNUMBER(D21),D21>0),D21*E21,"-") -> -
A22: F11 | B22: As Item F10 but between 10 and 20m depth | C22: m | D22: =IF(AND(ISNUMBER('[2]Section F'!D22),'[2]Section F'!D22>0),'[2]Section F'!D22,"Not Required") -> Not Required | E22: =IF(ISNUMBER(D22),"","N/A") -> N/A | F22: =IF(AND(ISNUMBER(D22),D22>0),D22*E22,"-") -> -
A23: F12 | B23: As Item F10 but between 20 and 30m depth | C23: m | D23: =IF(AND(ISNUMBER('[2]Section F'!D23),'[2]Section F'!D23>0),'[2]Section F'!D23,"Not Required") -> Not Required | E23: =IF(ISNUMBER(D23),"","N/A") -> N/A | F23: =IF(AND(ISNUMBER(D23),D23>0),D23*E23,"-") -> -
A24: F13 | B24: As Item F10 but between 30 and 40m depth | C24: m | D24: =IF(AND(ISNUMBER('[2]Section F'!D24),'[2]Section F'!D24>0),'[2]Section F'!D24,"Not Required") -> Not Required | E24: =IF(ISNUMBER(D24),"","N/A") -> N/A | F24: =IF(AND(ISNUMBER(D24),D24>0),D24*E24,"-") -> -
A25: F14 | B25: Extra over Items F10 to F13 for use of piezocone | C25: m | D25: Not Required | E25: =IF(ISNUMBER(D25),"","N/A") -> N/A | F25: =IF(AND(ISNUMBER(D25),D25>0),D25*E25,"-") -> -
A26: F15 | B26: Extra over Items F10 to F13 for interpretation of CPT/CPTU data | C26: m | D26: Not Required | E26: =IF(ISNUMBER(D26),"","N/A") -> N/A | F26: =IF(AND(ISNUMBER(D26),D26>0),D26*E26,"-") -> -
A27: F16 | B27: Carry out dissipation test up to 1 hour duration | C27: nr | D27: Not Required | E27: =IF(ISNUMBER(D27),"","N/A") -> N/A | F27: =IF(AND(ISNUMBER(D27),D27>0),D27*E27,"-") -> -
A28: F17 | B28: Extra over Item F16 for test duration exceeding 1 hour | C28: h | D28: Not Required | E28: =IF(ISNUMBER(D28),"","N/A") -> N/A | F28: =IF(AND(ISNUMBER(D28),D28>0),D28*E28,"-") -> -
A29: F18 | B29: Standing time for static cone penetration test equipment and crew | C29: h | D29: =IF(AND(ISNUMBER('[2]Section F'!$D$29),'[2]Section F'!$D$29>0),'[2]Section F'!$D$29,"Not Required") -> Not Required | E29: =IF(ISNUMBER(D29),"","N/A") -> N/A | F29: =IF(AND(ISNUMBER(D29),D29>0),D29*E29,"-") -> -
A30: F19 | B30: Extra over Items F10 to F13 for use of seismic cone | C30: m | D30: Not Required | E30: =IF(ISNUMBER(D30),"","N/A") -> N/A | F30: =IF(AND(ISNUMBER(D30),D30>0),D30*E30,"-") -> -
A31: F20 | B31: Carry out seismic cone test | C31: nr | D31: Not Required | E31: =IF(ISNUMBER(D31),"","N/A") -> N/A | F31: =IF(AND(ISNUMBER(D31),D31>0),D31*E31,"-") -> -
A32: F21 | B32: Extra over Item F20 for interpretation of seismic cone data | C32: nr | D32: Not Required | E32: =IF(ISNUMBER(D32),"","N/A") -> N/A | F32: =IF(AND(ISNUMBER(D32),D32>0),D32*E32,"-") -> -
A33: F22 | B33: Standing time for seismic cone test equipment and crew | C33: h | D33: Not Required | E33: =IF(ISNUMBER(D33),"","N/A") -> N/A | F33: =IF(AND(ISNUMBER(D33),D33>0),D33*E33,"-") -> -
B34: Total Section F carried to summary: | F34: =SUM(F11:F33) -> #VALUE!

Sheet Section G
A7: Number | B7: Item description | C7: Unit | D7: Quantity | E7: Rate | F7: Amount
E8: € | F8: €
A9: G | B9: Geophysical testing
B10: Land-based mapping techniques
A11: G1 | B11: Conduct and process Ground Penetrating Radar (GPR) profiles to PAS 128 QL B1P as per the specification | C11: m² | D11: Not Required | E11: =IF(ISNUMBER(D11),"","N/A") -> N/A | F11: =IF(AND(ISNUMBER(D11),D11>0),D11*E11,"-") -> -
A12: G2 | B12: Conduct and process electro magnetic conductivity (EMC) profiles | C12: ln m | D12: Not Required | E12: =IF(ISNUMBER(D12),"","N/A") -> N/A | F12: =IF(AND(ISNUMBER(D12),D12>0),D12*E12,"-") -> -
A13: G3 | B13: Conduct and process electrical resistivity tomography (ERT) profiles | C13: ln m | D13: Not Required | E13: =IF(ISNUMBER(D13),"","N/A") -> N/A | F13: =IF(AND(ISNUMBER(D13),D13>0),D13*E13,"-") -> -
A14: G4 | B14: Conduct and process seismic refraction spreads (P or S wave) | C14: ln m | D14: Not Required | E14: =IF(ISNUMBER(D14),"","N/A") -> N/A | F14: =IF(AND(ISNUMBER(D14),D14>0),D14*E14,"-") -> -
A15: G5 | B15: Conduct and [rocess surface wave spreads (1D or 2D MASW) | C15: ln m | D15: Not Required | E15: =IF(ISNUMBER(D15),"","N/A") -> N/A | F15: =IF(AND(ISNUMBER(D15),D15>0),D15*E15,"-") -> -
B16: Borehole geophysical surveying | D16: Not Required | E16: =IF(ISNUMBER(D16),"","N/A") -> N/A | F16: =IF(AND(ISNUMBER(D16),D16>0),D16*E16,"-") -> -
A17: G6 | B17: Establish down-hole geophysical logging equipment and personnel to the site of each exploratory hole and set up at each location | C17: sum | D17: Not Required | E17: =IF(ISNUMBER(D17),"","N/A") -> N/A | F17: =IF(AND(ISNUMBER(D17),D17>0),D17*E17,"-") -> -
A18: G7 | B18: Conduct and process down the hole calliper, natural gamma, resistivity, sonic, fluid, temperature, conductivity, and fluid flow logging | C18: m | D18: Not Required | E18: =IF(ISNUMBER(D18),"","N/A") -> N/A | F18: =IF(AND(ISNUMBER(D18),D18>0),D18*E18,"-") -> -
A19: G8 | B19: Conduct and process cross-hole seismic readings at specified intervals | C19: nr | D19: Not Required | E19: =IF(ISNUMBER(D19),"","N/A") -> N/A | F19: =IF(AND(ISNUMBER(D19),D19>0),D19*E19,"-") -> -
B20: Marine (overwater) geophysical surveying
A21: G9 | B21: Establish geophysical personnel and field equipment and demobilisation on completion | C21: sum | D21: Not Required | E21: =IF(ISNUMBER(D21),"","N/A") -> N/A | F21: =IF(AND(ISNUMBER(D21),D21>0),D21*E21,"-") -> -
A22: G10 | B22: conduct and process echo sounding, side scan sonar, magnetic, sub-bottom profile surveying | C22: day | D22: Not Required | E22: =IF(ISNUMBER(D22),"","N/A") -> N/A | F22: =IF(AND(ISNUMBER(D22),D22>0),D22*E22,"-") -> -
A23: Contract specific additional bill items
C24: day | D24: Not Required | E24: =IF(ISNUMBER(D24),"","N/A") -> N/A | F24: =IF(AND(ISNUMBER(D24),D24>0),D24*E24,"-") -> -
B25: Total Section G carried to summary: | F25: =SUM(F11:F24) -> 0

Sheet Section H
A7: Number | B7: Item description | C7: Unit | D7: Quantity | E7: Rate | F7: Amount
E8: € | F8: €
A9: H | B9: In situ testing
A10: H1.1 | B10: Standard penetration test in percussive borehole, depth range 0 to 10m | C10: nr | D10: =IF(AND(ISNUMBER('[2]Section H'!D10),'[2]Section H'!D10>0),'[2]Section H'!D10,"Not Required") -> Not Required | E10: =IF(ISNUMBER(D10),"","N/A") -> N/A | F10: =IF(ISNUMBER(D10),D10*E10,"-") -> -
A11: H1.2 | B11: Standard penetration test in percussive borehole, depth range 10 to 20m | C11: nr | D11: =IF(AND(ISNUMBER('[2]Section H'!D11),'[2]Section H'!D11>0),'[2]Section H'!D11,"Not Required") -> Not Required | E11: =IF(ISNUMBER(D11),"","N/A") -> N/A | F11: =IF(ISNUMBER(D11),D11*E11,"-") -> -
A12: H1.3 | B12: Standard penetration test in percussive borehole, depth range 20 to 30m | C12: nr | D12: =IF(AND(ISNUMBER('[2]Section H'!D12),'[2]Section H'!D12>0),'[2]Section H'!D12,"Not Required") -> Not Required | E12: =IF(ISNUMBER(D12),"","N/A") -> N/A | F12: =IF(ISNUMBER(D12),D12*E12,"-") -> -
A13: H1.4 | B13: Standard penetration test in percussive borehole, depth range 30 to 40m | C13: nr | D13: =IF(AND(ISNUMBER('[2]Section H'!D13),'[2]Section H'!D13>0),'[2]Section H'!D13,"Not Required") -> Not Required | E13: =IF(ISNUMBER(D13),"","N/A") -> N/A | F13: =IF(ISNUMBER(D13),D13*E13,"-") -> -
A14: H2.1 | B14: Standard penetration test in rotary drillhole, depth range 0 to 10m (PROVISIONAL) | C14: nr | D14: =IF(AND(ISNUMBER('[2]Section H'!D14),'[2]Section H'!D14>0),'[2]Section H'!D14,"Not Required") -> Not Required | E14: =IF(ISNUMBER(D14),"","N/A") -> N/A | F14: =IF(ISNUMBER(D14),D14*E14,"-") -> -
A15: H2.2 | B15: Standard penetration test in rotary drillhole, depth range 10 to 20m | C15: nr | D15: =IF(AND(ISNUMBER('[2]Section H'!D15),'[2]Section H'!D15>0),'[2]Section H'!D15,"Not Required") -> Not Required | E15: =IF(ISNUMBER(D15),"","N/A") -> N/A | F15: =IF(ISNUMBER(D15),D15*E15,"-") -> -
A16: H2.3 | B16: Standard penetration test in rotary drillhole, depth range 20 to 30m | C16: nr | D16: =IF(AND(ISNUMBER('[2]Section H'!D16),'[2]Section H'!D16>0),'[2]Section H'!D16,"Not Required") -> Not Required | E16: =IF(ISNUMBER(D16),"","N/A") -> N/A | F16: =IF(ISNUMBER(D16),D16*E16,"-") -> -
A17: H2.4 | B17: Standard penetration test in rotary drillhole, depth range 30 to 40m | C17: nr | D17: =IF(AND(ISNUMBER('[2]Section H'!D17),'[2]Section H'!D17>0),'[2]Section H'!D17,"Not Required") -> Not Required | E17: =IF(ISNUMBER(D17),"","N/A") -> N/A | F17: =IF(ISNUMBER(D17),D17*E17,"-") -> -
A18: H3.1 | B18: Standard penetration test in dynamic sampling boreholes, depth range 0 to 10m | C18: nr | D18: =IF(AND(ISNUMBER('[2]Section H'!D18),'[2]Section H'!D18>0),'[2]Section H'!D18,"Not Required") -> Not Required | E18: =IF(ISNUMBER(D18),"","N/A") -> N/A | F18: =IF(ISNUMBER(D18),D18*E18,"-") -> -
A19: H4 | B19: In-situ density testing | C19: nr | D19: Not Required | E19: =IF(ISNUMBER(D19),"","N/A") -> N/A | F19: =IF(ISNUMBER(D19),D19*E19,"-") -> -
A20: H4.1 | B20: Small pouring cylinder method | C20: nr | D20: Not Required | E20: =IF(ISNUMBER(D20),"","N/A") -> N/A | F20: =IF(ISNUMBER(D20),D20*E20,"-") -> -
A21: H4.2 | B21: Large pouring cylinder method | C21: nr | D21: Not Required | E21: =IF(ISNUMBER(D21),"","N/A") -> N/A | F21: =IF(ISNUMBER(D21),D21*E21,"-") -> -
A22: H4.3 | B22: Water replacement method | C22: nr | D22: Not Required | E22: =IF(ISNUMBER(D22),"","N/A") -> N/A | F22: =IF(ISNUMBER(D22),D22*E22,"-") -> -
A23: H4.4 | B23: Core cutter method | C23: nr | D23: Not Required | E23: =IF(ISNUMBER(D23),"","N/A") -> N/A | F23: =IF(ISNUMBER(D23),D23*E23,"-") -> -
A24: H4.5 | B24: Nuclear gauge method | C24: day | D24: Not Required | E24: =IF(ISNUMBER(D24),"","N/A") -> N/A | F24: =IF(ISNUMBER(D24),D24*E24,"-") -> -
A25: H5 | B25: California Bearing Ratio by plate bearing test by plunger method | C25: nr | D25: Not Required | E25: =IF(ISNUMBER(D25),"","N/A") -> N/A | F25: =IF(ISNUMBER(D25),D25*E25,"-") -> -
A26: H6 | B26: California Bearing Ratio by TRL DCP method | C26: nr | D26: =IF(AND(ISNUMBER('[2]Section H'!$D$26),'[2]Section H'!$D$26>0),'[2]Section H'!$D$26,"Not Required") -> #VALUE! | E26: =IF(ISNUMBER(D26),"","N/A") -> N/A | F26: =IF(ISNUMBER(D26),D26*E26,"-") -> -
A27: H7 | B27: Vane shear strength test in borehole / trial pit / trench | C27: nr | D27: Not Required | E27: =IF(ISNUMBER(D27),"","N/A") -> N/A | F27: =IF(ISNUMBER(D27),D27*E27,"-") -> -
A28: H8 | B28: Hand penetrometer test (set of 3 readings) | C28: nr | D28: Rate Only | E28: =IF(ISNUMBER(D28),"","N/A") -> N/A | F28: =IF(ISNUMBER(D28),D28*E28,"-") -> -
A29: H9 | B29: Hand vane test (set of 3 readings) | C29: nr | D29: =IF(AND(ISNUMBER('[2]Section H'!$D$29),'[2]Section H'!$D$29>0),'[2]Section H'!$D$29,"Not Required") -> #VALUE! | E29: =IF(ISNUMBER(D29),"","N/A") -> N/A | F29: =IF(ISNUMBER(D29),D29*E29,"-") -> -
B30: Other tests
A31: H10 | B31: In situ geophysical techniques (resistivity and redox potential) for earthing analysis | C31: nr | D31: Not Required | E31: =IF(ISNUMBER(D31),"","N/A") -> N/A | F31: =IF(ISNUMBER(D31),D31*E31,"-") -> -
B32: Permeability testing
A33: H11 | B33: Set up, execute and dismantle variable head permeability test in cable percussive borehole | C33: hr | D33: Not Required | E33: =IF(ISNUMBER(D33),"","N/A") -> N/A | F33: =IF(ISNUMBER(D33),D33*E33,"-") -> -
A34: H12 | B34: Set up, execute and dismantle constant head permeability test in cable percussive borehole | C34: hr | D34: Not Required | E34: =IF(ISNUMBER(D34),"","N/A") -> N/A | F34: =IF(ISNUMBER(D34),D34*E34,"-") -> -
A35: H13 | B35: Set up, execute and dismantle variable head permeability test in rotary drillhole | C35: hr | D35: Not Required | E35: =IF(ISNUMBER(D35),"","N/A") -> N/A | F35: =IF(ISNUMBER(D35),D35*E35,"-") -> -
A36: H14 | B36: Set up, execute and dismantle constant head permeability test in rotary drillhole | C36: hr | D36: Not Required | E36: =IF(ISNUMBER(D36),"","N/A") -> N/A | F36: =IF(ISNUMBER(D36),D36*E36,"-") -> -
A37: H15 | B37: Set up, execute and dismantle variable head permeability test in standpipe or standpipe piezometer (rising or falling head test) | C37: hr | D37: Not Required | E37: =IF(ISNUMBER(D37),"","N/A") -> N/A | F37: =IF(ISNUMBER(D37),D37*E37,"-") -> -
A38: H16 | B38: Set up and execute constant head permeability test in standpipe or standpipe piezometer | C38: hr | D38: Not Required | E38: =IF(ISNUMBER(D38),"","N/A") -> N/A | F38: =IF(ISNUMBER(D38),D38*E38,"-") -> -
A39: H17 | B39: Set up and execute packer permeability test in rotary borehole (0 to 10m) | C39: hr | D39: Not Required | E39: =IF(ISNUMBER(D39),"","N/A") -> N/A | F39: =IF(ISNUMBER(D39),D39*E39,"-") -> -
A40: H18 | B40: Set up and execute packer permeability test in rotary borehole (10 to 20m) | C40: hr | D40: Not Required | E40: =IF(ISNUMBER(D40),"","N/A") -> N/A | F40: =IF(ISNUMBER(D40),D40*E40,"-") -> -
B41: Note: rates for permeability test in boreholes or rotary holes to include standing time rate for plant and equipment
B42: Soil infiltration test (BRE Digest 365)
A43: H19 | B43: Set up at each test location, excavate trial hole and prepare test area | C43: nr | D43: =IF(AND(ISNUMBER('[2]Section H'!$D$43),'[2]Section H'!$D$43>0),'[2]Section H'!$D$43,"Not Required") -> #VALUE! | E43: =IF(ISNUMBER(D43),"","N/A") -> N/A | F43: =IF(ISNUMBER(D43),D43*E43,"-") -> -
A44: H20 | B44: Backfill test hole with clean imported gravel where excavation side walls are unstable | C44: m³ | D44: Not Required | E44: =IF(ISNUMBER(D44),"","N/A") -> N/A | F44: =IF(ISNUMBER(D44),D44*E44,"-") -> -
A45: H21 | B45: Install 50mm standpipe in H18 to allow for monitoring of water levels | C45: nr | D45: Not Required | E45: =IF(ISNUMBER(D45),"","N/A") -> N/A | F45: =IF(ISNUMBER(D45),D45*E45,"-") -> -
A46: H22 | B46: Carry out pre-soaking of test areas | C46: nr | D46: Not Required | E46: =IF(ISNUMBER(D46),"","N/A") -> N/A | F46: =IF(ISNUMBER(D46),D46*E46,"-") -> -
...

Sheet Section I
A7: Number | B7: Item description | C7: Unit | D7: Quantity | E7: Rate | F7: Amount
E8: € | F8: €
A9: I | B9: Instrumentation
B10: Standpipes and piezometers
A11: I1 | B11: Backfill exploratory hole with cement/bentonite grout or bentonite pellets | C11: m | D11: =IF(AND(ISNUMBER('[2]Section I'!D11),'[2]Section I'!D11>0),'[2]Section I'!D11,"Not Required") -> Not Required | E11: =IF(ISNUMBER(D11),"","N/A") -> N/A | F11: =IF(ISNUMBER(D11),D11*E11,"-") -> -
A12: I2 | B12: Provide and install 19mm casagrande piezometer tip | C12: nr | D12: =IF(AND(ISNUMBER('[2]Section I'!D12),'[2]Section I'!D12>0),'[2]Section I'!D12,"Not Required") -> #VALUE! | E12: =IF(ISNUMBER(D12),"","N/A") -> N/A | F12: =IF(ISNUMBER(D12),D12*E12,"-") -> -
A13: I3 | B13: Provide and install sand cell to I2 | C13: m | D13: =IF(AND(ISNUMBER('[2]Section I'!D13),'[2]Section I'!D13>0),'[2]Section I'!D13,"Not Required") -> #VALUE! | E13: =IF(ISNUMBER(D13),"","N/A") -> N/A | F13: =IF(ISNUMBER(D13),D13*E13,"-") -> -
