Workbook
Name cellx: #REF!
Name cellx: 'Section H'!$E$73
Name TOTAL_A: #REF!
Name TOTAL_A: 'Section A'!$F$72
Name TOTAL_A: 'Section A'!$F$72
Name TOTAL_B: #REF!
Name TOTAL_B: 'Section B'!$F$45
Name TOTAL_B: 'Section B'!$F$45
Name TOTAL_C: #REF!
Name TOTAL_C: 'Section C'!$F$113
Name TOTAL_C: 'Section C'!$F$113
Name TOTAL_D: #REF!
Name TOTAL_D: 'Section D'!$F$75
Name TOTAL_D: 'Section D'!$F$75
Name TOTAL_E: #REF!
Name TOTAL_E: 'Section E'!$F$33
Name TOTAL_E: 'Section E'!$F$33
Name TOTAL_F: #REF!
Name TOTAL_F: 'Section F'!$F$34
Name TOTAL_F: 'Section F'!$F$34
Name TOTAL_G: #REF!
Name TOTAL_G: 'Section G'!$F$25
Name TOTAL_G: 'Section G'!$F$25
Name TOTAL_H: #REF!
Name TOTAL_H: 'Section H'!$F$68
Name TOTAL_H: 'Section H'!$F$68
Name TOTAL_I: #REF!
Name TOTAL_I: 'Section I'!$F$49
Name TOTAL_I: 'Section I'!$F$49
Name TOTAL_J: #REF!
Name TOTAL_J: 'Section J'!$F$37
Name TOTAL_J: 'Section J'!$F$37
Name TOTAL_K: #REF!
Name TOTAL_K: 'Section K'!$F$127
Name TOTAL_K: 'Section K'!$F$127
Name TOTAL_L: #REF!
Name TOTAL_L: 'Section L'!$F$17
Name TOTAL_L: 'Section L'!$F$17

Sheet Section A
A7: Number | B7: Item description | C7: Unit | D7: Quantity | E7: Rate | F7: Amount
E8: € | F8: €
A9: A | B9: General items, provisional services and additional items
A10: A1 | B10: Offices and stores for the Contractor | C10: sum | D10: N/A | E10: N/A | F10: =IF(ISNUMBER(SEARCH("incl",$D10)),"-",IF(ISNUMBER(SEARCH("not r",$D10)),"-",IF(C10="sum","",$D10*$E10)))
A11: A2 | B11: Establish on site all plant, equipment and services for a Green Category site | C11: sum | D11: N/A | E11: N/A | F11: =IF(ISNUMBER(SEARCH("incl",$D11)),"-",IF(ISNUMBER(SEARCH("not r",$D11)),"-",IF(C11="sum","",$D11*$E11)))
A12: A2.1 | B12: Establish on site cable percussion ('shell l auger') boring plant and equipment for a Green Category site | C12: sum | D12: N/A | E12: N/A | F12: =IF(ISNUMBER(SEARCH("incl",$D12)),"-",IF(ISNUMBER(SEARCH("not r",$D12)),"-",IF(C12="sum","",$D12*$E12)))
A13: A2.2 | B13: Establish on site rotary drilling plant and equipment for a Green Category site | C13: sum | D13: N/A | E13: N/A | F13: =IF(ISNUMBER(SEARCH("incl",$D13)),"-",IF(ISNUMBER(SEARCH("not r",$D13)),"-",IF(C13="sum","",$D13*$E13)))
A14: A2.3 | B14: Establish on site Geobor S rotary drilling plant and equipment for a Green Category site (PROVISIONAL) | C14: sum | D14: Not Required | E14: N/A | F14: =IF(ISNUMBER(SEARCH("incl",$D14)),"-",IF(ISNUMBER(SEARCH("not r",$D14)),"-",IF(C14="sum","",$D14*$E14))) -> -
A15: A2.4 | B15: Establish on site trial pitting and trenching plant and equipment for a Green Category site | C15: sum | D15: N/A | E15: N/A | F15: =IF(ISNUMBER(SEARCH("incl",$D15)),"-",IF(ISNUMBER(SEARCH("not r",$D15)),"-",IF(C15="sum","",$D15*$E15)))
A16: A2.5 | B16: Establish on site in situ test and sampling equipment for a Green Category site | C16: sum | D16: N/A | E16: N/A | F16: =IF(ISNUMBER(SEARCH("incl",$D16)),"-",IF(ISNUMBER(SEARCH("not r",$D16)),"-",IF(C16="sum","",$D16*$E16)))
A17: A2.6 | B17: Establish on site cone penetration testing (CPT) plant and equipment for a Green Category site | C17: sum | D17: Not Required | E17: N/A | F17: =IF(ISNUMBER(SEARCH("incl",$D17)),"-",IF(ISNUMBER(SEARCH("not r",$D17)),"-",IF(C17="sum","",$D17*$E17))) -> -
A18: A2.7 | B18: Establish on site dynamic sampling and probing plant and equipment for a Green Category site | C18: sum | D18: N/A | E18: N/A | F18: =IF(ISNUMBER(SEARCH("incl",$D18)),"-",IF(ISNUMBER(SEARCH("not r",$D18)),"-",IF(C18="sum","",$D18*$E18)))
A19: A2.8 | B19: Establish on site geophysical survey equipment for a Green Category site | C19: sum | D19: Not Required | E19: N/A | F19: =IF(ISNUMBER(SEARCH("incl",$D19)),"-",IF(ISNUMBER(SEARCH("not r",$D19)),"-",IF(C19="sum","",$D19*$E19))) -> -
A20: A2.9 | B20: Establish on site instrumentation equipment as required for a Green Category site | C20: sum | D20: N/A | E20: N/A | F20: =IF(ISNUMBER(SEARCH("incl",$D20)),"-",IF(ISNUMBER(SEARCH("not r",$D20)),"-",IF(C20="sum","",$D20*$E20)))
A21: A3.1 | B21: Extra over item A2.1 - A2.9 for a yellow category site (Provisional) | C21: sum | D21: Not Required | E21: N/A | F21: =IF(ISNUMBER(SEARCH("incl",$D21)),"-",IF(ISNUMBER(SEARCH("not r",$D21)),"-",IF(C21="sum","",$D21*$E21))) -> -
... A26: A5.2 | B26: Decontamination of equipment during and at end of intrusive investigation for a Red Category site | C26: sum | D26: Not Required | E26: N/A | F26: =IF(ISNUMBER(SEARCH("incl",$D26)),"-",IF(ISNUMBER(SEARCH("not r",$D26)),"-",IF(C26="sum","",$D26*$E26))) -> -
A27: A6 | B27: Appropriate storage, transport and off-site disposal of excess contaminated arising’s from borehole, trial pit or slit trench to EPA regulated landfill site (includes any PPE equipment but excludes laboratory testing on suspected contaminated materials). Note item to be remeasured with delivery dockets and records maintained by the Contractor [PROVISIONAL] | C27: Provisional sum | D27: N/A | E27: N/A | F27: 1500
A28: A6.1 | B28: Contractor's uplift on Item A6 | C28: % | E28: N/A | F28: =F27*D28 -> 0 | G28: formula works | L28: =IF(OR(D28="not*",D28="*Incl*"),"-","") | M28: =IF(ISNUMBER(SEARCH("incl",$D28)),"-",IF(ISNUMBER(SEARCH("not r",$D28)),"-",$D28*$E28)) -> #VALUE!
A29: A7 | B29: Provide professional attendance to meet the contract requirements | C29: sum | D29: N/A | E29: N/A | F29: =IF(ISNUMBER(SEARCH("incl",$D29)),"-",IF(ISNUMBER(SEARCH("not r",$D29)),"-",IF(C29="sum","",$D29*$E29)))
A30: A7.1 | B30: Provide Technician | C30: per day | D30: Included in A7 | E30: N/A | F30: =IF(ISNUMBER(SEARCH("incl",$D30)),"-",IF(ISNUMBER(SEARCH("not r",$D30)),"-",IF(C30="sum","",$D30*$E30))) -> -
A31: A7.2 | B31: Provide Engineer / Geologist (as per item 2.3 of Specification) | C31: per day | D31: Included in A7 | E31: N/A | F31: =IF(ISNUMBER(SEARCH("incl",$D31)),"-",IF(ISNUMBER(SEARCH("not r",$D31)),"-",IF(C31="sum","",$D31*$E31))) -> -
A32: A7.3 | B32: Provide Chartered Engineer / Professional Geologist (as item 2.3 of Specification) | C32: per day | D32: Included in A7 | E32: N/A | F32: =IF(ISNUMBER(SEARCH("incl",$D32)),"-",IF(ISNUMBER(SEARCH("not r",$D32)),"-",IF(C32="sum","",$D32*$E32))) -> -
A33: A7.4 | B33: Provide Chartered Engineer / Professional Geologist (+10 years experience post charter) | C33: per day | D33: Included in A7 | E33: N/A | F33: =IF(ISNUMBER(SEARCH("incl",$D33)),"-",IF(ISNUMBER(SEARCH("not r",$D33)),"-",IF(C33="sum","",$D33*$E33))) -> -
A34: A7.5 | B34: Provide Chartered Engineer / Professional Geologist (+20 years experience post charter) | C34: per day | D34: Included in A7 | E34: N/A | F34: =IF(ISNUMBER(SEARCH("incl",$D34)),"-",IF(ISNUMBER(SEARCH("not r",$D34)),"-",IF(C34="sum","",$D34*$E34))) -> - | J34: CP only | K34: RC follow on + only | L34: TP
A35: A8 | B35: Set out the location at each exploratory hole or point | C35: Nr | D35: =G35 -> 0 | F35: =IF(ISNUMBER(SEARCH("incl",$D35)),"-",IF(ISNUMBER(SEARCH("not r",$D35)),"-",IF(C35="sum","",$D35*$E35))) -> 0 | G35: =SUM(J35:L35) -> 0 | J35: ='Section B'!H11+'Section B'!H12 -> 0 | K35: ='Section C'!H29+'Section C'!H31 -> 1 | L35: ='Section D'!H15 -> -1
A36: A8.1 | B36: Establish the location and elevation (X, Y, Z) of the ground at each 'as-built' exploratory hole or point | C36: nr | D36: =D35 -> 0 | F36: =IF(ISNUMBER(SEARCH("incl",$D36)),"-",IF(ISNUMBER(SEARCH("not r",$D36)),"-",IF(C36="sum","",$D36*$E36))) -> 0 | G36: =G35 -> 0
A37: A9 | B37: Preparation of Health and Safety documentation and Safety Risk Assessment | C37: sum | D37: N/A | E37: N/A | F37: =IF(ISNUMBER(SEARCH("incl",$D37)),"-",IF(ISNUMBER(SEARCH("not r",$D37)),"-",IF(C37="sum","",$D37*$E37)))
A38: A10 | B38: Facilities for the Investigation Supervisor | C38: per week | D38: Not Required | E38: N/A | F38: =IF(ISNUMBER(SEARCH("incl",$D38)),"-",IF(ISNUMBER(SEARCH("not r",$D38)),"-",IF(C38="sum","",$D38*$E38))) -> - | G38: Not full time sup
A39: A11 | B39: Vehicle(s) for the Investigation Supervisor | C39: vehicle wk | D39: Not Required | E39: N/A | F39: =IF(ISNUMBER(SEARCH("incl",$D39)),"-",IF(ISNUMBER(SEARCH("not r",$D39)),"-",IF(C39="sum","",$D39*$E39))) -> -
A40: A11.1 | B40: Provision of fuel and tolls for A11 (to be reimbursed under the contract) | C40: provisional sum | D40: Not Required | E40: N/A | F40: =IF(ISNUMBER(SEARCH("incl",$D40)),"-",IF(ISNUMBER(SEARCH("not r",$D40)),"-",IF(C40="sum","",$D40*$E40))) -> -
A41: A11.2 | B41: Contractors uplift on item A11 and A11.1 | C41: % uplift | D41: Not Required | E41: N/A | F41: =IF(ISNUMBER(SEARCH("incl",$D41)),"-",IF(ISNUMBER(SEARCH("not r",$D41)),"-",IF(C41="sum","",$D41*$E41))) -> -
A42: A12 | B42: Provision of phone and internet for the Investigation Supervisor (to be reimbursed under the contract) | C42: provisional sum | D42: Not Required | E42: N/A | F42: =IF(ISNUMBER(SEARCH("incl",$D42)),"-",IF(ISNUMBER(SEARCH("not r",$D42)),"-",IF(C42="sum","",$D42*$E42))) -> -
A43: A12.1 | B43: Contractors Uplift on item A12 | C43: % uplift | D43: Not Required | E43: N/A | F43: =IF(ISNUMBER(SEARCH("incl",$D43)),"-",IF(ISNUMBER(SEARCH("not r",$D43)),"-",IF(C43="sum","",$D43*$E43))) -> -
A44: A13 | B44: Deliver selected cores and samples specified Client address (address to be advised) | C44: provisional sum | D44: Not Required | E44: N/A | F44: =IF(ISNUMBER(SEARCH("incl",$D44)),"-",IF(ISNUMBER(SEARCH("not r",$D44)),"-",IF(C44="sum","",$D44*$E44))) -> -
A45: A14 | B45: Special additional testing and sampling required by Investigation Supervisor | C45: provisional sum | D45: Not Required | E45: N/A | F45: =IF(ISNUMBER(SEARCH("incl",$D45)),"-",IF(ISNUMBER(SEARCH("not r",$D45)),"-",IF(C45="sum","",$D45*$E45))) -> -
A46: A15 | B46: Traffic safety and management to include preparation of traffic management drawings for investigations on roads or pavement areas | C46: sum | D46: N/A | E46: N/A | F46: =IF(ISNUMBER(SEARCH("incl",$D46)),"-",IF(ISNUMBER(SEARCH("not r",$D46)),"-",IF(C46="sum","",$D46*$E46)))
A47: A16 | B47: Provision of road opening licences and road damage bonds | C47: sum | D47: Not Required | E47: N/A | F47: =IF(ISNUMBER(SEARCH("incl",$D47)),"-",IF(ISNUMBER(SEARCH("not r",$D47)),"-",IF(C47="sum","",$D47*$E47))) -> -
A48: A17 | B48: Contractors uplift on items A15 and A16 | C48: % uplift | D48: Not Required | E48: N/A | F48: =IF(ISNUMBER(SEARCH("incl",$D48)),"-",IF(ISNUMBER(SEARCH("not r",$D48)),"-",IF(C48="sum","",$D48*$E48))) -> -
A49: A18 | B49: One master copy of Desk Study Report | C49: sum | D49: Not Required | E49: N/A | F49: =IF(ISNUMBER(SEARCH("incl",$D49)),"-",IF(ISNUMBER(SEARCH("not r",$D49)),"-",IF(C49="sum","",$D49*$E49))) -> -
A50: A18.1 | B50: Additional hard copy of Desk Study Report | C50: nr | D50: Not Required | E50: N/A | F50: =IF(ISNUMBER(SEARCH("incl",$D50)),"-",IF(ISNUMBER(SEARCH("not r",$D50)),"-",IF(C50="sum","",$D50*$E50))) -> -
...

Sheet Section B
J1: Open Hole
I2: CALC | J2: NEW | K2: ='Log Schedule'!A2 -> BH 1 | L2: ='Log Schedule'!A3 -> BH 2 | M2: ='Log Schedule'!A4 -> 0 | N2: ='Log Schedule'!A5 -> 0
I3: 10 | J3: BH (m) | K3: ='Log Schedule'!C2 -> 19
I4: 5 | J4: CP (m) | K4: ='Log Schedule'!F2 -> 8
J5: Rot | K5: =K3-K4 -> 11 | L5: =L3-L4 -> 0 | M5: =M3-M4 -> 0 | N5: =N3-N4 -> 0 | O5: =O3-O4 -> 0 | P5: =P3-P4 -> 0 | Q5: =Q3-Q4 -> 0 | R5: =R3-R4 -> 0 | ... AW5: =AW3-AW4 -> 0
J6: CRASH BARRIER | K6: 0 | L6: 0 | M6: 0 | N6: 0 | O6: 0 | P6: 0 | Q6: 0 | R6: 0 | S6: 0 | T6: 0 | U6: 0 | V6: 0 | W6: 0 | X6: 0 | Y6: 0 | Z6: 0 | AA6: 0 | AB6: 0 | AC6: 0 | AD6: 0 | AE6: 0 | AF6: 0 | AG6: 0 | AH6: 0 | AI6: 0 | AJ6: 0 | AK6: 0 | AL6: 0 | AM6: 0 | AN6: 0 | AO6: 0 | AP6: 0 | AQ6: 0 | AR6: 0 | AS6: 0 | AT6: 0 | AU6: 0 | AV6: 0 | AW6: 0
A7: Number | B7: Item description | C7: Unit | D7: Quantity | E7: Rate | F7: Amount | H7: Totals | J7: Paved Area
E8: € | F8: € | J8: verge
A9: B | B9: Cable Percussion Boring (cable tool or percussive boring using minimum of 200mm diameter casing)
A10: B1 | B10: Move boring plant and equipment to the site of each exploratory hole and set up (cable percussive only) | C10: Refer to items B1.1 and B1.2 | D10: Refer to items B1.1 and B1.2 | E10: N/A | F10: =IF(ISNUMBER(SEARCH("incl",$D10)),"-",IF(ISNUMBER(SEARCH("not r",$D10)),"-",IF(ISNUMBER(SEARCH("refer",$D10)),"-",IF(C10="sum","",$D10*$E10)))) -> - | H10: =SUM(K10:AU10) -> 0
A11: B1.1.1 | B11: Move boring plant and equipment to the site of each exploratory hole, set up, dismantle on completion and reinstate (cable percussive only) | C11: nr | D11: 25 | F11: =IF(ISNUMBER(SEARCH("incl",$D11)),"-",IF(ISNUMBER(SEARCH("not r",$D11)),"-",IF(ISNUMBER(SEARCH("refer",$D11)),"-",IF(C11="sum","",$D11*$E11)))) -> 0 | H11: =SUM(K11:AU11) -> 0 | I11: added item & includes reinstatement check preamble | K11: =IF(K$3>0,IF(K$5>0,0,IF(K$6=0,1,0)),0) -> 0 | L11: =IF(L$3>0,IF(L$5>0,0,IF(L$6=0,1,0)),0) -> 0 | M11: =IF(M$3>0,IF(M$5>0,0,IF(M$6=0,1,0)),0) -> 0 | N11: =IF(N$3>0,IF(N$5>0,0,IF(N$6=0,1,0)),0) -> 0 | O11: =IF(O$3>0,IF(O$5>0,0,IF(O$6=0,1,0)),0) -> 0 | P11: =IF(P$3>0,IF(P$5>0,0,IF(P$6=0,1,0)),0) -> 0 | Q11: =IF(Q$3>0,IF(Q$5>0,0,IF(Q$6=0,1,0)),0) -> 0 | R11: =IF(R$3>0,IF(R$5>0,0,IF(R$6=0,1,0)),0) -> 0 | ... AW11: =IF(AW$3>0,IF(AW$5>0,0,IF(AW$6=0,1,0)),0) -> 0 | AY11: IF(AK$2>0,IF(AK$4>0,0,IF(AK$5=0,1,0)),0)
A12: B1.1.2 | B12: Move boring plant and equipment to the site of each exploratory hole over safety barrier or other fence or wall, set up, dismantle on completion and reinstate (cable percussive only) | C12: nr | D12: =H12 -> 0 | F12: =IF(ISNUMBER(SEARCH("incl",$D12)),"-",IF(ISNUMBER(SEARCH("not r",$D12)),"-",IF(ISNUMBER(SEARCH("refer",$D12)),"-",IF(C12="sum","",$D12*$E12)))) -> 0 | H12: =SUM(K12:AU12) -> 0 | K12: =IF(K$3>0,IF(K$4>0,0,IF(K$6=0,0,1)),0) -> 0 | L12: =IF(L$3>0,IF(L$4>0,0,IF(L$6=0,0,1)),0) -> 0 | M12: =IF(M$3>0,IF(M$4>0,0,IF(M$6=0,0,1)),0) -> 0 | N12: =IF(N$3>0,IF(N$4>0,0,IF(N$6=0,0,1)),0) -> 0 | O12: =IF(O$3>0,IF(O$4>0,0,IF(O$6=0,0,1)),0) -> 0 | P12: =IF(P$3>0,IF(P$4>0,0,IF(P$6=0,0,1)),0) -> 0 | Q12: =IF(Q$3>0,IF(Q$4>0,0,IF(Q$6=0,0,1)),0) -> 0 | R12: =IF(R$3>0,IF(R$4>0,0,IF(R$6=0,0,1)),0) -> 0 | ... AW12: =IF(AW$3>0,IF(AW$4>0,0,IF(AW$6=0,0,1)),0) -> 0 | AY12: IF(AK$2>0 | BA12: IF(AK$3>0 | BC12: IF(AK$5=0 | BD12: 1
A13: B1.2.1 | B13: Move boring plant and equipment to the site of each exploratory hole, set up, dismantle on completion and reinstate (where borehole is to be followed on with rotary drilling) | C13: nr | D13: =H13 -> 1 | F13: =IF(ISNUMBER(SEARCH("incl",$D13)),"-",IF(ISNUMBER(SEARCH("not r",$D13)),"-",IF(ISNUMBER(SEARCH("refer",$D13)),"-",IF(C13="sum","",$D13*$E13)))) -> 0 | H13: =SUM(K13:AU13) -> 1 | K13: =IF(K$3>0,IF(K$4>0,IF(K5=0,0,IF(K$6=0,1,0)),0),0) -> 1 | L13: =IF(L$3>0,IF(L$4>0,IF(L5=0,0,IF(L$6=0,1,0)),0),0) -> 0 | M13: =IF(M$3>0,IF(M$4>0,IF(M5=0,0,IF(M$6=0,1,0)),0),0) -> 0 | N13: =IF(N$3>0,IF(N$4>0,IF(N5=0,0,IF(N$6=0,1,0)),0),0) -> 0 | O13: =IF(O$3>0,IF(O$4>0,IF(O5=0,0,IF(O$6=0,1,0)),0),0) -> 0 | P13: =IF(P$3>0,IF(P$4>0,IF(P5=0,0,IF(P$6=0,1,0)),0),0) -> 0 | Q13: =IF(Q$3>0,IF(Q$4>0,IF(Q5=0,0,IF(Q$6=0,1,0)),0),0) -> 0 | R13: =IF(R$3>0,IF(R$4>0,IF(R5=0,0,IF(R$6=0,1,0)),0),0) -> 0 | ... AW13: =IF(AW$3>0,IF(AW$4>0,IF(AW5=0,0,IF(AW$6=0,1,0)),0),0) -> 0 | AY13: 0 | BA13: IF(AK$5=0 | BC13: 0
A14: B1.2.2 | B14: Move boring plant and equipment to the site of each exploratory hole over safety barrier or other fence or wall, set up, dismantle on completion and reinstate (where borehole is to be followed on with rotary drilling) | C14: nr | D14: =H14 -> 0 | F14: =IF(ISNUMBER(SEARCH("incl",$D14)),"-",IF(ISNUMBER(SEARCH("not r",$D14)),"-",IF(ISNUMBER(SEARCH("refer",$D14)),"-",IF(C14="sum","",$D14*$E14)))) -> 0 | H14: =SUM(K14:AU14) -> 0 | K14: =IF(K$3>0,IF(K$4>0,IF(K5=0,0,IF(K$6=0,0,1)),0)) -> 0 | L14: =IF(L$3>0,IF(L$4>0,IF(L5=0,0,IF(L$6=0,0,1)),0)) -> FALSE | M14: =IF(M$3>0,IF(M$4>0,IF(M5=0,0,IF(M$6=0,0,1)),0)) -> FALSE | N14: =IF(N$3>0,IF(N$4>0,IF(N5=0,0,IF(N$6=0,0,1)),0)) -> FALSE | O14: =IF(O$3>0,IF(O$4>0,IF(O5=0,0,IF(O$6=0,0,1)),0)) -> FALSE | P14: =IF(P$3>0,IF(P$4>0,IF(P5=0,0,IF(P$6=0,0,1)),0)) -> FALSE | Q14: =IF(Q$3>0,IF(Q$4>0,IF(Q5=0,0,IF(Q$6=0,0,1)),0)) -> FALSE | R14: =IF(R$3>0,IF(R$4>0,IF(R5=0,0,IF(R$6=0,0,1)),0)) -> FALSE | ... AW14: =IF(AW$3>0,IF(AW$4>0,IF(AW5=0,0,IF(AW$6=0,0,1)),0)) -> FALSE | BA14: 0
A15: B2 | B15: Extra over Item B1 for setting up on a slope of gradient greater than 20% | C15: Refer to items B2.1 and B2.2 | D15: Refer to items B2.1 and B2.2 | E15: N/A | F15: =IF(ISNUMBER(SEARCH("incl",$D15)),"-",IF(ISNUMBER(SEARCH("not r",$D15)),"-",IF(ISNUMBER(SEARCH("refer",$D15)),"-",IF(C15="sum","",$D15*$E15)))) -> - | H15: =SUM(K15:AU15) -> 0 | I15: none | R15: 0
A16: B2.1 | B16: Extra over Item B1.1 for setting up on a slope of gradient greater than 20% | C16: nr | D16: Not Required | E16: N/A | F16: =IF(ISNUMBER(SEARCH("incl",$D16)),"-",IF(ISNUMBER(SEARCH("not r",$D16)),"-",IF(ISNUMBER(SEARCH("refer",$D16)),"-",IF(C16="sum","",$D16*$E16)))) -> - | H16: =SUM(K16:AU16) -> 0 | R16: 0
A17: B2.2 | B17: Extra over Item B1.2 for setting up on a slope of gradient greater than 20% | C17: nr | D17: Not Required | E17: N/A | F17: =IF(ISNUMBER(SEARCH("incl",$D17)),"-",IF(ISNUMBER(SEARCH("not r",$D17)),"-",IF(ISNUMBER(SEARCH("refer",$D17)),"-",IF(C17="sum","",$D17*$E17)))) -> - | H17: =SUM(K17:AU17) -> 0
A18: B3 | B18: Hand digging and CAT scan at borehole location to confirm absence of utility ducts (maximum depth of 1.2m or lesser if ground is assessed as potentially unstable) | C18: nr | D18: =H18 -> 1 | F18: =IF(ISNUMBER(SEARCH("incl",$D18)),"-",IF(ISNUMBER(SEARCH("not r",$D18)),"-",IF(ISNUMBER(SEARCH("refer",$D18)),"-",IF(C18="sum","",$D18*$E18)))) -> 0 | H18: =SUM(K18:AU18) -> 1 | I18: 1 | J18: per BH | K18: =MAX(K$11:K$13) -> 1 | L18: =IF(L4>0,1,0) -> 0 | M18: =MAX(M$11:M$13) -> 0 | N18: =MAX(N$11:N$13) -> 0 | O18: =IF(O4>0,1,0) -> 0 | P18: =IF(P4>0,1,0) -> 0 | Q18: =IF(Q4>0,1,0) -> 0 | R18: =IF(R4>0,1,0) -> 0 | S18: =IF(S4>0,1,0) -> 0 | T18: =IF(T4>0,1,0) -> 0 | U18: =IF(U4>0,1,0) -> 0 | V18: =IF(V4>0,1,0) -> 0 | ... AW18: =IF(AW4>0,1,0) -> 0
A19: B3.1 | B19: Break out obstructions where present when hand digging at exploratory hole location for Item B3. | C19: m3 | D19: =H19 -> 1 | F19: =IF(ISNUMBER(SEARCH("incl",$D19)),"-",IF(ISNUMBER(SEARCH("not r",$D19)),"-",IF(ISNUMBER(SEARCH("refer",$D19)),"-",IF(C19="sum","",$D19*$E19)))) -> 0 | H19: 1 | I19: 0.25 | J19: m thick x1m2 | K19: =$I19*K$7 -> 0 | L19: =$I19*L$7 -> 0 | M19: =$I19*M$7 -> 0 | N19: =$I19*N$7 -> 0 | O19: =$I19*O$7 -> 0 | P19: =$I19*P$7 -> 0 | Q19: =$I19*Q$7 -> 0 | R19: =$I19*R$7 -> 0 | ... AW19: =$I19*AW$7 -> 0
A20: B4 | B20: Advance borehole between existing ground level and 10 m depth | C20: m | D20: =H20 -> 8 | F20: =IF(ISNUMBER(SEARCH("incl",$D20)),"-",IF(ISNUMBER(SEARCH("not r",$D20)),"-",IF(ISNUMBER(SEARCH("refer",$D20)),"-",IF(C20="sum","",$D20*$E20)))) -> 0 | H20: =SUM(K20:AU20)-I20 -> 8 | J20: take away for OH/Core as obstruct | K20: =IF(K$4>10,10,K$4) -> 8 | L20: =IF(L$4>10,10,L$4) -> 0 | M20: =IF(M$4>10,10,M$4) -> 0 | N20: =IF(N$4>10,10,N$4) -> 0 | O20: =IF(O$4>10,10,O$4) -> 0 | P20: =IF(P$4>10,10,P$4) -> 0 | Q20: =IF(Q$4>10,10,Q$4) -> 0 | R20: =IF(R$4>10,10,R$4) -> 0 | ... AW20: =IF(AW$4>10,10,AW$4) -> 0
A21: B5 | B21: As Item B4 but between 10 m and 20 m depth | C21: m | D21: =H21 -> 0 | F21: =IF(ISNUMBER(SEARCH("incl",$D21)),"-",IF(ISNUMBER(SEARCH("not r",$D21)),"-",IF(ISNUMBER(SEARCH("refer",$D21)),"-",IF(C21="sum","",$D21*$E21)))) -> 0 | H21: =SUM(K21:AU21) -> 0 | K21: =IF(K$4>20,10,IF(K$4>10,K$4-10,0)) -> 0 | L21: =IF(L$4>20,10,IF(L$4>10,L$4-10,0)) -> 0 | M21: =IF(M$4>20,10,IF(M$4>10,M$4-10,0)) -> 0 | N21: =IF(N$4>20,10,IF(N$4>10,N$4-10,0)) -> 0 | O21: =IF(O$4>20,10,IF(O$4>10,O$4-10,0)) -> 0 | P21: =IF(P$4>20,10,IF(P$4>10,P$4-10,0)) -> 0 | Q21: =IF(Q$4>20,10,IF(Q$4>10,Q$4-10,0)) -> 0 | R21: =IF(R$4>20,10,IF(R$4>10,R$4-10,0)) -> 0 | ... AW21: =IF(AW$4>20,10,IF(AW$4>10,AW$4-10,0)) -> 0
A22: B6 | B22: As Item B4 but between 20 m and 30 m depth | C22: m | D22: Not Required | E22: N/A | F22: =IF(ISNUMBER(SEARCH("incl",$D22)),"-",IF(ISNUMBER(SEARCH("not r",$D22)),"-",IF(ISNUMBER(SEARCH("refer",$D22)),"-",IF(C22="sum","",$D22*$E22)))) -> - | H22: =SUM(K22:AU22) -> 0 | K22: =IF(K$4>30,10,IF(K$4>20,K$4-20,0)) -> 0 | L22: =IF(L$4>30,10,IF(L$4>20,L$4-20,0)) -> 0 | M22: =IF(M$4>30,10,IF(M$4>20,M$4-20,0)) -> 0 | N22: =IF(N$4>30,10,IF(N$4>20,N$4-20,0)) -> 0 | O22: =IF(O$4>30,10,IF(O$4>20,O$4-20,0)) -> 0 | P22: =IF(P$4>30,10,IF(P$4>20,P$4-20,0)) -> 0 | Q22: =IF(Q$4>30,10,IF(Q$4>20,Q$4-20,0)) -> 0 | R22: =IF(R$4>30,10,IF(R$4>20,R$4-20,0)) -> 0 | ... AW22: =IF(AW$4>30,10,IF(AW$4>20,AW$4-20,0)) -> 0
A23: B7 | B23: As Item B4 but between 30 m and 40 m depth | C23: m | D23: Not Required | E23: N/A | F23: =IF(ISNUMBER(SEARCH("incl",$D23)),"-",IF(ISNUMBER(SEARCH("not r",$D23)),"-",IF(ISNUMBER(SEARCH("refer",$D23)),"-",IF(C23="sum","",$D23*$E23)))) -> - | H23: =SUM(K23:AU23) -> 0 | K23: =IF(K$4>40,10,IF(K$4>30,K$4-30,0)) -> 0 | L23: =IF(L$4>40,10,IF(L$4>30,L$4-30,0)) -> 0 | M23: =IF(M$4>40,10,IF(M$4>30,M$4-30,0)) -> 0 | N23: =IF(N$4>40,10,IF(N$4>30,N$4-30,0)) -> 0 | O23: =IF(O$4>40,10,IF(O$4>30,O$4-30,0)) -> 0 | P23: =IF(P$4>40,10,IF(P$4>30,P$4-30,0)) -> 0 | Q23: =IF(Q$4>40,10,IF(Q$4>30,Q$4-30,0)) -> 0 | R23: =IF(R$4>40,10,IF(R$4>30,R$4-30,0)) -> 0 | ... AW23: =IF(AW$4>40,10,IF(AW$4>30,AW$4-30,0)) -> 0
A24: B8 | B24: As Item B4 but between 40 m and 50 m depth | C24: m | D24: Not Required | E24: N/A | F24: =IF(ISNUMBER(SEARCH("incl",$D24)),"-",IF(ISNUMBER(SEARCH("not r",$D24)),"-",IF(ISNUMBER(SEARCH("refer",$D24)),"-",IF(C24="sum","",$D24*$E24)))) -> - | H24: =SUM(K24:AU24) -> 0 | K24: =IF(K$4>50,10,IF(K$4>40,K$4-40,0)) -> 0 | L24: =IF(L$4>50,10,IF(L$4>40,L$4-40,0)) -> 0 | M24: =IF(M$4>50,10,IF(M$4>40,M$4-40,0)) -> 0 | N24: =IF(N$4>50,10,IF(N$4>40,N$4-40,0)) -> 0 | O24: =IF(O$4>50,10,IF(O$4>40,O$4-40,0)) -> 0 | P24: =IF(P$4>50,10,IF(P$4>40,P$4-40,0)) -> 0 | Q24: =IF(Q$4>50,10,IF(Q$4>40,Q$4-40,0)) -> 0 | R24: =IF(R$4>50,10,IF(R$4>40,R$4-40,0)) -> 0 | ... AW24: =IF(AW$4>50,10,IF(AW$4>40,AW$4-40,0)) -> 0
A25: B9 | B25: Advance borehole through hard stratum or obstruction | C25: h | D25: =H25 -> 2 | F25: =IF(ISNUMBER(SEARCH("incl",$D25)),"-",IF(ISNUMBER(SEARCH("not r",$D25)),"-",IF(ISNUMBER(SEARCH("refer",$D25)),"-",IF(C25="sum","",$D25*$E25)))) -> 0 | H25: =SUM(K25:AU25) -> 2 | I25: 2 | J25: per CP | K25: =MAX(K$11:K$13)*$I25 -> 2 | L25: =MAX(L$11:L$13)*$I25 -> 0 | M25: =MAX(M$11:M$13)*$I25 -> 0 | N25: =MAX(N$11:N$13)*$I25 -> 0 | O25: =MAX(O$11:O$13)*$I25 -> 0 | P25: =MAX(P$11:P$13)*$I25 -> 0 | Q25: =MAX(Q$11:Q$13)*$I25 -> 0 | R25: =MAX(R$11:R$13)*$I25 -> 0 | ... AW25: =MAX(AW$11:AW$13)*$I25 -> 0
A26: B10 | B26: Provide aquifer protection measures at a single aquiclude/aquifer boundary or cross-contamination control measures at a single soil boundary in a borehole | C26: nr | D26: Not Required | E26: N/A | F26: =IF(ISNUMBER(SEARCH("incl",$D26)),"-",IF(ISNUMBER(SEARCH("not r",$D26)),"-",IF(ISNUMBER(SEARCH("refer",$D26)),"-",IF(C26="sum","",$D26*$E26)))) -> - | H26: =SUM(K26:AU26) -> 0
A27: B11 | B27: Backfill borehole with cement/bentonite grout or bentonite pellets (where standpipe piezometer is not installed) | C27: m³ | D27: =ROUNDUP(H27,0) -> 1 | F27: =IF(ISNUMBER(SEARCH("incl",$D27)),"-",IF(ISNUMBER(SEARCH("not r",$D27)),"-",IF(ISNUMBER(SEARCH("refer",$D27)),"-",IF(C27="sum","",$D27*$E27)))) -> 0 | H27: =SUM(K27:AU27) -> 0.25132741 | I27: 0.2 | J27: m dia | K27: =(PI()*$I27^2)/4*K$4 -> 0.25132741 | L27: =(PI()*$I27^2)/4*L$4 -> 0 | M27: =(PI()*$I27^2)/4*M$4 -> 0 | N27: =(PI()*$I27^2)/4*N$4 -> 0 | O27: =(PI()*$I27^2)/4*O$4 -> 0 | P27: =(PI()*$I27^2)/4*P$4 -> 0 | Q27: =(PI()*$I27^2)/4*Q$4 -> 0 | R27: =(PI()*$I27^2)/4*R$4 -> 0 | ... AW27: =(PI()*$I27^2)/4*AW$4 -> 0
A28: B12 | B28: Standing time for borehole plant, equipment and crew | C28: h | D28: =ROUNDUP(H28,0) -> 1 | F28: =IF(ISNUMBER(SEARCH("incl",$D28)),"-",IF(ISNUMBER(SEARCH("not r",$D28)),"-",IF(ISNUMBER(SEARCH("refer",$D28)),"-",IF(C28="sum","",$D28*$E28)))) -> 0 | H28: =SUM(K28:AU28) -> 0.5 | I28: 0.5 | J28: per CP | K28: =MAX(K$11:K$13)*$I28 -> 0.5 | L28: =MAX(L$11:L$13)*$I28 -> 0 | M28: =MAX(M$11:M$13)*$I28 -> 0 | N28: =MAX(N$11:N$13)*$I28 -> 0 | O28: =MAX(O$11:O$13)*$I28 -> 0 | P28: =MAX(P$11:P$13)*$I28 -> 0 | Q28: =MAX(Q$11:Q$13)*$I28 -> 0 | R28: =MAX(R$11:R$13)*$I28 -> 0 | ... AW28: =MAX(AW$11:AW$13)*$I28 -> 0
B29: Dynamic sampling (Windowless Sampling) | H29: =SUM(K29:AU29) -> 0
A30: B13 | B30: Move dynamic sampling equipment to the site of each exploratory hole and set up | C30: nr | D30: Not Required | F30: =IF(ISNUMBER(SEARCH("incl",$D30)),"-",IF(ISNUMBER(SEARCH("not r",$D30)),"-",IF(ISNUMBER(SEARCH("refer",$D30)),"-",IF(C30="sum","",$D30*$E30)))) -> - | H30: =SUM(K30:AU30) -> 0
A31: B14 | B31: Extra over Item B13 for setting up on a slope of gradient greater than 20% | C31: nr | D31: Not Required | F31: =IF(ISNUMBER(SEARCH("incl",$D31)),"-",IF(ISNUMBER(SEARCH("not r",$D31)),"-",IF(ISNUMBER(SEARCH("refer",$D31)),"-",IF(C31="sum","",$D31*$E31)))) -> - | H31: =SUM(K31:AU31) -> 0
A32: B15 | B32: Hand digging and CAT scan at dynamic sampling location to confirm absence of utility ducts (maximum depth of 1.2m or lesser if ground is assessed as potentially unstable) | C32: nr | D32: Not Required | F32: =IF(ISNUMBER(SEARCH("incl",$D32)),"-",IF(ISNUMBER(SEARCH("not r",$D32)),"-",IF(ISNUMBER(SEARCH("refer",$D32)),"-",IF(C32="sum","",$D32*$E32)))) -> - | H32: =SUM(K32:AU32) -> 0
A33: B16 | B33: Break out surface obstruction where present | C33: h | D33: Not Required | F33: =IF(ISNUMBER(SEARCH("incl",$D33)),"-",IF(ISNUMBER(SEARCH("not r",$D33)),"-",IF(ISNUMBER(SEARCH("refer",$D33)),"-",IF(C33="sum","",$D33*$E33)))) -> - | H33: =SUM(K33:AU33) -> 0
A34: B17 | B34: Advance dynamic sample hole between existing ground level and 5 m depth | C34: m | D34: Not Required | F34: =IF(ISNUMBER(SEARCH("incl",$D34)),"-",IF(ISNUMBER(SEARCH("not r",$D34)),"-",IF(ISNUMBER(SEARCH("refer",$D34)),"-",IF(C34="sum","",$D34*$E34)))) -> - | H34: =SUM(K34:AU34) -> 0
A35: B18 | B35: As Item B15 but between 5 and 10 m depth | C35: m | D35: Not Required | F35: =IF(ISNUMBER(SEARCH("incl",$D35)),"-",IF(ISNUMBER(SEARCH("not r",$D35)),"-",IF(ISNUMBER(SEARCH("refer",$D35)),"-",IF(C35="sum","",$D35*$E35)))) -> - | H35: =SUM(K35:AU35) -> 0
A36: B19 | B36: Dynamic sample=ing >10m as instructed by the Investigation Supervisor | C36: m | D36: Not Required | F36: =IF(ISNUMBER(SEARCH("incl",$D36)),"-",IF(ISNUMBER(SEARCH("not r",$D36)),"-",IF(ISNUMBER(SEARCH("refer",$D36)),"-",IF(C36="sum","",$D36*$E36)))) -> - | H36: =SUM(K36:AU36) -> 0
A37: B20 | B37: Standing time for dynamic sampling equipment and crew | C37: hr | D37: Not Required | F37: =IF(ISNUMBER(SEARCH("incl",$D37)),"-",IF(ISNUMBER(SEARCH("not r",$D37)),"-",IF(ISNUMBER(SEARCH("refer",$D37)),"-",IF(C37="sum","",$D37*$E37)))) -> - | H37: =SUM(K37:AU37) -> 0
A38: B21 | B38: Backfill dynamic sample borehole with cement/bentonite grout or bentonite pellets (where standpipe or piezometer is not installed) | C38: m³ | D38: Not Required | F38: =IF(ISNUMBER(SEARCH("incl",$D38)),"-",IF(ISNUMBER(SEARCH("not r",$D38)),"-",IF(ISNUMBER(SEARCH("refer",$D38)),"-",IF(C38="sum","",$D38*$E38)))) -> - | H38: =SUM(K38:AU38) -> 0
B39: Reinstatement of Cable Percussive Borehole and Dynamic Sample Borehole
A40: B22 | B40: Reinstatement of gravel hardstanding | C40: m² | D40: Included in B1.1 & B1.2 | E40: N/A | F40: =IF(ISNUMBER(SEARCH("incl",$D40)),"-",IF(ISNUMBER(SEARCH("not r",$D40)),"-",IF(ISNUMBER(SEARCH("refer",$D40)),"-",IF(C40="sum","",$D40*$E40)))) -> - | H40: =SUM(K40:AU40) -> 0 | I40: check preamble
...

Sheet Section C
J1: Open Hole | K1: ='Section B'!K1 -> 0 | L1: ='Section B'!L1 -> 0 | M1: ='Section B'!M1 -> 0 | N1: ='Section B'!N1 -> 0 | O1: ='Section B'!O1 -> 0 | P1: ='Section B'!P1 -> 0 | Q1: ='Section B'!Q1 -> 0 | R1: ='Section B'!R1 -> 0 | ... AW1: ='Section B'!AW1 -> 0
J2: NEW | K2: ='Section B'!K2 -> BH 1 | L2: ='Section B'!L2 -> BH 2 | M2: ='Section B'!M2 -> 0 | N2: ='Section B'!N2 -> 0 | O2: ='Section B'!O2 -> 0 | P2: ='Section B'!P2 -> 0 | Q2: ='Section B'!Q2 -> 0 | R2: ='Section B'!R2 -> 0 | ... AW2: ='Section B'!AW2 -> 0
B3: of each exploratory hole, set up, dismantle on completion and reinstate (cable percussive only) | I3: 10 | J3: BH (m) | K3: ='Section B'!K3 -> 19 | L3: ='Section B'!L3 -> 0 | M3: ='Section B'!M3 -> 0 | N3: ='Section B'!N3 -> 0 | O3: ='Section B'!O3 -> 0 | P3: ='Section B'!P3 -> 0 | Q3: ='Section B'!Q3 -> 0 | R3: ='Section B'!R3 -> 0 | ... AW3: ='Section B'!AW3 -> 0
H4: CALC | I4: 5 | J4: CP (m) | K4: ='Section B'!K4 -> 8 | L4: ='Section B'!L4 -> 0 | M4: ='Section B'!M4 -> 0 | N4: ='Section B'!N4 -> 0 | O4: ='Section B'!O4 -> 0 | P4: ='Section B'!P4 -> 0 | Q4: ='Section B'!Q4 -> 0 | R4: ='Section B'!R4 -> 0 | ... AW4: ='Section B'!AW4 -> 0
J5: Rot | K5: =K3-K4 -> 11 | L5: =L3-L4 -> 0 | M5: =M3-M4 -> 0 | N5: =N3-N4 -> 0 | O5: =O3-O4 -> 0 | P5: =P3-P4 -> 0 | Q5: =Q3-Q4 -> 0 | R5: =R3-R4 -> 0 | ... AW5: =AW3-AW4 -> 0
J6: CRASH BARRIER | K6: ='Section B'!K6 -> 0 | L6: ='Section B'!L6 -> 0 | M6: ='Section B'!M6 -> 0 | N6: ='Section B'!N6 -> 0 | O6: ='Section B'!O6 -> 0 | P6: ='Section B'!P6 -> 0 | Q6: ='Section B'!Q6 -> 0 | R6: ='Section B'!R6 -> 0 | ... AW6: ='Section B'!AW6 -> 0
A7: Number | B7: Item description | C7: Unit | D7: Quantity | E7: Rate | F7: Amount | H7: Totals
E8: € | F8: €
A9: C | B9: Rotary drilling
B10: Hand augering
A11: C1 | B11: Bring hand auger equipment to the position of each exploratory hole | C11: nr | D11: Not Required | F11: =IF(ISNUMBER(SEARCH("incl",$D11)),"-",IF(ISNUMBER(SEARCH("not r",$D11)),"-",IF(ISNUMBER(SEARCH("refer",$D11)),"-",IF(C11="sum","",$D11*$E11)))) -> - | H11: =SUM(K11:AU11) -> 0
A12: C2 | B12: Bore with hand auger from existing ground level to 2m depth | C12: m | D12: Not Required | F12: =IF(ISNUMBER(SEARCH("incl",$D12)),"-",IF(ISNUMBER(SEARCH("not r",$D12)),"-",IF(ISNUMBER(SEARCH("refer",$D12)),"-",IF(C12="sum","",$D12*$E12)))) -> - | H12: =SUM(K12:AU12) -> 0
A13: C3 | B13: As Item C2 but between 2 and 4m depth | C13: m | D13: Not Required | F13: =IF(ISNUMBER(SEARCH("incl",$D13)),"-",IF(ISNUMBER(SEARCH("not r",$D13)),"-",IF(ISNUMBER(SEARCH("refer",$D13)),"-",IF(C13="sum","",$D13*$E13)))) -> - | H13: =SUM(K13:AU13) -> 0
A14: C4 | B14: Standing time for hand auger equipment and crew | C14: h | D14: Not Required | F14: =IF(ISNUMBER(SEARCH("incl",$D14)),"-",IF(ISNUMBER(SEARCH("not r",$D14)),"-",IF(ISNUMBER(SEARCH("refer",$D14)),"-",IF(C14="sum","",$D14*$E14)))) -> - | H14: =SUM(K14:AU14) -> 0
A15: C5 | B15: Provision of hand augering equipment and crew for augering as directed by the Investigation Supervisor maximum depth 4m | C15: day | D15: Not Required | F15: =IF(ISNUMBER(SEARCH("incl",$D15)),"-",IF(ISNUMBER(SEARCH("not r",$D15)),"-",IF(ISNUMBER(SEARCH("refer",$D15)),"-",IF(C15="sum","",$D15*$E15)))) -> - | H15: =SUM(K15:AU15) -> 0
A16: C6 | B16: Backfill hand auger hole with cement/bentonite grout or bentonite pellets | C16: m | D16: Not Required | F16: =IF(ISNUMBER(SEARCH("incl",$D16)),"-",IF(ISNUMBER(SEARCH("not r",$D16)),"-",IF(ISNUMBER(SEARCH("refer",$D16)),"-",IF(C16="sum","",$D16*$E16)))) -> - | H16: =SUM(K16:AU16) -> 0
B17: Continuous flight and hollow-stem flight augering
A18: C7 | B18: Move mechanical augering plant and equipment to the site of each exploratory hole and set up. | C18: nr | D18: Not Required | F18: =IF(ISNUMBER(SEARCH("incl",$D18)),"-",IF(ISNUMBER(SEARCH("not r",$D18)),"-",IF(ISNUMBER(SEARCH("refer",$D18)),"-",IF(C18="sum","",$D18*$E18)))) -> - | H18: =SUM(K18:AU18) -> 0
A19: C7.1 | B19: Hand digging and CAT scan at rotary drillhole location to confirm absence of utility ducts ( maximum depth of 1.2m or lesser if ground is assessed as potentially unstable). | C19: nr | D19: Not Required | F19: =IF(ISNUMBER(SEARCH("incl",$D19)),"-",IF(ISNUMBER(SEARCH("not r",$D19)),"-",IF(ISNUMBER(SEARCH("refer",$D19)),"-",IF(C19="sum","",$D19*$E19)))) -> - | H19: =SUM(K19:AU19) -> 0
A20: C8 | B20: Extra over Item C7 for setting up on a slope of gradient greater than 20% | C20: nr | D20: Not Required | F20: =IF(ISNUMBER(SEARCH("incl",$D20)),"-",IF(ISNUMBER(SEARCH("not r",$D20)),"-",IF(ISNUMBER(SEARCH("refer",$D20)),"-",IF(C20="sum","",$D20*$E20)))) -> - | H20: =SUM(K20:AU20) -> 0
A21: C9 | B21: Break out obstructions where present when hand digging at auger hole location for Item C7.1. | C21: m3 | D21: Not Required | F21: =IF(ISNUMBER(SEARCH("incl",$D21)),"-",IF(ISNUMBER(SEARCH("not r",$D21)),"-",IF(ISNUMBER(SEARCH("refer",$D21)),"-",IF(C21="sum","",$D21*$E21)))) -> - | H21: =SUM(K21:AU21) -> 0
A22: C10 | B22: Standing time for rotary auger equipment and crew. | C22: h | D22: Not Required | F22: =IF(ISNUMBER(SEARCH("incl",$D22)),"-",IF(ISNUMBER(SEARCH("not r",$D22)),"-",IF(ISNUMBER(SEARCH("refer",$D22)),"-",IF(C22="sum","",$D22*$E22)))) -> - | H22: =SUM(K22:AU22) -> 0
A23: C11 | B23: Auger in materials other than hard strata at the specified diameter between existing ground level and 10m depth. | C23: m | D23: Not Required | F23: =IF(ISNUMBER(SEARCH("incl",$D23)),"-",IF(ISNUMBER(SEARCH("not r",$D23)),"-",IF(ISNUMBER(SEARCH("refer",$D23)),"-",IF(C23="sum","",$D23*$E23)))) -> - | H23: =SUM(K23:AU23) -> 0
A24: C12 | B24: As Item C11 but between 10 and 20m depth. | C24: m | D24: Not Required | F24: =IF(ISNUMBER(SEARCH("incl",$D24)),"-",IF(ISNUMBER(SEARCH("not r",$D24)),"-",IF(ISNUMBER(SEARCH("refer",$D24)),"-",IF(C24="sum","",$D24*$E24)))) -> - | H24: =SUM(K24:AU24) -> 0
A25: C13 | B25: As Item C11 but between 20 and 30m depth. | C25: m | D25: Not Required | F25: =IF(ISNUMBER(SEARCH("incl",$D25)),"-",IF(ISNUMBER(SEARCH("not r",$D25)),"-",IF(ISNUMBER(SEARCH("refer",$D25)),"-",IF(C25="sum","",$D25*$E25)))) -> - | H25: =SUM(K25:AU25) -> 0
A26: C14 | B26: Backfill auger hole with cement/bentonite grout or bentonite pellets (PROVISIONAL) | C26: m | D26: Not Required | F26: =IF(ISNUMBER(SEARCH("incl",$D26)),"-",IF(ISNUMBER(SEARCH("not r",$D26)),"-",IF(ISNUMBER(SEARCH("refer",$D26)),"-",IF(C26="sum","",$D26*$E26)))) -> - | H26: =SUM(K26:AU26) -> 0
B27: Rotary drilling with and without core recovery
A28: C15 | B28: Move rotary drilling plant and equipment to the site of each exploratory drillhole and set up. | C28: nr | D28: Refer to C15.1.1 to C15.2.2 & C15.3 | E28: Refer to C15.1 and C15.2 & C15.3 | F28: =IF(ISNUMBER(SEARCH("incl",$D28)),"-",IF(ISNUMBER(SEARCH("not r",$D28)),"-",IF(ISNUMBER(SEARCH("refer",$D28)),"-",IF(C28="sum","",$D28*$E28)))) -> - | H28: =SUM(K28:AU28) -> 0
A29: C15.1.1 | B29: Move rotary drilling plant and equipment to the site of each exploratory drillhole, set up, dismantle on completion and reinstate (rotary follow-on). | C29: nr | D29: =H29 -> 1 | F29: =IF(ISNUMBER(SEARCH("incl",$D29)),"-",IF(ISNUMBER(SEARCH("not r",$D29)),"-",IF(ISNUMBER(SEARCH("refer",$D29)),"-",IF(C29="sum","",$D29*$E29)))) -> 0 | H29: =SUM(K29:AU29) -> 1 | K29: =IF(K$5=0,0,IF(K$4=0,0,IF(K$6=0,1,0))) -> 1 | L29: =IF(L$5=0,0,IF(L$4=0,0,IF(L$6=0,1,0))) -> 0 | M29: =IF(M$5=0,0,IF(M$4=0,0,IF(M$6=0,1,0))) -> 0 | N29: =IF(N$5=0,0,IF(N$4=0,0,IF(N$6=0,1,0))) -> 0 | O29: =IF(O$5=0,0,IF(O$4=0,0,IF(O$6=0,1,0))) -> 0 | P29: =IF(P$5=0,0,IF(P$4=0,0,IF(P$6=0,1,0))) -> 0 | Q29: =IF(Q$5=0,0,IF(Q$4=0,0,IF(Q$6=0,1,0))) -> 0 | R29: =IF(R$5=0,0,IF(R$4=0,0,IF(R$6=0,1,0))) -> 0 | ... AW29: =IF(AW$5=0,0,IF(AW$4=0,0,IF(AW$6=0,1,0))) -> 0
A30: C15.1.2 | B30: Move rotary drilling plant and equipment to the site of each exploratory drillhole over safety barrier or other fence or wall, set up, dismantle on completion and reinstate (rotary follow-on). | C30: nr | D30: =H30 -> 0 | F30: =IF(ISNUMBER(SEARCH("incl",$D30)),"-",IF(ISNUMBER(SEARCH("not r",$D30)),"-",IF(ISNUMBER(SEARCH("refer",$D30)),"-",IF(C30="sum","",$D30*$E30)))) -> 0 | H30: =SUM(K30:AU30) -> 0 | K30: =IF(K$5=0,0,IF(K$4=0,0,IF(K$6=0,0,1))) -> 0 | L30: =IF(L$5=0,0,IF(L$4=0,0,IF(L$6=0,0,1))) -> 0 | M30: =IF(M$5=0,0,IF(M$4=0,0,IF(M$6=0,0,1))) -> 0 | N30: =IF(N$5=0,0,IF(N$4=0,0,IF(N$6=0,0,1))) -> 0 | O30: =IF(O$5=0,0,IF(O$4=0,0,IF(O$6=0,0,1))) -> 0 | P30: =IF(P$5=0,0,IF(P$4=0,0,IF(P$6=0,0,1))) -> 0 | Q30: =IF(Q$5=0,0,IF(Q$4=0,0,IF(Q$6=0,0,1))) -> 0 | R30: =IF(R$5=0,0,IF(R$4=0,0,IF(R$6=0,0,1))) -> 0 | ... AW30: =IF(AW$5=0,0,IF(AW$4=0,0,IF(AW$6=0,0,1))) -> 0
A31: C15.2.1 | B31: Move rotary drilling plant and equipment to the site of each exploratory drillhole, set up, dismantle on completion and reinstate (rotary only). | C31: nr | D31: =H31 -> 0 | F31: =IF(ISNUMBER(SEARCH("incl",$D31)),"-",IF(ISNUMBER(SEARCH("not r",$D31)),"-",IF(ISNUMBER(SEARCH("refer",$D31)),"-",IF(C31="sum","",$D31*$E31)))) -> 0 | H31: =SUM(K31:AU31) -> 0 | K31: =IF(K$5=0,0,IF(K$4=0,IF(K$6=0,1,0),0)) -> 0 | L31: =IF(L$5=0,0,IF(L$4=0,IF(L$6=0,1,0),0)) -> 0 | M31: =IF(M$5=0,0,IF(M$4=0,IF(M$6=0,1,0),0)) -> 0 | N31: =IF(N$5=0,0,IF(N$4=0,IF(N$6=0,1,0),0)) -> 0 | O31: =IF(O$5=0,0,IF(O$4=0,IF(O$6=0,1,0),0)) -> 0 | P31: =IF(P$5=0,0,IF(P$4=0,IF(P$6=0,1,0),0)) -> 0 | Q31: =IF(Q$5=0,0,IF(Q$4=0,IF(Q$6=0,1,0),0)) -> 0 | R31: =IF(R$5=0,0,IF(R$4=0,IF(R$6=0,1,0),0)) -> 0 | ... AW31: =IF(AW$5=0,0,IF(AW$4=0,IF(AW$6=0,1,0),0)) -> 0
A32: C15.2.2 | B32: Move rotary drilling plant and equipment to the site of each exploratory drillhole, over safety barrier or other fence or wall, set up, dismantle on completion and reinstate (rotary only). | C32: nr | D32: =H32 -> 0 | F32: =IF(ISNUMBER(SEARCH("incl",$D32)),"-",IF(ISNUMBER(SEARCH("not r",$D32)),"-",IF(ISNUMBER(SEARCH("refer",$D32)),"-",IF(C32="sum","",$D32*$E32)))) -> 0 | H32: =SUM(K32:AU32) -> 0 | K32: =IF(K$5=0,0,IF(K$4=0,IF(K$6=0,0,1),0)) -> 0 | L32: =IF(L$5=0,0,IF(L$4=0,IF(L$6=0,0,1),0)) -> 0 | M32: =IF(M$5=0,0,IF(M$4=0,IF(M$6=0,0,1),0)) -> 0 | N32: =IF(N$5=0,0,IF(N$4=0,IF(N$6=0,0,1),0)) -> 0 | O32: =IF(O$5=0,0,IF(O$4=0,IF(O$6=0,0,1),0)) -> 0 | P32: =IF(P$5=0,0,IF(P$4=0,IF(P$6=0,0,1),0)) -> 0 | Q32: =IF(Q$5=0,0,IF(Q$4=0,IF(Q$6=0,0,1),0)) -> 0 | R32: =IF(R$5=0,0,IF(R$4=0,IF(R$6=0,0,1),0)) -> 0 | ... AW32: =IF(AW$5=0,0,IF(AW$4=0,IF(AW$6=0,0,1),0)) -> 0
A33: C15.3 | B33: Hand digging and CAT scan at rotary drillhole location to confirm absence of utility ducts ( maximum depth of 1.2m or lesser if ground is assessed as potentially unstable) for rotary only borehole | C33: nr | D33: =H33 -> 0 | F33: =IF(ISNUMBER(SEARCH("incl",$D33)),"-",IF(ISNUMBER(SEARCH("not r",$D33)),"-",IF(ISNUMBER(SEARCH("refer",$D33)),"-",IF(C33="sum","",$D33*$E33)))) -> 0 | H33: =SUM(K33:AU33) -> 0 | K33: =K31 -> 0 | L33: =L31 -> 0 | M33: =M31 -> 0 | N33: =N31 -> 0 | O33: =O31 -> 0 | P33: =P31 -> 0 | Q33: =Q31 -> 0 | R33: =R31 -> 0 | ... AW33: =AW31 -> 0
A34: C16 | B34: Extra over Item C15 for setting up on a slope of gradient greater than 20%. | C34: nr | D34: Not Required | E34: N/A | F34: =IF(ISNUMBER(SEARCH("incl",$D34)),"-",IF(ISNUMBER(SEARCH("not r",$D34)),"-",IF(ISNUMBER(SEARCH("refer",$D34)),"-",IF(C34="sum","",$D34*$E34)))) -> - | H34: =SUM(K34:AU34) -> 0
A35: C17 | B35: Extra over Item C15 for setting up drilling plant for inclined drillhole | C35: nr | D35: Not Required | E35: N/A | F35: =IF(ISNUMBER(SEARCH("incl",$D35)),"-",IF(ISNUMBER(SEARCH("not r",$D35)),"-",IF(ISNUMBER(SEARCH("refer",$D35)),"-",IF(C35="sum","",$D35*$E35)))) -> - | H35: =SUM(K35:AU35) -> 0
A36: C18 | B36: Break out obstructions where present when hand digging at exploratory hole location for C15.3. | C36: m3 | D36: 1 | F36: =IF(ISNUMBER(SEARCH("incl",$D36)),"-",IF(ISNUMBER(SEARCH("not r",$D36)),"-",IF(ISNUMBER(SEARCH("refer",$D36)),"-",IF(C36="sum","",$D36*$E36)))) -> 0 | I36: 1 | J36: assumed
A37: C19 | B37: Standing time for rotary drilling plant, equipment and crew (PROVISIONAL) | C37: h | D37: =H37 -> 0.5 | F37: =IF(ISNUMBER(SEARCH("incl",$D37)),"-",IF(ISNUMBER(SEARCH("not r",$D37)),"-",IF(ISNUMBER(SEARCH("refer",$D37)),"-",IF(C37="sum","",$D37*$E37)))) -> 0 | H37: =(H$29+H$31)*$I37 -> 0.5 | I37: 0.5 | J37: assume AVG per rot | K37: =MAX(K$29:K$31)*$I37 -> 0.5 | L37: =MAX(L$29:L$31)*$I37 -> 0 | M37: =MAX(M$29:M$31)*$I37 -> 0 | N37: =MAX(N$29:N$31)*$I37 -> 0 | O37: =MAX(O$29:O$31)*$I37 -> 0 | P37: =MAX(P$29:P$31)*$I37 -> 0 | Q37: =MAX(Q$29:Q$31)*$I37 -> 0 | R37: =MAX(R$29:R$31)*$I37 -> 0 | ... AW37: =MAX(AW$29:AW$31)*$I37 -> 0
A38: C20 | B38: Provide aquifer protection measures at a single aquiclude/aquifer boundary in a drillhole | C38: nr | D38: Not Required | E38: N/A | F38: =IF(ISNUMBER(SEARCH("incl",$D38)),"-",IF(ISNUMBER(SEARCH("not r",$D38)),"-",IF(ISNUMBER(SEARCH("refer",$D38)),"-",IF(C38="sum","",$D38*$E38)))) -> - | H38: =SUM(K38:AU38) -> 0
B39: Drilling without cores
A40: C21 | B40: Rotary drill in materials other than hard strata at the specified diameter, from which cores are not required, between existing ground level and 10m depth (PROVISIONAL) | C40: m | D40: =H40 -> 30 | F40: =IF(ISNUMBER(SEARCH("incl",$D40)),"-",IF(ISNUMBER(SEARCH("not r",$D40)),"-",IF(ISNUMBER(SEARCH("refer",$D40)),"-",IF(C40="sum","",$D40*$E40)))) -> 0 | H40: =I40 -> 30 | I40: =SUM(K40:AW40) -> 30 | K40: =K1 -> 0 | L40: =L1 -> 0 | M40: =M1 -> 0 | N40: =N1 -> 0 | O40: =O1 -> 0 | P40: =P1 -> 0 | Q40: =Q1 -> 0 | R40: =R1 -> 0 | ... AD40: =AD1 -> 0 | AE40: 10 | AF40: 10 | AG40: 10 | AH40: =AH1 -> 0 | AI40: =AI1 -> 0 | AJ40: =AJ1 -> 0 | AK40: =AK1 -> 0 | AL40: =AL1 -> 0 | AM40: =AM1 -> 0
...

Sheet Section D
J1: xxx | K1: ='Section B'!K1 -> 0 | L1: ='Section B'!L1 -> 0 | M1: ='Section B'!M1 -> 0 | N1: ='Section B'!N1 -> 0 | O1: ='Section B'!O1 -> 0 | P1: ='Section B'!P1 -> 0 | Q1: ='Section B'!Q1 -> 0 | R1: ='Section B'!R1 -> 0 | ... AW1: ='Section B'!AW1 -> 0
H2: TRIAL PITS | J2: SITE-NEW | K2: ='Log Schedule'!A35 -> TP 01 | L2: ='Log Schedule'!A36 -> TP 02
J3: TP | K3: =IF(K$4>0,CONCATENATE("TP-",K2),IF('Section B'!K$3=0,"TP??","-")) -> TP-TP 01 | L3: =IF(L$4>0,CONCATENATE("TP-",L2),IF('Section B'!L$3=0,"TP??","-")) -> TP-TP 02 | M3: =IF(M$4>0,CONCATENATE("TP-",M2),IF('Section B'!M$3=0,"TP??","-")) -> TP?? | N3: =IF(N$4>0,CONCATENATE("TP-",N2),IF('Section B'!N$3=0,"TP??","-")) -> TP?? | O3: =IF(O$4>0,CONCATENATE("TP-",O2),IF('Section B'!O$3=0,"TP??","-")) -> TP?? | P3: =IF(P$4>0,CONCATENATE("TP-",P2),IF('Section B'!P$3=0,"TP??","-")) -> TP?? | Q3: =IF(Q$4>0,CONCATENATE("TP-",Q2),IF('Section B'!Q$3=0,"TP??","-")) -> TP?? | R3: =IF(R$4>0,CONCATENATE("TP-",R2),IF('Section B'!R$3=0,"TP??","-")) -> TP?? | ... AW3: =IF(AW$4>0,CONCATENATE("TP-",AW2),IF('Section B'!AW$3=0,"TP??","-")) -> TP??
J4: TP Depth | K4: ='Log Schedule'!C35 -> 4.5 | L4: ='Log Schedule'!C36 -> 4.5
H5: CALC | J5: SLOPE
J6: CRASH BARRIER
J7: VERGE/Purple Book/ROL | AT7: 1 | AU7: 1
A8: Number | B8: Item description | C8: Unit | D8: Quantity | E8: Rate | F8: Amount | H8: Totals | J8: CBR | Y8: 0 | AB8: 1 | AC8: 1
E9: € | F9: € | J9: Paved Area | V9: 1 | AT9: 1 | AU9: 1
A10: D | B10: Pitting and trenching
B11: Inspection pits Included for each exploratory hole: refer hand digging and CAT scan items at exploratory hole locations
A12: D1 | B12: Excavate inspection pit by hand to 1.2m depth. | C12: nr | D12: Not required | E12: N/A | F12: =IF(ISNUMBER(SEARCH("incl",$D12)),"-",IF(ISNUMBER(SEARCH("not r",$D12)),"-",IF(ISNUMBER(SEARCH("refer",$D12)),"-",IF(C12="sum","",$D12*$E12)))) -> -
A13: D2 | B13: Extra over Item D1 for breaking out surface obstructions. | C13: m3 | D13: Not required | E13: N/A | F13: =IF(ISNUMBER(SEARCH("incl",$D13)),"-",IF(ISNUMBER(SEARCH("not r",$D13)),"-",IF(ISNUMBER(SEARCH("refer",$D13)),"-",IF(C13="sum","",$D13*$E13)))) -> - | K13: was hrs: change to m3
B14: Trial pits and trenches (non paved areas) | Y14: =IF(Y$3>0,IF(Y$4>0,IF(Y5=0,0,IF(Y$6=0,0,1)),0)) -> 0 | BK14: ST | BL14: plus TP | BM14: minus ST road
A15: D3 | B15: Move equipment to the site of each trial pit or trench dismantle on completion and reinstate. | C15: nr | D15: =H15 -> -1 | F15: =IF(ISNUMBER(SEARCH("incl",$D15)),"-",IF(ISNUMBER(SEARCH("not r",$D15)),"-",IF(ISNUMBER(SEARCH("refer",$D15)),"-",IF(C15="sum","",$D15*$E15)))) -> 0 | H15: =SUM(K15:BF15)-I26 -> -1 | K15: =IF(K$4>0,1,0) -> 1 | L15: =IF(L$4>0,1,0) -> 1 | M15: =IF(M$4>0,1,0) -> 0 | N15: =IF(N$4>0,1,0) -> 0 | O15: =IF(O$4>0,1,0) -> 0 | P15: =IF(P$4>0,1,0) -> 0 | Q15: =IF(Q$4>0,1,0) -> 0 | R15: =IF(R$4>0,1,0) -> 0 | ... BF15: =IF(BF$4>0,1,0) -> 0 | BG15: based on X No ST's in carriageway/footway | BK15: 0 | BL15: 0 | BM15: 0 | BN15: =BK15+BL15-BM15 -> 0
A16: D3.1 | B16: Extra over item D3 for setting to the site of exploratory hole over safety barrier or other fence or wall, set up, dismantle on completion and reinstate. | C16: nr | D16: Not required | E16: N/A | F16: =IF(ISNUMBER(SEARCH("incl",$D16)),"-",IF(ISNUMBER(SEARCH("not r",$D16)),"-",IF(ISNUMBER(SEARCH("refer",$D16)),"-",IF(C16="sum","",$D16*$E16)))) -> - | H16: =SUM(K16:AU16) -> 0 | K16: =IF(K$6>0,1,0) -> 0 | L16: =IF(L$6>0,1,0) -> 0 | M16: =IF(M$6>0,1,0) -> 0 | N16: =IF(N$6>0,1,0) -> 0 | O16: =IF(O$6>0,1,0) -> 0 | P16: =IF(P$6>0,1,0) -> 0 | Q16: =IF(Q$6>0,1,0) -> 0 | R16: =IF(R$6>0,1,0) -> 0 | ... BF16: =IF(BF$6>0,1,0) -> 0
A17: D4 | B17: Extra over Item D3 for setting up on a slope of gradient greater than 20% | C17: nr | D17: Not required | E17: N/A | F17: =IF(ISNUMBER(SEARCH("incl",$D17)),"-",IF(ISNUMBER(SEARCH("not r",$D17)),"-",IF(ISNUMBER(SEARCH("refer",$D17)),"-",IF(C17="sum","",$D17*$E17)))) -> - | H17: =SUM(K17:AU17) -> 0 | K17: =IF(K$5>0,1,0) -> 0 | L17: =IF(L$5>0,1,0) -> 0 | M17: =IF(M$5>0,1,0) -> 0 | N17: =IF(N$5>0,1,0) -> 0 | O17: =IF(O$5>0,1,0) -> 0 | P17: =IF(P$5>0,1,0) -> 0 | Q17: =IF(Q$5>0,1,0) -> 0 | R17: =IF(R$5>0,1,0) -> 0 | ... BF17: =IF(BF$5>0,1,0) -> 0
A18: D5 | B18: Extra over Item D3 for trial pit or trench between 4.5 and 6m depth | C18: nr | D18: Not required | E18: N/A | F18: =IF(ISNUMBER(SEARCH("incl",$D18)),"-",IF(ISNUMBER(SEARCH("not r",$D18)),"-",IF(ISNUMBER(SEARCH("refer",$D18)),"-",IF(C18="sum","",$D18*$E18)))) -> - | H18: =SUM(K18:AU18) -> 0
A19: D6 | B19: Excavate trial pit between existing ground level and 3m depth | C19: m depth | D19: =H19 -> 6 | F19: =IF(ISNUMBER(SEARCH("incl",$D19)),"-",IF(ISNUMBER(SEARCH("not r",$D19)),"-",IF(ISNUMBER(SEARCH("refer",$D19)),"-",IF(C19="sum","",$D19*$E19)))) -> 0 | H19: =SUM(K19:BF19) -> 6 | K19: =IF(K$4>3,3,K$4) -> 3 | L19: =IF(L$4>3,3,L$4) -> 3 | M19: =IF(M$4>3,3,M$4) -> 0 | N19: =IF(N$4>3,3,N$4) -> 0 | O19: =IF(O$4>3,3,O$4) -> 0 | P19: =IF(P$4>3,3,P$4) -> 0 | Q19: =IF(Q$4>3,3,Q$4) -> 0 | R19: =IF(R$4>3,3,R$4) -> 0 | ... BF19: =IF(BF$4>3,3,BF$4) -> 0
A20: D7 | B20: As Item D6 but between 3.0 and 4.5m depth | C20: m | D20: =H20 -> 3 | F20: =IF(ISNUMBER(SEARCH("incl",$D20)),"-",IF(ISNUMBER(SEARCH("not r",$D20)),"-",IF(ISNUMBER(SEARCH("refer",$D20)),"-",IF(C20="sum","",$D20*$E20)))) -> 0 | H20: =SUM(K20:BF20) -> 3 | K20: =IF(K$4>3,IF(K$4>4.5,1.5,K$4-3),0) -> 1.5 | L20: =IF(L$4>3,IF(L$4>4.5,1.5,L$4-3),0) -> 1.5 | M20: =IF(M$4>3,IF(M$4>4.5,1.5,M$4-3),0) -> 0 | N20: =IF(N$4>3,IF(N$4>4.5,1.5,N$4-3),0) -> 0 | O20: =IF(O$4>3,IF(O$4>4.5,1.5,O$4-3),0) -> 0 | P20: =IF(P$4>3,IF(P$4>4.5,1.5,P$4-3),0) -> 0 | Q20: =IF(Q$4>3,IF(Q$4>4.5,1.5,Q$4-3),0) -> 0 | R20: =IF(R$4>3,IF(R$4>4.5,1.5,R$4-3),0) -> 0 | ... BF20: =IF(BF$4>3,IF(BF$4>4.5,1.5,BF$4-3),0) -> 0
A21: D8 | B21: As Item D6 but between 4.5 and 6m depth | C21: m | D21: Not required | E21: N/A | F21: =IF(ISNUMBER(SEARCH("incl",$D21)),"-",IF(ISNUMBER(SEARCH("not r",$D21)),"-",IF(ISNUMBER(SEARCH("refer",$D21)),"-",IF(C21="sum","",$D21*$E21)))) -> - | H21: =SUM(K21:AU21) -> 0 | K21: =IF(K$4>4.5,K$4-4.5,0) -> 0 | L21: =IF(L$4>4.5,L$4-4.5,0) -> 0 | M21: =IF(M$4>4.5,M$4-4.5,0) -> 0 | N21: =IF(N$4>4.5,N$4-4.5,0) -> 0 | O21: =IF(O$4>4.5,O$4-4.5,0) -> 0 | P21: =IF(P$4>4.5,P$4-4.5,0) -> 0 | Q21: =IF(Q$4>4.5,Q$4-4.5,0) -> 0 | R21: =IF(R$4>4.5,R$4-4.5,0) -> 0 | ... BF21: =IF(BF$4>4.5,BF$4-4.5,0) -> 0
A22: D9 | B22: Excavate trial trench between existing ground level and 3.0m depth | C22: m3 | D22: Not required | E22: N/A | F22: =IF(ISNUMBER(SEARCH("incl",$D22)),"-",IF(ISNUMBER(SEARCH("not r",$D22)),"-",IF(ISNUMBER(SEARCH("refer",$D22)),"-",IF(C22="sum","",$D22*$E22)))) -> - | BG22: was 1200 | BH22: take as = (No of trenches x 2.5m assumed depth x 5m average length) | BO22: spec say 1.5m depth
A23: D10 | B23: As Item D9 between 3.0 and 4.5m in depth | C23: m3 | D23: Not required | E23: N/A | F23: =IF(ISNUMBER(SEARCH("incl",$D23)),"-",IF(ISNUMBER(SEARCH("not r",$D23)),"-",IF(ISNUMBER(SEARCH("refer",$D23)),"-",IF(C23="sum","",$D23*$E23)))) -> - | BI23: 31 | BJ23: 1.5 | BK23: 5 | BL23: 0.45 | BN23: =BI23*BJ23*BK23*BL23 -> 104.625 | BO23: 110
A24: D11 | B24: As Item D9 between 4.5 and 6m depth | C24: m3 | D24: Not required | E24: N/A | F24: =IF(ISNUMBER(SEARCH("incl",$D24)),"-",IF(ISNUMBER(SEARCH("not r",$D24)),"-",IF(ISNUMBER(SEARCH("refer",$D24)),"-",IF(C24="sum","",$D24*$E24)))) -> - | BI24: No | BJ24: D | BK24: L | BL24: W | BN24: Vol
B25: Trial pits and trenches (paved areas) | I25: TPs in Paved Areas
A26: D12 | B26: Set up trial pit in road area to include erection of traffic management systems (works supervised by Engineer/ Geologist with valid CSCS Card for signing, lighting and guarding at roadworks) | C26: nr | D26: =H26 -> 3 | F26: =IF(ISNUMBER(SEARCH("incl",$D26)),"-",IF(ISNUMBER(SEARCH("not r",$D26)),"-",IF(ISNUMBER(SEARCH("refer",$D26)),"-",IF(C26="sum","",$D26*$E26)))) -> 0 | H26: =I26 -> 3 | I26: =SUM(K9:BF9) -> 3
A27: D13 | B27: Set up slit trench in road area to include erection of traffic management systems (works supervised by Engineer/ Geologist with valid CSCS Card for signing, lighting and guarding at roadworks) | C27: nr | D27: =H27 -> 11 | F27: =IF(ISNUMBER(SEARCH("incl",$D27)),"-",IF(ISNUMBER(SEARCH("not r",$D27)),"-",IF(ISNUMBER(SEARCH("refer",$D27)),"-",IF(C27="sum","",$D27*$E27)))) -> 0 | H27: 11
A28: D14 | B28: Saw cut paved areas in advance of the works | C28: ln m | D28: =ROUNDUP(H28,0) -> 84 | F28: =IF(ISNUMBER(SEARCH("incl",$D28)),"-",IF(ISNUMBER(SEARCH("not r",$D28)),"-",IF(ISNUMBER(SEARCH("refer",$D28)),"-",IF(C28="sum","",$D28*$E28)))) -> 0 | H28: =SUM(K28:BF28)+(M33*J33) -> 84 | K28: =IF(K$9=1,2+1+2+1,0) -> 0 | L28: =IF(L$9=1,2+1+2+1,0) -> 0 | M28: =IF(M$9=1,2+1+2+1,0) -> 0 | N28: =IF(N$9=1,2+1+2+1,0) -> 0 | O28: =IF(O$9=1,2+1+2+1,0) -> 0 | P28: =IF(P$9=1,2+1+2+1,0) -> 0 | Q28: =IF(Q$9=1,2+1+2+1,0) -> 0 | R28: =IF(R$9=1,2+1+2+1,0) -> 0 | ... BF28: =IF(BF$9=1,2+1+2+1,0) -> 0 | BH28: take as = [ No of trenches x (2No sides x 3m) + (2No sides x 1m) ]
A29: D15 | B29: Breaking out hard material or surface obstructions | C29: m3 | D29: =ROUNDUP(H29,0) -> 4 | F29: =IF(ISNUMBER(SEARCH("incl",$D29)),"-",IF(ISNUMBER(SEARCH("not r",$D29)),"-",IF(ISNUMBER(SEARCH("refer",$D29)),"-",IF(C29="sum","",$D29*$E29)))) -> 0 | H29: =SUM(K29:BF29) -> 3.6 | J29: Nominal | K29: =K$28*0.2 -> 0 | L29: =L$28*0.2 -> 0 | M29: =M$28*0.2 -> 0 | N29: =N$28*0.2 -> 0 | O29: =O$28*0.2 -> 0 | P29: =P$28*0.2 -> 0 | Q29: =Q$28*0.2 -> 0 | R29: =R$28*0.2 -> 0 | ... BF29: =BF$28*0.2 -> 0 | BG29: was5.25 | BH29: take as = (No of trenches x 250mm assumed surface x (3x1)sqm )
A30: D16 | B30: Excavate trial pit in paved areas between ground level and 1.20m depth (works by either hand excavation or hand assisted machine excavation) | C30: m depth | D30: =ROUNDUP(H30,0) -> 0 | F30: =IF(ISNUMBER(SEARCH("incl",$D30)),"-",IF(ISNUMBER(SEARCH("not r",$D30)),"-",IF(ISNUMBER(SEARCH("refer",$D30)),"-",IF(C30="sum","",$D30*$E30)))) -> 0 | H30: =SUM(K30:BF30) -> 0 | K30: =IF(K$9=1,IF(K$4>1.2,1.2,K$4),0) -> 0 | L30: =IF(L$9=1,IF(L$4>1.2,1.2,L$4),0) -> 0 | M30: =IF(M$9=1,IF(M$4>1.2,1.2,M$4),0) -> 0 | N30: =IF(N$9=1,IF(N$4>1.2,1.2,N$4),0) -> 0 | O30: =IF(O$9=1,IF(O$4>1.2,1.2,O$4),0) -> 0 | P30: =IF(P$9=1,IF(P$4>1.2,1.2,P$4),0) -> 0 | Q30: =IF(Q$9=1,IF(Q$4>1.2,1.2,Q$4),0) -> 0 | R30: =IF(R$9=1,IF(R$4>1.2,1.2,R$4),0) -> 0 | ... BF30: =IF(BF$9=1,IF(BF$4>1.2,1.2,BF$4),0) -> 0 | BI30: 0 | BJ30: 0.25 | BK30: 5 | BL30: 0.45 | BN30: =BI30*BJ30*BK30*BL30 -> 0
A31: D17 | B31: As D16 but depth in range 1.2m to 3.0m | C31: ln m | D31: =ROUNDUP(H31,0) -> 0 | F31: =IF(ISNUMBER(SEARCH("incl",$D31)),"-",IF(ISNUMBER(SEARCH("not r",$D31)),"-",IF(ISNUMBER(SEARCH("refer",$D31)),"-",IF(C31="sum","",$D31*$E31)))) -> 0 | H31: =SUM(K31:BF31) -> 0 | K31: =IF(K$9=1,IF(K$4>1.2,IF(K$4>3,1.8,K$4-1.2),0),0) -> 0 | L31: =IF(L$9=1,IF(L$4>1.2,IF(L$4>3,1.8,L$4-1.2),0),0) -> 0 | M31: =IF(M$9=1,IF(M$4>1.2,IF(M$4>3,1.8,M$4-1.2),0),0) -> 0 | N31: =IF(N$9=1,IF(N$4>1.2,IF(N$4>3,1.8,N$4-1.2),0),0) -> 0 | O31: =IF(O$9=1,IF(O$4>1.2,IF(O$4>3,1.8,O$4-1.2),0),0) -> 0 | P31: =IF(P$9=1,IF(P$4>1.2,IF(P$4>3,1.8,P$4-1.2),0),0) -> 0 | Q31: =IF(Q$9=1,IF(Q$4>1.2,IF(Q$4>3,1.8,Q$4-1.2),0),0) -> 0 | R31: =IF(R$9=1,IF(R$4>1.2,IF(R$4>3,1.8,R$4-1.2),0),0) -> 0 | ... BF31: =IF(BF$9=1,IF(BF$4>1.2,IF(BF$4>3,1.8,BF$4-1.2),0),0) -> 0 | BG31: 1.2m-0.25=0.95m | BI31: No of ST | BJ31: D | BK31: L | BL31: W | BN31: Vol
A32: D18 | B32: Excavate slit trench in paved areas between ground level and 1.2m depth (works by either hand excavation or hand assisted machine excavation) | C32: m³ | D32: =H32 -> 79.2 | F32: =IF(ISNUMBER(SEARCH("incl",$D32)),"-",IF(ISNUMBER(SEARCH("not r",$D32)),"-",IF(ISNUMBER(SEARCH("refer",$D32)),"-",IF(C32="sum","",$D32*$E32)))) -> 0 | H32: =J33*K33 -> 79.2 | J32: No. Slit Trenches | K32: Pit Volume | M32: Slit Trench Area | BI32: 0 | BJ32: 0.95 | BK32: 5 | BL32: 0.45 | BN32: =BI32*BJ32*BK32*BL32 -> 0
A33: D19 | B33: Excavate slit trench in paved areas between 1.2m to 3.0m depth (works by either hand excavation or hand assisted machine excavation) | C33: m³ | D33: Not required | F33: =IF(ISNUMBER(SEARCH("incl",$D33)),"-",IF(ISNUMBER(SEARCH("not r",$D33)),"-",IF(ISNUMBER(SEARCH("refer",$D33)),"-",IF(C33="sum","",$D33*$E33)))) -> - | J33: =H27 -> 11 | K33: =(2+1+2+1)*1.2 -> 7.2 | M33: =(2+1+2+1) -> 6 | BH33: assume only 25% of ST's to be excavated to this depth in carriageway/footway
A34: D20 | B34: Standing time for excavation plant, equipment and crew for machine dug trial pit or trench | C34: h | D34: =H34 -> 9 | F34: =IF(ISNUMBER(SEARCH("incl",$D34)),"-",IF(ISNUMBER(SEARCH("not r",$D34)),"-",IF(ISNUMBER(SEARCH("refer",$D34)),"-",IF(C34="sum","",$D34*$E34)))) -> 0 | H34: 9 | BI34: 0 | BJ34: 0.3 | BK34: 5 | BL34: 0.45 | BN34: =BI34*BJ34*BK34*BL34 -> 0
B35: Observation pits and trenches | BI35: No of ST | BJ35: D | BK35: L | BL35: W | BN35: Vol
A36: D21 | B36: Move equipment to the site of each observation pit or trench of not greater than 4.5m depth | C36: nr | D36: Not required | E36: N/A | F36: =IF(ISNUMBER(SEARCH("incl",$D36)),"-",IF(ISNUMBER(SEARCH("not r",$D36)),"-",IF(ISNUMBER(SEARCH("refer",$D36)),"-",IF(C36="sum","",$D36*$E36)))) -> -
A37: D22 | B37: Extra over Item D21 for setting up on a slope of gradient greater than 20% | C37: nr | D37: Not required | E37: N/A | F37: =IF(ISNUMBER(SEARCH("incl",$D37)),"-",IF(ISNUMBER(SEARCH("not r",$D37)),"-",IF(ISNUMBER(SEARCH("refer",$D37)),"-",IF(C37="sum","",$D37*$E37)))) -> -
A38: D23 | B38: Extra over Item D21 for trial pit or trench between 4.5 and 6m depth | C38: nr | D38: Not required | E38: N/A | F38: =IF(ISNUMBER(SEARCH("incl",$D38)),"-",IF(ISNUMBER(SEARCH("not r",$D38)),"-",IF(ISNUMBER(SEARCH("refer",$D38)),"-",IF(C38="sum","",$D38*$E38)))) -> -
A39: D24 | B39: Excavate observation pit between existing ground level and 3.0m depth | C39: m | D39: Not required | E39: N/A | F39: =IF(ISNUMBER(SEARCH("incl",$D39)),"-",IF(ISNUMBER(SEARCH("not r",$D39)),"-",IF(ISNUMBER(SEARCH("refer",$D39)),"-",IF(C39="sum","",$D39*$E39)))) -> -
A40: D25 | B40: As Item D24 but between 3.0 and 4.5m depth | C40: m | D40: Not required | E40: N/A | F40: =IF(ISNUMBER(SEARCH("incl",$D40)),"-",IF(ISNUMBER(SEARCH("not r",$D40)),"-",IF(ISNUMBER(SEARCH("refer",$D40)),"-",IF(C40="sum","",$D40*$E40)))) -> -
...

Sheet Section E
A7: Number | B7: Item description | C7: Unit | D7: Quantity | E7: Rate | F7: Amount
E8: € | F8: €
A9: E | B9: Sampling and monitoring during intrusive investigation
B10: Samples for geotechnical purposes
A11: E1 | B11: Jar sample | C11: nr | D11: Not Required | F11: =IF(ISNUMBER(SEARCH("incl",$D11)),"-",IF(ISNUMBER(SEARCH("not r",$D11)),"-",IF(ISNUMBER(SEARCH("refer",$D11)),"-",IF(C11="sum","",$D11*$E11)))) -> - | K11: CP | L11: TP | M11: ST
A12: E2 | B12: Tub sample | C12: nr | D12: =H12 -> 17 | F12: =IF(ISNUMBER(SEARCH("incl",$D12)),"-",IF(ISNUMBER(SEARCH("not r",$D12)),"-",IF(ISNUMBER(SEARCH("refer",$D12)),"-",IF(C12="sum","",$D12*$E12)))) -> 0 | H12: =I12*SUM(K12:M12) -> 17 | I12: 1 | J12: per m | K12: ='Section B'!H20+'Section B'!H21+'Section B'!H22+'Section B'!H23+'Section B'!H24 -> 8 | L12: ='Section D'!H19+'Section D'!H20+'Section D'!H21+'Section D'!H30+'Section D'!H31+'Section D'!H39+'Section D'!H40+'Section D'!H41+'Section D'!H42 -> 9 | M12: 0
A13: E3 | B13: Bulk sample | C13: nr | D13: =H13 -> 17 | F13: =IF(ISNUMBER(SEARCH("incl",$D13)),"-",IF(ISNUMBER(SEARCH("not r",$D13)),"-",IF(ISNUMBER(SEARCH("refer",$D13)),"-",IF(C13="sum","",$D13*$E13)))) -> 0 | H13: =I13*SUM(K13:M13) -> 17 | I13: 1 | J13: per m | K13: ='Section B'!H20+'Section B'!H21+'Section B'!H22+'Section B'!H23+'Section B'!H24 -> 8 | L13: ='Section D'!H19+'Section D'!H20+'Section D'!H21+'Section D'!H30+'Section D'!H31+'Section D'!H39+'Section D'!H40+'Section D'!H41+'Section D'!H42 -> 9 | M13: 0
A14: E4 | B14: Large bulk disturbed sample | C14: nr | D14: 10 | F14: =IF(ISNUMBER(SEARCH("incl",$D14)),"-",IF(ISNUMBER(SEARCH("not r",$D14)),"-",IF(ISNUMBER(SEARCH("refer",$D14)),"-",IF(C14="sum","",$D14*$E14)))) -> 0 | H14: 10 | I14: nominal for E/W
A15: E5 | B15: Open tube- thick walled sample (0 to 10m depth) | C15: nr | D15: =H15 -> 1 | F15: =IF(ISNUMBER(SEARCH("incl",$D15)),"-",IF(ISNUMBER(SEARCH("not r",$D15)),"-",IF(ISNUMBER(SEARCH("refer",$D15)),"-",IF(C15="sum","",$D15*$E15)))) -> 0 | H15: =ROUNDUP(I15*K15,0) -> 1 | I15: 0.5 | J15: per BH avg | K15: ='Section B'!$H$17+'Section B'!$H$18 -> 1
A16: E6 | B16: Open tube- thin walled sample (0 to 10m depth) | C16: nr | D16: =H16 -> 1 | F16: =IF(ISNUMBER(SEARCH("incl",$D16)),"-",IF(ISNUMBER(SEARCH("not r",$D16)),"-",IF(ISNUMBER(SEARCH("refer",$D16)),"-",IF(C16="sum","",$D16*$E16)))) -> 0 | H16: =ROUNDUP(I16*K16,0) -> 1 | I16: 0.25 | J16: per BH avg | K16: ='Section B'!$H$17+'Section B'!$H$18 -> 1 | O16: 10 | P16: =O16/O$19 -> 0.55555556
A17: E7 | B17: Piston sample (0 to 10m depth) | C17: nr | D17: Not required | F17: =IF(ISNUMBER(SEARCH("incl",$D17)),"-",IF(ISNUMBER(SEARCH("not r",$D17)),"-",IF(ISNUMBER(SEARCH("refer",$D17)),"-",IF(C17="sum","",$D17*$E17)))) -> - | O17: 1 | P17: =O17/O$19 -> 0.055555556
A18: E8.1 | B18: Extra over rate for item E5 in depth range 10m to 20m | C18: sum | D18: Not required | F18: =IF(ISNUMBER(SEARCH("incl",$D18)),"-",IF(ISNUMBER(SEARCH("not r",$D18)),"-",IF(ISNUMBER(SEARCH("refer",$D18)),"-",IF(C18="sum","",$D18*$E18)))) -> - | O18: 8 | P18: =O18/O$19 -> 0.44444444
A19: E8.2 | B19: Extra over rate for item E6 in depth range 10m to 20m | C19: sum | D19: Not required | F19: =IF(ISNUMBER(SEARCH("incl",$D19)),"-",IF(ISNUMBER(SEARCH("not r",$D19)),"-",IF(ISNUMBER(SEARCH("refer",$D19)),"-",IF(C19="sum","",$D19*$E19)))) -> - | O19: 18 | P19: =O19/O$19 -> 1
A20: E8.3 | B20: Extra over rate for item E7 in depth range 10m to 20m | C20: sum | D20: Not required | F20: =IF(ISNUMBER(SEARCH("incl",$D20)),"-",IF(ISNUMBER(SEARCH("not r",$D20)),"-",IF(ISNUMBER(SEARCH("refer",$D20)),"-",IF(C20="sum","",$D20*$E20)))) -> - | K20: CP | L20: TP | M20: ST
A21: E9 | B21: Groundwater sample | C21: nr | D21: =ROUNDUP(H21,0) -> 2 | F21: =IF(ISNUMBER(SEARCH("incl",$D21)),"-",IF(ISNUMBER(SEARCH("not r",$D21)),"-",IF(ISNUMBER(SEARCH("refer",$D21)),"-",IF(C21="sum","",$D21*$E21)))) -> 0 | H21: =I21*SUM(K21:M21) -> 1.5 | I21: 0.5 | J21: of holes | K21: ='Section B'!$H$11+'Section B'!$H$13 -> 1 | L21: ='Section D'!$H$15+'Section D'!$H$26+'Section D'!$H$36 -> 2
A22: E10 | B22: Ground Gas sample | C22: nr | D22: Not Required | F22: =IF(ISNUMBER(SEARCH("incl",$D22)),"-",IF(ISNUMBER(SEARCH("not r",$D22)),"-",IF(ISNUMBER(SEARCH("refer",$D22)),"-",IF(C22="sum","",$D22*$E22)))) -> -
A23: E11 | B23: Cut, prepare and protect core sub-sample | C23: nr | D23: Not Required | F23: =IF(ISNUMBER(SEARCH("incl",$D23)),"-",IF(ISNUMBER(SEARCH("not r",$D23)),"-",IF(ISNUMBER(SEARCH("refer",$D23)),"-",IF(C23="sum","",$D23*$E23)))) -> -
