Workbook

Sheet Section A
A2: Number | B2: Item description | C2: Unit | D2: Quantity | E2: Rate | F2: Amount
E3: € | F3: €
A4: A | B4: General items, provisional services and additional items
A5: A1 | B5: Offices and stores for the Contractor | C5: sum | D5: 1 | E5: 25000 | F5: =IFERROR(IF(ISNUMBER(D5),D5*E5,"-"),"") -> 25000
A6: A2 | B6: Establish on site all plant, equipment and services for a Green Category site | C6: Refer to Items A2.1-2.9 | D6: Refer to Items A2.1-2.9 | E6: =IF(ISNUMBER(D6),"","N/A") -> N/A
A7: A2.1 | B7: Establish on site cable percussion ('shell & auger') boring plant and equipment for a Green Category site (Stage 1 - NON TRACK) | C7: sum | D7: 1 | E7: 5000 | F7: =IFERROR(IF(ISNUMBER(D7),D7*E7,"-"),"") -> 5000
A8: A2.1A | B8: Establish on site cable percussion ('shell & auger') boring plant and equipment for a Green Category site (Stage 2 - NON TRACK) | C8: sum | D8: 1 | E8: 5000 | F8: =IFERROR(IF(ISNUMBER(D8),D8*E8,"-"),"") -> 5000
A9: A2.1.1 | B9: Establish on site cable percussion ('shell & auger') boring plant and equipment for a Green Category site (Stage 1 - NIGHT TIME ON TRACK) | C9: sum | D9: 1 | E9: 25000 | F9: =IFERROR(IF(ISNUMBER(D9),D9*E9,"-"),"") -> 25000
A10: A2.2 | B10: Establish on site rotary drilling plant and equipment for a Green Category site (Stage 1 - NON TRACK) | C10: sum | D10: 1 | E10: 5000 | F10: =IFERROR(IF(ISNUMBER(D10),D10*E10,"-"),"") -> 5000
A11: A2.2A | B11: Establish on site rotary drilling plant and equipment for a Green Category site (Stage 2 - NON TRACK) | C11: sum | D11: 1 | E11: 5000 | F11: =IFERROR(IF(ISNUMBER(D11),D11*E11,"-"),"") -> 5000
A12: A2.2.1 | B12: Establish on site rotary drilling plant and equipment for a Green Category site (Stage 1 - NIGHT TIME ON TRACK) | C12: sum | D12: 1 | E12: 25000 | F12: =IFERROR(IF(ISNUMBER(D12),D12*E12,"-"),"") -> 25000
A13: A2.3 | B13: Establish on site Geobor S rotary drilling plant and equipment for a Green Category site | C13: sum | D13: 1 | E13: 2500 | F13: =IFERROR(IF(ISNUMBER(D13),D13*E13,"-"),"") -> 2500
A14: A2.3.1 | B14: Establish on site Geobor S rotary drilling plant and equipment for a Green Category site (Stage 1 - NIGHT TIME ON TRACK) | C14: sum | D14: 1 | E14: 2500 | F14: =IFERROR(IF(ISNUMBER(D14),D14*E14,"-"),"") -> 2500
A15: A2.4 | B15: Establish on site trial pitting and trenching plant and equipment for a Green Category site (Stage 1 - NIGHT TIME ON TRACK) | C15: sum | D15: 1 | E15: 25000 | F15: =IFERROR(IF(ISNUMBER(D15),D15*E15,"-"),"") -> 25000
A16: A2.5 | B16: Establish on site in situ test and sampling equipment for a Green Category site (Stages 1 to 4 - NON TRACK) | C16: sum | D16: 1 | E16: 7500 | F16: =IFERROR(IF(ISNUMBER(D16),D16*E16,"-"),"") -> 7500
A17: A2.5A | B17: Establish on site in situ test and sampling equipment for a Green Category site (Stages 1 to 4 - NIGHT TIME ON TRACK) | C17: sum | D17: 1 | E17: 15000 | F17: =IFERROR(IF(ISNUMBER(D17),D17*E17,"-"),"") -> 15000
A18: A2.6 | B18: Establish on site cone penetration testing (CPT) plant and equipment for a Green Category site | C18: sum | D18: Not Required | E18: =IF(ISNUMBER(D18),"","N/A") -> N/A
A19: A2.7 | B19: Establish on site dynamic sampling and probing plant and equipment for a Green Category site (Stage 1 - NON TRACK) | C19: sum | D19: 1 | E19: 2500 | F19: =IFERROR(IF(ISNUMBER(D19),D19*E19,"-"),"") -> 2500
A20: A2.7A | B20: Establish on site dynamic sampling and probing plant and equipment for a Green Category site (Stage 3 - NIGHT TIME ON TRACK) | C20: sum | D20: 1 | E20: 15000 | F20: =IFERROR(IF(ISNUMBER(D20),D20*E20,"-"),"") -> 15000
A21: A2.8 | B21: Establish on site geophysical survey equipment for a Green Category site (Stage 1) | C21: sum | D21: 1 | E21: 1500 | F21: =IFERROR(IF(ISNUMBER(D21),D21*E21,"-"),"") -> 1500
A22: A2.9 | B22: Establish on site instrumentation equipment as required for a Green Category site (Stage 1) | C22: sum | D22: 1 | E22: 2000 | F22: =IFERROR(IF(ISNUMBER(D22),D22*E22,"-"),"") -> 2000
A23: A2.9.1 | B23: Extra over Item A2.1 - A2.9 for working within Irish Rail property | C23: sum | D23: 1 | E23: 25000 | F23: =IFERROR(IF(ISNUMBER(D23),D23*E23,"-"),"") -> 25000
A24: A3.1 | B24: Extra over item A2.1 - A2.9 for a yellow category site | C24: sum | D24: 1 | E24: 5000 | F24: =IFERROR(IF(ISNUMBER(D24),D24*E24,"-"),"") -> 5000
A25: A3.2 | B25: As Item A3.1 but for a Red Category site | C25: provisional sum | E25: =IF(ISNUMBER(D25),"","N/A") -> N/A | F25: 1000
A26: A4.1 | B26: Maintain on site all site safety equipment for a Yellow Category site | C26: sum | D26: 1 | E26: 2500 | F26: =IFERROR(IF(ISNUMBER(D26),D26*E26,"-"),"") -> 2500
A27: A4.2 | B27: Maintain on site all site safety equipment for a Red Category site | C27: provisional sum | E27: =IF(ISNUMBER(D27),"","N/A") -> N/A | F27: 1000
A28: A5.1 | B28: Decontamination of equipment during and at end of intrusive investigation for a Yellow Category site | C28: sum | D28: 1 | E28: 2500 | F28: =IFERROR(IF(ISNUMBER(D28),D28*E28,"-"),"") -> 2500
A29: A5.2 | B29: Decontamination of equipment during and at end of intrusive investigation for a Red Category site | C29: provisional sum | D29: Not Required | E29: =IF(ISNUMBER(D29),"","N/A") -> N/A
A30: A6 | B30: Appropriate storage, transport and off-site disposal of excess contaminated arising’s from borehole, trial pit or slit trench to EPA regulated landfill site (includes any PPE equipment but excludes laboratory testing on suspected contaminated materials). Note item to be remeasured with delivery dockets and records maintained by the Contractor | C30: provisional sum | D30: 1 | E30: =IF(ISNUMBER(D30),"","N/A") | F30: 1000
A31: A6.1 | B31: Contractor's uplift on Item A6 | C31: % | E31: 1000 | F31: 100
A32: A7 | B32: Provide professional attendance to meet the contract requirements | C32: sum | D32: 1 | E32: 5000 | F32: =IFERROR(IF(ISNUMBER(D32),D32*E32,"-"),"") -> 5000
A33: A7.1 | B33: Provide Technician | C33: per day | D33: Included in A7 | E33: n/a
A34: A7.2 | B34: Provide Engineer / Geologist (as per item 2.3 of Specification) | C34: per day | D34: Included in A7 | E34: =IF(ISNUMBER(D34),"","N/A") -> N/A
A35: A7.3 | B35: Provide Chartered Engineer / Professional Geologist (as item 2.3 of Specification) | C35: per day | D35: Included in A7 | E35: =IF(ISNUMBER(D35),"","N/A") -> N/A
A36: A7.4 | B36: Provide Chartered Engineer / Professional Geologist (+10 years experience post charter) | C36: per day | D36: Included in A7 | E36: =IF(ISNUMBER(D36),"","N/A") -> N/A
A37: A7.5 | B37: Provide Chartered Engineer / Professional Geologist (+20 years experience post charter) | C37: per day | D37: Included in A7 | E37: =IF(ISNUMBER(D37),"","N/A") -> N/A
A38: A8 | B38: Set out the location at each exploratory hole or point | C38: nr | D38: 601 | E38: 10 | F38: =IFERROR(IF(ISNUMBER(D38),D38*E38,"-"),"") -> 6010
A39: A8.1 | B39: Establish the location and elevation (X, Y, Z) of the ground at each 'as-built' exploratory hole or point (NON TRACK) | C39: nr | D39: 90 | E39: 10 | F39: =IFERROR(IF(ISNUMBER(D39),D39*E39,"-"),"") -> 900
A40: A8.2 | B40: Establish the location and elevation (X, Y, Z) of the ground at each 'as-built' exploratory hole or point (NIGHT TIME ON TRACK) | C40: nr | D40: 511 | E40: 10 | F40: =IFERROR(IF(ISNUMBER(D40),D40*E40,"-"),"") -> 5110
A41: A9 | B41: Preparation of Health and Safety documentation and Safety Risk Assessment for Work on or near the track (IE as PSCS). | C41: sum | D41: 1 | E41: 2500 | F41: =IFERROR(IF(ISNUMBER(D41),D41*E41,"-"),"") -> 2500
...

Sheet Section B
A2: Number | B2: Item description | C2: Unit | D2: Quantity | E2: Rate | F2: Amount
B3: Non-Track Works | E3: € | F3: €
A4: B | B4: Cable Percussion Boring (cable tool or percussive boring using minimum of 200mm diameter casing)
A5: B1 | B5: Move boring plant and equipment to the site of each exploratory hole and set up (cable percussive only) | C5: Refer to items B1.1 and B1.2 | D5: Refer to items B1.1 and B1.2 | E5: =IF(ISNUMBER(D5),"","N/A") -> N/A | F5: =IFERROR(IF(ISNUMBER(D5),D5*E5,"-"),"") -> -
A6: B1.1.1 | B6: Move boring plant and equipment to the site of each exploratory hole, set up, dismantle on completion and reinstate (cable percussive only) | C6: nr | D6: Not Required | E6: =IF(ISNUMBER(D6),"","N/A") -> N/A | F6: =IFERROR(IF(ISNUMBER(D6),D6*E6,"-"),"") -> -
A7: B1.1.2 | B7: Move boring plant and equipment to the site of each exploratory hole over safety barrier or other fence or wall, set up, dismantle on completion and reinstate (cable percussive only) | C7: nr | D7: Not Required | E7: =IF(ISNUMBER(D7),"","N/A") -> N/A | F7: =IFERROR(IF(ISNUMBER(D7),D7*E7,"-"),"") -> - | Z7: Addressed
A8: B1.2.1 | B8: Move boring plant and equipment to the site of each exploratory hole, set up, dismantle on completion and reinstate (where borehole is to be followed on with rotary drilling) | C8: nr | D8: Not Required | E8: =IF(ISNUMBER(D8),"","N/A") -> N/A | F8: =IFERROR(IF(ISNUMBER(D8),D8*E8,"-"),"") -> -
A9: B1.2.1.1 | B9: Move boring plant and equipment to the site of each exploratory hole, set up, dismantle on completion and reinstate (where borehole is to be followed on with rotary drilling) | C9: nr | D9: 47 | E9: 250 | F9: =IFERROR(IF(ISNUMBER(D9),D9*E9,"-"),"") -> 11750
A10: B1.2.1.2 | B10: Extra Over Item B1.2.1.1 Set up borehole in road area to include erection of traffic management systems (works supervised by Engineer/Geologist with valid CSCS Card for Signing, Lighting and Guarding at Roadworks) | C10: nr | D10: 22 | E10: 500 | F10: =IFERROR(IF(ISNUMBER(D10),D10*E10,"-"),"") -> 11000
A11: B1.2.2 | B11: Move boring plant and equipment to the site of each exploratory hole over safety barrier or other fence or wall, set up, dismantle on completion and reinstate (where borehole is to be followed on with rotary drilling) | C11: nr | D11: Not Required | E11: =IF(ISNUMBER(D11),"","N/A") -> N/A | F11: =IFERROR(IF(ISNUMBER(D11),D11*E11,"-"),"") -> -
A12: B1.2.2.1 | B12: Extra Over Items B1.1-B1.2 for moving locations where distance travelled is > 5km | C12: nr | D12: 5 | E12: 500 | F12: =IFERROR(IF(ISNUMBER(D12),D12*E12,"-"),"") -> 2500
A13: B2 | B13: Extra over Item B1 for setting up on a slope of gradient greater than 20% | C13: Refer to items B2.1 and B2.2 | D13: Refer to items B2.1 and B2.2 | E13: =IF(ISNUMBER(D13),"","N/A") -> N/A | F13: =IFERROR(IF(ISNUMBER(D13),D13*E13,"-"),"") -> -
A14: B2.1 | B14: Extra over Item B1.1 for setting up on a slope of gradient greater than 20% | C14: nr | D14: Not Required | E14: =IF(ISNUMBER(D14),"","N/A") -> N/A | F14: =IFERROR(IF(ISNUMBER(D14),D14*E14,"-"),"") -> -
A15: B2.2 | B15: Extra over Item B1.2 for setting up on a slope of gradient greater than 20% | C15: nr | D15: Not Required | E15: =IF(ISNUMBER(D15),"","N/A") -> N/A | F15: =IFERROR(IF(ISNUMBER(D15),D15*E15,"-"),"") -> -
A16: B3 | B16: Hand digging and CAT scan at borehole location to confirm absence of utility ducts (maximum depth of 1.2m or lesser if ground is assessed as potentially unstable) | C16: nr | D16: 25 | E16: 200 | F16: =IFERROR(IF(ISNUMBER(D16),D16*E16,"-"),"") -> 5000
A17: B3.1 | B17: Break out obstructions where present when hand digging at exploratory hole location for Item B3. | C17: m3 | D17: 15 | E17: 50 | F17: =IFERROR(IF(ISNUMBER(D17),D17*E17,"-"),"") -> 750
A18: B3.2 | B18: Hand digging and CAT scan at borehole location to confirm absence of utility ducts (maximum depth of 1.20m or lesser if ground is assessed as potentially unstable) in road areas | C18: nr | D18: 22 | E18: 250 | F18: =IFERROR(IF(ISNUMBER(D18),D18*E18,"-"),"") -> 5500
A19: B4 | B19: Advance borehole between existing ground level and 10 m depth | C19: m | D19: 470 | E19: 30 | F19: =IFERROR(IF(ISNUMBER(D19),D19*E19,"-"),"") -> 14100
A20: B5 | B20: As Item B4 but between 10 m and 20 m depth | C20: m | D20: 165 | E20: 35 | F20: =IFERROR(IF(ISNUMBER(D20),D20*E20,"-"),"") -> 5775
A21: B6 | B21: As Item B4 but between 20 m and 30 m depth | C21: m | D21: 20 | E21: 40 | F21: =IFERROR(IF(ISNUMBER(D21),D21*E21,"-"),"") -> 800
A22: B7 | B22: As Item B4 but between 30 m and 40 m depth | C22: m | D22: Not Required | E22: =IF(ISNUMBER(D22),"","N/A") -> N/A | F22: =IFERROR(IF(ISNUMBER(D22),D22*E22,"-"),"") -> -
A23: B8 | B23: As Item B4 but between 40 m and 50 m depth | C23: m | D23: Not Required | E23: =IF(ISNUMBER(D23),"","N/A") -> N/A | F23: =IFERROR(IF(ISNUMBER(D23),D23*E23,"-"),"") -> -
A24: B9 | B24: Advance borehole through hard stratum or obstruction | C24: h | D24: 108 | E24: 50 | F24: =IFERROR(IF(ISNUMBER(D24),D24*E24,"-"),"") -> 5400
A25: B10 | B25: Provide aquifer protection measures at a single aquiclude/aquifer boundary or cross-contamination control measures at a single soil boundary in a borehole | C25: nr | D25: Included in B1 to B1.2.2 | E25: =IF(ISNUMBER(D25),"","N/A") -> N/A | F25: =IFERROR(IF(ISNUMBER(D25),D25*E25,"-"),"") -> -
A26: B11 | B26: Backfill borehole with cement/bentonite grout or bentonite pellets (where standpipe piezometer is not installed) | C26: m³ | D26: Included in B1 to B1.2.2 | E26: =IF(ISNUMBER(D26),"","N/A") -> N/A | F26: =IFERROR(IF(ISNUMBER(D26),D26*E26,"-"),"") -> -
A27: B12 | B27: Standing time for borehole plant, equipment and crew (excl briefings and setup/dismantling of equipment) | C27: h | D27: 47 | E27: 75 | F27: =IFERROR(IF(ISNUMBER(D27),D27*E27,"-"),"") -> 3525
B28: Dynamic sampling (Window and Windowless Sampling)
A29: B13 | B29: Move dynamic sampling equipment to the site of each exploratory hole and set up | C29: nr | D29: 9 | E29: 250 | F29: =IFERROR(IF(ISNUMBER(D29),D29*E29,"-"),"") -> 2250
A30: B14 | B30: Extra over Item B13 for setting up on a slope of gradient greater than 20% | C30: nr | D30: Not Required | E30: =IF(ISNUMBER(D30),"","N/A") -> N/A | F30: =IFERROR(IF(ISNUMBER(D30),D30*E30,"-"),"") -> -
A31: B15 | B31: Hand digging and CAT scan at dynamic sampling location to confirm absence of utility ducts (maximum depth of 1.2m or lesser if ground is assessed as potentially unstable) | C31: nr | D31: 9 | E31: 250 | F31: =IFERROR(IF(ISNUMBER(D31),D31*E31,"-"),"") -> 2250
A32: B16 | B32: Break out surface obstruction where present | C32: h | D32: 3 | E32: 75 | F32: =IFERROR(IF(ISNUMBER(D32),D32*E32,"-"),"") -> 225
A33: B17 | B33: Advance dynamic sample hole between existing ground level and 5 m depth | C33: m | D33: 45 | E33: 15 | F33: =IFERROR(IF(ISNUMBER(D33),D33*E33,"-"),"") -> 675
A34: B18 | B34: As Item B15 but between 5 and 10 m depth | C34: m | D34: 45 | E34: 20 | F34: =IFERROR(IF(ISNUMBER(D34),D34*E34,"-"),"") -> 900
A35: B19 | B35: Dynamic sampling >10m as instructed by the Investigation Supervisor | C35: m | D35: Not Required | E35: =IF(ISNUMBER(D35),"","N/A") -> N/A | F35: =IFERROR(IF(ISNUMBER(D35),D35*E35,"-"),"") -> -
A36: B20 | B36: Standing time for dynamic sampling equipment and crew (excl briefings and setup/dismantling of equipment) | C36: hr | D36: 3 | E36: 75 | F36: =IFERROR(IF(ISNUMBER(D36),D36*E36,"-"),"") -> 225
A37: B21 | B37: Backfill dynamic sample borehole with cement/bentonite grout or bentonite pellets (where standpipe or piezometer is not installed) | C37: m³ | D37: 1 | E37: 25 | F37: =IFERROR(IF(ISNUMBER(D37),D37*E37,"-"),"") -> 25
B38: Reinstatement of Cable Percussive Borehole and Dynamic Sample Borehole
A39: B22 | B39: Reinstatement of gravel hardstanding | C39: m² | D39: Included in B1.1 & B1.2 | E39: =IF(ISNUMBER(D39),"","N/A") -> N/A | F39: =IFERROR(IF(ISNUMBER(D39),D39*E39,"-"),"") -> -
A40: B23 | B40: Reinstatement of asphalt / bituminous pavement | C40: m² | D40: Included in D53 | E40: =IF(ISNUMBER(D40),"","N/A") -> N/A | F40: =IFERROR(IF(ISNUMBER(D40),D40*E40,"-"),"") -> -
A41: B24 | B41: Reinstatement of grass areas | C41: m² | D41: Included in B1.1 & B1.2 | E41: =IF(ISNUMBER(D41),"","N/A") -> N/A | F41: =IFERROR(IF(ISNUMBER(D41),D41*E41,"-"),"") -> -
...

Sheet Section B.1
A2: Number | B2: Item description | C2: Unit | D2: Quantity | E2: Rate | F2: Amount
B3: On-Track Works | E3: € | F3: €
A4: B | B4: Cable Percussion Boring (cable tool or percussive boring using minimum of 200mm diameter casing)
A5: B1 | B5: Move boring plant and equipment to the site of each exploratory hole and set up (cable percussive only) | C5: Refer to items B1.1 and B1.2 | D5: Refer to items B1.1 and B1.2 | E5: =IF(ISNUMBER(D5),"","N/A") -> N/A | F5: =IFERROR(IF(ISNUMBER(D5),D5*E5,"-"),"") -> -
A6: B1.1.1 | B6: Move boring plant and equipment to the site of each exploratory hole, set up, dismantle on completion and reinstate (cable percussive only) | C6: nr | D6: Not Required | E6: =IF(ISNUMBER(D6),"","N/A") -> N/A | F6: =IFERROR(IF(ISNUMBER(D6),D6*E6,"-"),"") -> -
A7: B1.1.2 | B7: Move boring plant and equipment to the site of each exploratory hole over safety barrier or other fence or wall, set up, dismantle on completion and reinstate (cable percussive only) | C7: nr | D7: Not Required | E7: =IF(ISNUMBER(D7),"","N/A") -> N/A | F7: =IFERROR(IF(ISNUMBER(D7),D7*E7,"-"),"") -> -
A8: B1.2.1.1 | B8: Move boring plant and equipment to the site of each exploratory hole, set up, dismantle on completion and reinstate (where borehole is to be followed on with rotary drilling) | C8: nr | D8: 12 | E8: 1500 | F8: =IFERROR(IF(ISNUMBER(D8),D8*E8,"-"),"") -> 18000
A9: B1.2.1.2 | B9: Extra Over Item B1.1 Set up borehole in trackside area to include compliance with Irish Rail requirements (works supervised by Engineer/Geologist with valid PTS card / works by crew with valid PTS cards) | C9: nr | D9: 12 | E9: 1500 | F9: =IFERROR(IF(ISNUMBER(D9),D9*E9,"-"),"") -> 18000
A10: B1.2.2 | B10: Move boring plant and equipment to the site of each exploratory hole over safety barrier or other fence or wall, set up, dismantle on completion and reinstate (where borehole is to be followed on with rotary drilling) | C10: nr | D10: Not Required | E10: =IF(ISNUMBER(D10),"","N/A") -> N/A | F10: =IFERROR(IF(ISNUMBER(D10),D10*E10,"-"),"") -> -
A11: B2 | B11: Extra over Item B1 for setting up on a slope of gradient greater than 20% | C11: Refer to items B2.1 and B2.2 | D11: Refer to items B2.1 and B2.2 | E11: =IF(ISNUMBER(D11),"","N/A") -> N/A | F11: =IFERROR(IF(ISNUMBER(D11),D11*E11,"-"),"") -> -
A12: B2.1 | B12: Extra over Item B1.1 for setting up on a slope of gradient greater than 20% | C12: nr | D12: Not Required | E12: =IF(ISNUMBER(D12),"","N/A") -> N/A | F12: =IFERROR(IF(ISNUMBER(D12),D12*E12,"-"),"") -> -
A13: B2.2 | B13: Extra over Item B1.2 for setting up on a slope of gradient greater than 20% | C13: nr | D13: Not Required | E13: =IF(ISNUMBER(D13),"","N/A") -> N/A | F13: =IFERROR(IF(ISNUMBER(D13),D13*E13,"-"),"") -> -
A14: B3 | B14: Hand digging and CAT scan at borehole location to confirm absence of utility ducts (maximum depth of 1.2m or lesser if ground is assessed as potentially unstable) | C14: nr | D14: Not Required | E14: =IF(ISNUMBER(D14),"","N/A") -> N/A | F14: =IFERROR(IF(ISNUMBER(D14),D14*E14,"-"),"") -> -
A15: B3.1 | B15: Break out obstructions where present when hand digging at exploratory hole location for Item B3. | C15: m3 | D15: Not Required | E15: =IF(ISNUMBER(D15),"","N/A") -> N/A | F15: =IFERROR(IF(ISNUMBER(D15),D15*E15,"-"),"") -> -
A16: B3.2 | B16: Hand digging and CAT scan at borehole location to confirm absence of utility ducts (maximum depth of 1.20m or lesser if ground is assessed as potentially unstable) in trackside areas | C16: nr | D16: 12 | E16: 500 | F16: =IFERROR(IF(ISNUMBER(D16),D16*E16,"-"),"") -> 6000
A17: B4 | B17: Advance borehole between existing ground level and 10 m depth | C17: m | D17: 120 | E17: 30 | F17: =IFERROR(IF(ISNUMBER(D17),D17*E17,"-"),"") -> 3600
A18: B5 | B18: As Item B4 but between 10 m and 20 m depth | C18: m | D18: 20 | E18: 35 | F18: =IFERROR(IF(ISNUMBER(D18),D18*E18,"-"),"") -> 700
A19: B6 | B19: As Item B4 but between 20 m and 30 m depth | C19: m | D19: Not Required | E19: =IF(ISNUMBER(D19),"","N/A") -> N/A | F19: =IFERROR(IF(ISNUMBER(D19),D19*E19,"-"),"") -> -
A20: B7 | B20: As Item B4 but between 30 m and 40 m depth | C20: m | D20: Not Required | E20: =IF(ISNUMBER(D20),"","N/A") -> N/A | F20: =IFERROR(IF(ISNUMBER(D20),D20*E20,"-"),"") -> -
A21: B8 | B21: As Item B4 but between 40 m and 50 m depth | C21: m | D21: Not Required | E21: =IF(ISNUMBER(D21),"","N/A") -> N/A | F21: =IFERROR(IF(ISNUMBER(D21),D21*E21,"-"),"") -> -
A22: B9 | B22: Advance borehole through hard stratum or obstruction | C22: h | D22: 12 | E22: 50 | F22: =IFERROR(IF(ISNUMBER(D22),D22*E22,"-"),"") -> 600
A23: B10 | B23: Provide aquifer protection measures at a single aquiclude/aquifer boundary or cross-contamination control measures at a single soil boundary in a borehole | C23: nr | D23: Included in B1 to B1.2.2 | E23: =IF(ISNUMBER(D23),"","N/A") -> N/A | F23: =IFERROR(IF(ISNUMBER(D23),D23*E23,"-"),"") -> -
A24: B11 | B24: Backfill borehole with cement/bentonite grout or bentonite pellets (where standpipe piezometer is not installed) | C24: m³ | D24: Included in B1 to B1.2.2 | E24: =IF(ISNUMBER(D24),"","N/A") -> N/A | F24: =IFERROR(IF(ISNUMBER(D24),D24*E24,"-"),"") -> -
A25: B12 | B25: Standing time for borehole plant, equipment and crew (excl briefings and setup/dismantling of equipment) | C25: h | D25: 12 | E25: 150 | F25: =IFERROR(IF(ISNUMBER(D25),D25*E25,"-"),"") -> 1800
B26: Dynamic sampling (Window and Windowless Sampling) Night Works On Track
A27: B13 | B27: Move dynamic sampling equipment to the site of each exploratory hole and set up | C27: nr | D27: 144 | E27: 500 | F27: =IFERROR(IF(ISNUMBER(D27),D27*E27,"-"),"") -> 72000
A28: B14 | B28: Extra over Item B13 for setting up on a slope of gradient greater than 20% | C28: nr | D28: Not Required | F28: =IFERROR(IF(ISNUMBER(D28),D28*E28,"-"),"") -> -
A29: B15 | B29: Hand digging and CAT scan at dynamic sampling location to confirm absence of utility ducts (maximum depth of 1.2m or lesser if ground is assessed as potentially unstable). Include use of 100mm sleeve each location cleared of services for in advance of drilling as per S1.9.3 of Volume A (i). | C29: nr | D29: 144 | E29: 250 | F29: =IFERROR(IF(ISNUMBER(D29),D29*E29,"-"),"") -> 36000
A30: B16 | B30: Break out surface obstruction where present | C30: h | D30: 65 | E30: 50 | F30: =IFERROR(IF(ISNUMBER(D30),D30*E30,"-"),"") -> 3250
A31: B17 | B31: Advance dynamic sample hole between existing ground level and 5 m depth | C31: m | D31: 720 | E31: 20 | F31: =IFERROR(IF(ISNUMBER(D31),D31*E31,"-"),"") -> 14400
A32: B18 | B32: As Item B15 but between 5 and 10 m depth | C32: m | D32: 270 | E32: 25 | F32: =IFERROR(IF(ISNUMBER(D32),D32*E32,"-"),"") -> 6750
A33: B19 | B33: Dynamic sampling >10m as instructed by the Investigation Supervisor | C33: m | D33: Not Required | E33: =IF(ISNUMBER(D33),"","N/A") -> N/A | F33: =IFERROR(IF(ISNUMBER(D33),D33*E33,"-"),"") -> -
A34: B20 | B34: Standing time for dynamic sampling equipment and crew (excl briefings and setup/dismantling of equipment) | C34: hr | D34: 85 | E34: 250 | F34: =IFERROR(IF(ISNUMBER(D34),D34*E34,"-"),"") -> 21250
A35: B21 | B35: Backfill dynamic sample borehole with cement/bentonite grout or bentonite pellets (where standpipe or piezometer is not installed) | C35: m³ | D35: 12 | E35: 25 | F35: =IFERROR(IF(ISNUMBER(D35),D35*E35,"-"),"") -> 300
B36: Reinstatement of Cable Percussive Borehole and Dynamic Sample Borehole
A37: B22 | B37: Reinstatement of gravel hardstanding | C37: m² | D37: Included in B1.1 & B1.2 | E37: =IF(ISNUMBER(D37),"","N/A") -> N/A | F37: =IFERROR(IF(ISNUMBER(D37),D37*E37,"-"),"") -> -
A38: B23 | B38: Reinstatement of asphalt / bituminous pavement | C38: m² | D38: Included in D53 | E38: =IF(ISNUMBER(D38),"","N/A") -> N/A | F38: =IFERROR(IF(ISNUMBER(D38),D38*E38,"-"),"") -> -
A39: B24 | B39: Reinstatement of grass areas | C39: m² | D39: Included in B1.1 & B1.2 | E39: =IF(ISNUMBER(D39),"","N/A") -> N/A | F39: =IFERROR(IF(ISNUMBER(D39),D39*E39,"-"),"") -> -
A40: B25 | B40: Provision of stock proof fencing to borehole or dynamic sample work area | C40: nr | D40: Not Required | E40: =IF(ISNUMBER(D40),"","N/A") -> N/A | F40: =IFERROR(IF(ISNUMBER(D40),D40*E40,"-"),"") -> -
A41: B26 | B41: Disposal of excess or surplus inert arisings from cable percussion boring or dynamic sampling (where standpipe or piezometer is not installed) | C41: m³ | D41: Included in B1 to B1.2.2 | E41: =IF(ISNUMBER(D41),"","N/A") -> N/A | F41: =IFERROR(IF(ISNUMBER(D41),D41*E41,"-"),"") -> -
...

Sheet Section C
A2: Number | B2: Item description | C2: Unit | D2: Quantity | E2: Rate | F2: Amount
B3: Non-Track Works | E3: € | F3: €
A4: C | B4: Rotary drilling
B5: Hand augering
A6: C1 | B6: Bring hand auger equipment to the position of each exploratory hole | C6: nr | D6: Not Required | E6: =IF(ISNUMBER(D6),"","N/A") -> N/A | F6: =IFERROR(IF(ISNUMBER(D6),D6*E6,"-"),"") -> -
A7: C2 | B7: Bore with hand auger from existing ground level to 2m depth | C7: m | D7: Not Required | E7: =IF(ISNUMBER(D7),"","N/A") -> N/A | F7: =IFERROR(IF(ISNUMBER(D7),D7*E7,"-"),"") -> -
A8: C3 | B8: As Item C2 but between 2 and 4m depth | C8: m | D8: Not Required | E8: =IF(ISNUMBER(D8),"","N/A") -> N/A | F8: =IFERROR(IF(ISNUMBER(D8),D8*E8,"-"),"") -> -
A9: C4 | B9: Standing time for hand auger equipment and crew | C9: h | D9: Not Required | E9: =IF(ISNUMBER(D9),"","N/A") -> N/A | F9: =IFERROR(IF(ISNUMBER(D9),D9*E9,"-"),"") -> -
A10: C5 | B10: Provision of hand augering equipment and crew for augering as directed by the Investigation Supervisor maximum depth 4m | C10: day | D10: Not Required | E10: =IF(ISNUMBER(D10),"","N/A") -> N/A | F10: =IFERROR(IF(ISNUMBER(D10),D10*E10,"-"),"") -> -
A11: C6 | B11: Backfill hand auger hole with cement/bentonite grout or bentonite pellets | C11: m | D11: Not Required | E11: =IF(ISNUMBER(D11),"","N/A") -> N/A | F11: =IFERROR(IF(ISNUMBER(D11),D11*E11,"-"),"") -> -
F12: =IFERROR(IF(ISNUMBER(D12),D12*E12,"-"),"") -> -
B13: Continuous flight and hollow-stem flight augering | F13: =IFERROR(IF(ISNUMBER(D13),D13*E13,"-"),"") -> -
A14: C7 | B14: Move mechanical augering plant and equipment to the site of each exploratory hole and set up. | C14: nr | D14: Not Required | E14: =IF(ISNUMBER(D14),"","N/A") -> N/A | F14: =IFERROR(IF(ISNUMBER(D14),D14*E14,"-"),"") -> -
A15: C7.1 | B15: Hand digging and CAT scan at rotary drillhole location to confirm absence of utility ducts ( maximum depth of 1.2m or lesser if ground is assessed as potentially unstable). | C15: nr | D15: Not Required | E15: =IF(ISNUMBER(D15),"","N/A") -> N/A | F15: =IFERROR(IF(ISNUMBER(D15),D15*E15,"-"),"") -> -
A16: C8 | B16: Extra over Item C7 for setting up on a slope of gradient greater than 20% | C16: nr | D16: Not Required | E16: =IF(ISNUMBER(D16),"","N/A") -> N/A | F16: =IFERROR(IF(ISNUMBER(D16),D16*E16,"-"),"") -> -
A17: C9 | B17: Break out obstructions where present when hand digging at auger hole location for Item C7.1. | C17: m3 | D17: Not Required | E17: =IF(ISNUMBER(D17),"","N/A") -> N/A | F17: =IFERROR(IF(ISNUMBER(D17),D17*E17,"-"),"") -> -
A18: C10 | B18: Standing time for rotary auger equipment and crew. | C18: h | D18: Not Required | E18: =IF(ISNUMBER(D18),"","N/A") -> N/A | F18: =IFERROR(IF(ISNUMBER(D18),D18*E18,"-"),"") -> -
A19: C11 | B19: Auger in materials other than hard strata at the specified diameter between existing ground level and 10m depth. | C19: m | D19: Not Required | E19: =IF(ISNUMBER(D19),"","N/A") -> N/A | F19: =IFERROR(IF(ISNUMBER(D19),D19*E19,"-"),"") -> -
A20: C12 | B20: As Item C11 but between 10 and 20m depth. | C20: m | D20: Not Required | E20: =IF(ISNUMBER(D20),"","N/A") -> N/A | F20: =IFERROR(IF(ISNUMBER(D20),D20*E20,"-"),"") -> -
A21: C13 | B21: As Item C11 but between 20 and 30m depth. | C21: m | D21: Not Required | E21: =IF(ISNUMBER(D21),"","N/A") -> N/A | F21: =IFERROR(IF(ISNUMBER(D21),D21*E21,"-"),"") -> -
A22: C14 | B22: Backfill auger hole with cement/bentonite grout or bentonite pellets | C22: m | D22: Not Required | E22: =IF(ISNUMBER(D22),"","N/A") -> N/A | F22: =IFERROR(IF(ISNUMBER(D22),D22*E22,"-"),"") -> -
F23: =IFERROR(IF(ISNUMBER(D23),D23*E23,"-"),"") -> -
B24: Rotary drilling with and without core recovery | F24: =IFERROR(IF(ISNUMBER(D24),D24*E24,"-"),"") -> -
A25: C15 | B25: Move rotary drilling plant and equipment to the site of each exploratory drillhole and set up. | C25: nr | D25: Refer to C15.1.1 to C15.2.2 & C15.3 | E25: =IF(ISNUMBER(D25),"","N/A") -> N/A | F25: =IFERROR(IF(ISNUMBER(D25),D25*E25,"-"),"") -> -
A26: C15.1.1 | B26: Move rotary drilling plant and equipment to the site of each exploratory drillhole, set up, dismantle on completion and reinstate (rotary follow-on) | C26: nr | D26: 47 | E26: 300 | F26: =IFERROR(IF(ISNUMBER(D26),D26*E26,"-"),"") -> 14100
A27: C15.1.2 | B27: Move rotary drilling plant and equipment to the site of each exploratory drillhole over safety barrier or other fence or wall, set up, dismantle on completion and reinstate (rotary follow-on). | C27: nr | D27: Not Required | E27: N/A | F27: =IFERROR(IF(ISNUMBER(D27),D27*E27,"-"),"") -> -
A28: C15.1.2.1 | B28: Move rotary drilling plant and equipment to the site of each exploratory drillhole over safety barrier or other fence or wall, set up, dismantle on completion and reinstate (rotary follow-on) | C28: nr | D28: Not Required | E28: N/A | F28: =IFERROR(IF(ISNUMBER(D28),D28*E28,"-"),"") -> -
A29: C15.2.1 | B29: Move rotary drilling plant and equipment to the site of each exploratory drillhole, set up, dismantle on completion and reinstate (rotary only). | C29: nr | D29: 3 | E29: 300 | F29: =IFERROR(IF(ISNUMBER(D29),D29*E29,"-"),"") -> 900
A30: C15.2.2 | B30: Move rotary drilling plant and equipment to the site of each exploratory drillhole, over safety barrier or other fence or wall, set up, dismantle on completion and reinstate (rotary only). | C30: nr | D30: Not Required | E30: N/A | F30: =IFERROR(IF(ISNUMBER(D30),D30*E30,"-"),"") -> -
A31: B15.2.3 (NT) | B31: Extra Over Item B1.2.1.1 Set up borehole in road area to include erection of traffic management systems (works supervised by Engineer/Geologist with valid CSCS Card for Signing, Lighting and Guarding at Roadworks) | C31: nr | D31: Not Required | E31: N/A | F31: =IFERROR(IF(ISNUMBER(D31),D31*E31,"-"),"") -> -
A32: C15.3 | B32: Hand digging and CAT scan at rotary drillhole location to confirm absence of utility ducts ( maximum depth of 1.2m or lesser if ground is assessed as potentially unstable) for rotary only borehole | C32: nr | D32: Not Required | E32: =IF(ISNUMBER(D32),"","N/A") -> N/A | F32: =IFERROR(IF(ISNUMBER(D32),D32*E32,"-"),"") -> -
A33: C16 | B33: Extra over Item C15 for setting up on a slope of gradient greater than 20%. | C33: nr | D33: Not Required | E33: N/A | F33: =IFERROR(IF(ISNUMBER(D33),D33*E33,"-"),"") -> -
A34: C17 | B34: Extra over Item C15 for setting up drilling plant for inclined drillhole | C34: nr | E34: =IF(ISNUMBER(D35),"","N/A") | F34: =IFERROR(IF(ISNUMBER(D34),D34*E34,"-"),"") -> -
A35: C18 | B35: Break out obstructions where present when hand digging at exploratory hole location for C15.3. | C35: m3 | D35: 3.5 | E35: 50 | F35: =IFERROR(IF(ISNUMBER(D35),D35*E35,"-"),"") -> 175
A36: C19 | B36: Standing time for rotary drilling plant, equipment and crew (excl briefings and setup/dismantling of equipment) | C36: h | D36: 50 | E36: 75 | F36: =IFERROR(IF(ISNUMBER(D36),D36*E36,"-"),"") -> 3750
A37: C20 | B37: Provide aquifer protection measures at a single aquiclude/aquifer boundary in a drillhole | C37: nr | D37: Not Required | E37: =IF(ISNUMBER(D37),"","N/A") -> N/A | F37: =IFERROR(IF(ISNUMBER(D37),D37*E37,"-"),"") -> -
B39: Drilling without cores
A40: C21 | B40: Rotary drill in materials other than hard strata at the specified diameter, from which cores are not required, between existing ground level and 10m depth. | C40: m | D40: Not Required | E40: =IF(ISNUMBER(D40),"","N/A") -> N/A | F40: =IFERROR(IF(ISNUMBER(D40),D40*E40,"-"),"") -> -
A41: C22 | B41: As Item C21 but between 10 and 20m depth. | C41: m | D41: Not Required | E41: =IF(ISNUMBER(D41),"","N/A") -> N/A | F41: =IFERROR(IF(ISNUMBER(D41),D41*E41,"-"),"") -> -
A42: C23 | B42: As Item C21 but between 20 and 30m depth | C42: m | D42: Not Required | E42: =IF(ISNUMBER(D42),"","N/A") -> N/A | F42: =IFERROR(IF(ISNUMBER(D42),D42*E42,"-"),"") -> -
...

Sheet Section C.1
A2: Number | B2: Item description | C2: Unit | D2: Quantity | E2: Rate | F2: Amount
B3: On-Track Works | E3: € | F3: €
A4: C | B4: Rotary drilling
B5: Hand augering
A6: C1 | B6: Bring hand auger equipment to the position of each exploratory hole | C6: nr | D6: Not Required | E6: =IF(ISNUMBER(D6),"","N/A") -> N/A | F6: =IFERROR(IF(ISNUMBER(D6),D6*E6,"-"),"") -> -
A7: C2 | B7: Bore with hand auger from existing ground level to 2m depth | C7: m | D7: Not Required | E7: =IF(ISNUMBER(D7),"","N/A") -> N/A | F7: =IFERROR(IF(ISNUMBER(D7),D7*E7,"-"),"") -> -
A8: C3 | B8: As Item C2 but between 2 and 4m depth | C8: m | D8: Not Required | E8: =IF(ISNUMBER(D8),"","N/A") -> N/A | F8: =IFERROR(IF(ISNUMBER(D8),D8*E8,"-"),"") -> -
A9: C4 | B9: Standing time for hand auger equipment and crew (excl briefings and setup/dismantling of equipment) | C9: h | D9: Not Required | E9: =IF(ISNUMBER(D9),"","N/A") -> N/A | F9: =IFERROR(IF(ISNUMBER(D9),D9*E9,"-"),"") -> -
A10: C5 | B10: Provision of hand augering equipment and crew for augering as directed by the Investigation Supervisor maximum depth 4m | C10: day | D10: Not Required | E10: =IF(ISNUMBER(D10),"","N/A") -> N/A | F10: =IFERROR(IF(ISNUMBER(D10),D10*E10,"-"),"") -> -
A11: C6 | B11: Backfill hand auger hole with cement/bentonite grout or bentonite pellets | C11: m | D11: Not Required | E11: =IF(ISNUMBER(D11),"","N/A") -> N/A | F11: =IFERROR(IF(ISNUMBER(D11),D11*E11,"-"),"") -> -
F12: =IFERROR(IF(ISNUMBER(D12),D12*E12,"-"),"") -> -
B13: Continuous flight and hollow-stem flight augering | F13: =IFERROR(IF(ISNUMBER(D13),D13*E13,"-"),"") -> -
A14: C7 | B14: Move mechanical augering plant and equipment to the site of each exploratory hole and set up. | C14: nr | D14: Not Required | E14: =IF(ISNUMBER(D14),"","N/A") -> N/A | F14: =IFERROR(IF(ISNUMBER(D14),D14*E14,"-"),"") -> -
A15: C7.1 | B15: Hand digging and CAT scan at rotary drillhole location to confirm absence of utility ducts ( maximum depth of 1.2m or lesser if ground is assessed as potentially unstable). | C15: nr | D15: Not Required | E15: =IF(ISNUMBER(D15),"","N/A") -> N/A | F15: =IFERROR(IF(ISNUMBER(D15),D15*E15,"-"),"") -> -
A16: C8 | B16: Extra over Item C7 for setting up on a slope of gradient greater than 20% | C16: nr | D16: Not Required | E16: =IF(ISNUMBER(D16),"","N/A") -> N/A | F16: =IFERROR(IF(ISNUMBER(D16),D16*E16,"-"),"") -> -
A17: C9 | B17: Break out obstructions where present when hand digging at auger hole location for Item C7.1. | C17: m3 | D17: Not Required | E17: =IF(ISNUMBER(D17),"","N/A") -> N/A | F17: =IFERROR(IF(ISNUMBER(D17),D17*E17,"-"),"") -> -
A18: C10 | B18: Standing time for rotary auger equipment and crew. | C18: h | D18: Not Required | E18: =IF(ISNUMBER(D18),"","N/A") -> N/A | F18: =IFERROR(IF(ISNUMBER(D18),D18*E18,"-"),"") -> -
A19: C11 | B19: Auger in materials other than hard strata at the specified diameter between existing ground level and 10m depth. | C19: m | D19: Not Required | E19: =IF(ISNUMBER(D19),"","N/A") -> N/A | F19: =IFERROR(IF(ISNUMBER(D19),D19*E19,"-"),"") -> -
A20: C12 | B20: As Item C11 but between 10 and 20m depth. | C20: m | D20: Not Required | E20: =IF(ISNUMBER(D20),"","N/A") -> N/A | F20: =IFERROR(IF(ISNUMBER(D20),D20*E20,"-"),"") -> -
A21: C13 | B21: As Item C11 but between 20 and 30m depth. | C21: m | D21: Not Required | E21: =IF(ISNUMBER(D21),"","N/A") -> N/A | F21: =IFERROR(IF(ISNUMBER(D21),D21*E21,"-"),"") -> -
A22: C14 | B22: Backfill auger hole with cement/bentonite grout or bentonite pellets | C22: m | D22: Not Required | E22: =IF(ISNUMBER(D22),"","N/A") -> N/A | F22: =IFERROR(IF(ISNUMBER(D22),D22*E22,"-"),"") -> -
F23: =IFERROR(IF(ISNUMBER(D23),D23*E23,"-"),"") -> -
B24: Rotary drilling with and without core recovery | F24: =IFERROR(IF(ISNUMBER(D24),D24*E24,"-"),"") -> -
A25: C15 | B25: Move rotary drilling plant and equipment to the site of each exploratory drillhole and set up. | C25: nr | D25: Refer to C15.1.1 to C15.2.2 & C15.3 | E25: =IF(ISNUMBER(D25),"","N/A") -> N/A | F25: =IFERROR(IF(ISNUMBER(D25),D25*E25,"-"),"") -> -
A26: C15.1.1 | B26: Move rotary drilling plant and equipment to the site of each exploratory drillhole, set up, dismantle on completion and reinstate (rotary follow-on) | C26: nr | D26: 12 | E26: 500 | F26: =IFERROR(IF(ISNUMBER(D26),D26*E26,"-"),"") -> 6000
A27: C15.1.2 | B27: Move rotary drilling plant and equipment to the site of each exploratory drillhole over safety barrier or other fence or wall, set up, dismantle on completion and reinstate (rotary follow-on). | C27: nr | D27: Not Required | E27: =IF(ISNUMBER(D27),"","N/A") -> N/A | F27: =IFERROR(IF(ISNUMBER(D27),D27*E27,"-"),"") -> -
A28: C15.1.2.1 | B28: Move rotary drilling plant and equipment to the site of each exploratory drillhole over safety barrier or other fence or wall, set up, dismantle on completion and reinstate (rotary follow-on) - Night Works/Within Permanent Way | C28: nr | D28: Not Required | E28: =IF(ISNUMBER(D28),"","N/A") -> N/A | F28: =IFERROR(IF(ISNUMBER(D28),D28*E28,"-"),"") -> -
A29: C15.2.1 | B29: Move rotary drilling plant and equipment to the site of each exploratory drillhole, set up, dismantle on completion and reinstate (rotary only). | C29: nr | D29: Not Required | E29: =IF(ISNUMBER(D29),"","N/A") -> N/A | F29: =IFERROR(IF(ISNUMBER(D29),D29*E29,"-"),"") -> -
A30: C15.2.2 | B30: Move rotary drilling plant and equipment to the site of each exploratory drillhole, over safety barrier or other fence or wall, set up, dismantle on completion and reinstate (rotary only). | C30: nr | D30: Not Required | E30: =IF(ISNUMBER(D30),"","N/A") -> N/A | F30: =IFERROR(IF(ISNUMBER(D30),D30*E30,"-"),"") -> -
A31: C15.3 | B31: Hand digging and CAT scan at rotary drillhole location to confirm absence of utility ducts ( maximum depth of 1.2m or lesser if ground is assessed as potentially unstable) for rotary only borehole | C31: nr | D31: Not Required | E31: =IF(ISNUMBER(D31),"","N/A") -> N/A | F31: =IFERROR(IF(ISNUMBER(D31),D31*E31,"-"),"") -> -
A32: C16 | B32: Extra over Item C15 for setting up on a slope of gradient greater than 20%. | C32: nr | D32: Not Required | E32: =IF(ISNUMBER(D32),"","N/A") -> N/A | F32: =IFERROR(IF(ISNUMBER(D32),D32*E32,"-"),"") -> -
A33: C17 | B33: Extra over Item C15 for setting up drilling plant for inclined drillhole | C33: nr | E33: =IF(ISNUMBER(D34),"","N/A") | F33: =IFERROR(IF(ISNUMBER(D34),D34*E33,"-"),"")
A34: C18 | B34: Break out obstructions where present when hand digging at exploratory hole location for C15.3. | C34: m3 | D34: 4 | E34: 25 | F34: =IFERROR(IF(ISNUMBER(D34),D34*E34,"-"),"") -> 100
A35: C19 | B35: Standing time for rotary drilling plant, equipment and crew (excl briefings and setup/dismantling of equipment) | C35: h | D35: 12 | E35: 100 | F35: =IFERROR(IF(ISNUMBER(D35),D35*E35,"-"),"") -> 1200
A36: C20 | B36: Provide aquifer protection measures at a single aquiclude/aquifer boundary in a drillhole | C36: nr | E36: =IF(ISNUMBER(D36),"","N/A") -> N/A | F36: =IFERROR(IF(ISNUMBER(D36),D36*E36,"-"),"") -> -
F37: =IFERROR(IF(ISNUMBER(D37),D37*E37,"-"),"") -> -
B38: Drilling without cores | D38: Not Required | F38: =IFERROR(IF(ISNUMBER(D38),D38*E38,"-"),"") -> -
A39: C21 | B39: Rotary drill in materials other than hard strata at the specified diameter, from which cores are not required, between existing ground level and 10m depth | C39: m | D39: Not Required | E39: =IF(ISNUMBER(D39),"","N/A") -> N/A | F39: =IFERROR(IF(ISNUMBER(D39),D39*E39,"-"),"") -> -
A40: C22 | B40: As Item C21 but between 10 and 20m depth. | C40: m | D40: Not Required | E40: =IF(ISNUMBER(D40),"","N/A") -> N/A | F40: =IFERROR(IF(ISNUMBER(D40),D40*E40,"-"),"") -> -
A41: C23 | B41: As Item C21 but between 20 and 30m depth | C41: m | D41: Not Required | E41: =IF(ISNUMBER(D41),"","N/A") -> N/A | F41: =IFERROR(IF(ISNUMBER(D41),D41*E41,"-"),"") -> -
...

Sheet Section D
A2: Number | B2: Item description | C2: Unit | D2: Quantity | E2: Rate | F2: Amount
B3: On Track Works | E3: € | F3: €
A4: D | B4: Pitting and trenching
B5: Inspection pits Included for each exploratory hole: refer hand digging and CAT scan items at exploratory hole locations
A6: D1 | B6: Excavate inspection pit by hand to 1.2m depth. | C6: nr | D6: Not Required | E6: =IF(ISNUMBER(D6),"","N/A") -> N/A
A7: D2 | B7: Extra over Item D1 for breaking out surface obstructions. | C7: m3 | D7: Not Required | E7: =IF(ISNUMBER(D7),"","N/A") -> N/A
B9: Trial pits and trenches (non paved areas)
A10: D3 | B10: Move equipment to the site of each trial pit or trench dismantle on completion and reinstate. | C10: nr | D10: Not Required | E10: =IF(ISNUMBER(D10),"","N/A") -> N/A
A11: D3.1 | B11: Extra over item D3 for setting to the site of exploratory hole over safety barrier or other fence or wall, set up, dismantle on completion and reinstate. | C11: nr | D11: Not Required | E11: =IF(ISNUMBER(D11),"","N/A") -> N/A
A12: D4 | B12: Extra over Item D3 for setting up on a slope of gradient greater than 20% | C12: nr | D12: Not Required | E12: =IF(ISNUMBER(D12),"","N/A") -> N/A
A13: D5 | B13: Extra over Item D3 for trial pit or trench between 4.5 and 6m depth | C13: nr | D13: Not Required | E13: =IF(ISNUMBER(D13),"","N/A") -> N/A
A14: D6 | B14: Excavate trial pit between existing ground level and 3m depth | C14: m depth | D14: Not Required | E14: =IF(ISNUMBER(D14),"","N/A") -> N/A
A15: D7 | B15: As Item D6 but between 3.0 and 4.5m depth | C15: m | D15: Not Required | E15: =IF(ISNUMBER(D15),"","N/A") -> N/A
A16: D8 | B16: As Item D6 but between 4.5 and 6m depth | C16: m | D16: Not Required | E16: =IF(ISNUMBER(D16),"","N/A") -> N/A
A17: D9 | B17: Excavate trial trench between existing ground level and 3.0m depth | C17: m3 | D17: Not Required | E17: =IF(ISNUMBER(D17),"","N/A") -> N/A
A18: D10 | B18: As Item D9 between 3.0 and 4.5m in depth | C18: m3 | D18: Not Required | E18: =IF(ISNUMBER(D18),"","N/A") -> N/A
A19: D11 | B19: As Item D9 between 4.5 and 6m depth | C19: m3 | D19: Not Required | E19: =IF(ISNUMBER(D19),"","N/A") -> N/A
B21: Trial pits and trenches (paved areas)
A22: D12 | B22: Set up trial pit in road area to include erection of traffic management systems (works supervised by Engineer/ Geologist with valid CSCS Card for signing, lighting and guarding at roadworks) | C22: nr | D22: Not Required | E22: =IF(ISNUMBER(D22),"","N/A") -> N/A
A23: D13 | B23: Set up slit trench in road area to include erection of traffic management systems (works supervised by Engineer/ Geologist with valid CSCS Card for signing, lighting and guarding at roadworks) | C23: nr | D23: Not Required | E23: =IF(ISNUMBER(D23),"","N/A") -> N/A
A24: D14 | B24: Saw cut paved areas in advance of the works | C24: ln m | D24: Not Required | E24: =IF(ISNUMBER(D24),"","N/A") -> N/A
A25: D15 | B25: Breaking out hard material or surface obstructions | C25: m3 | D25: Not Required | E25: =IF(ISNUMBER(D25),"","N/A") -> N/A
A26: D16 | B26: Excavate trial pit in paved areas between ground level and 1.20m depth (works by either hand excavation or hand assisted machine excavation) | C26: m depth | D26: Not Required | E26: =IF(ISNUMBER(D26),"","N/A") -> N/A
A27: D17 | B27: As D16 but depth in range 1.2m to 3.0m | C27: ln m | D27: Not Required | E27: =IF(ISNUMBER(D27),"","N/A") -> N/A
A28: D18 | B28: Excavate slit trench in paved areas between ground level and 1.2m depth (works by either hand excavation or hand assisted machine excavation) | C28: m³ | D28: Not Required | E28: =IF(ISNUMBER(D28),"","N/A") -> N/A
A29: D19 | B29: Excavate slit trench in paved areas between 1.2m to 3.0m depth (works by either hand excavation or hand assisted machine excavation) | C29: m³ | D29: Not Required | E29: =IF(ISNUMBER(D29),"","N/A") -> N/A
A30: D20 | B30: Standing time for excavation plant, equipment and crew for machine dug trial pit or trench (excl briefings and setup/dismantling of equipment) | C30: h | D30: Not Required | E30: =IF(ISNUMBER(D30),"","N/A") -> N/A
B32: Observation pits and trenches
A33: D21 | B33: Move equipment to the site of each observation pit or trench of not greater than 4.5m depth | C33: nr | D33: Not Required | E33: =IF(ISNUMBER(D33),"","N/A") -> N/A
A34: D22 | B34: Extra over Item D21 for setting up on a slope of gradient greater than 20% | C34: nr | D34: Not Required | E34: =IF(ISNUMBER(D34),"","N/A") -> N/A
A35: D23 | B35: Extra over Item D21 for trial pit or trench between 4.5 and 6m depth | C35: nr | D35: Not Required | E35: =IF(ISNUMBER(D35),"","N/A") -> N/A
A36: D24 | B36: Excavate observation pit between existing ground level and 3.0m depth | C36: m | D36: Not Required | E36: =IF(ISNUMBER(D36),"","N/A") -> N/A
A37: D25 | B37: As Item D24 but between 3.0 and 4.5m depth | C37: m | D37: Not Required | E37: =IF(ISNUMBER(D37),"","N/A") -> N/A
A38: D26 | B38: As Item D24 but between 4.5 and 6m depth | C38: m | D38: Not Required | E38: =IF(ISNUMBER(D38),"","N/A") -> N/A
A39: D27 | B39: Extra over Item D24 for hand excavation | C39: m | D39: Not Required | E39: =IF(ISNUMBER(D39),"","N/A") -> N/A
A40: D28 | B40: Excavate observation trench between existing ground level and 3.0m depth | C40: m3 | D40: Not Required | E40: =IF(ISNUMBER(D40),"","N/A") -> N/A
A41: D29 | B41: As Item D28 but between 3.0 and 4.5m depth | C41: m3 | D41: Not Required | E41: =IF(ISNUMBER(D41),"","N/A") -> N/A
A42: D30 | B42: As Item D28 but between 4.5 and 6m depth | C42: m3 | D42: Not Required | E42: =IF(ISNUMBER(D42),"","N/A") -> N/A
A43: D31 | B43: Extra over Item D28 for hand excavation | C43: m3 | D43: Not Required | E43: =IF(ISNUMBER(D43),"","N/A") -> N/A
A44: D32 | B44: Extra over Items D24 to D26 for breaking out hard strata or obstructions | C44: h | D44: Not Required | E44: =IF(ISNUMBER(D44),"","N/A") -> N/A
...

Sheet Section E
A2: Number | B2: Item description | C2: Unit | D2: Quantity | E2: Rate | F2: Amount
E3: € | F3: €
A4: E | B4: Sampling and monitoring during intrusive investigation
B5: Samples for geotechnical purposes
A6: E1 | B6: Jar sample | C6: nr | D6: Not Required | E6: =IF(ISNUMBER(D6),"","N/A") -> N/A | F6: =IFERROR(IF(ISNUMBER(D6),D6*E6,"-"),"") -> -
A7: E2 | B7: Tub sample | C7: nr | D7: 2456 | E7: 5 | F7: =IFERROR(IF(ISNUMBER(D7),D7*E7,"-"),"") -> 12280
A8: E3 | B8: Bulk sample | C8: nr | D8: =D7 -> 2456 | E8: 5 | F8: =IFERROR(IF(ISNUMBER(D8),D8*E8,"-"),"") -> 12280
A9: E4 | B9: Large bulk disturbed sample | C9: nr | D9: 50 | E9: 5 | F9: =IFERROR(IF(ISNUMBER(D9),D9*E9,"-"),"") -> 250
A10: E5 | B10: Open tube- thick walled sample (0 to 10m depth) | C10: nr | D10: 158.2 | E10: 20 | F10: =IFERROR(IF(ISNUMBER(D10),D10*E10,"-"),"") -> 3164
A11: E6 | B11: Open tube- thin walled sample (0 to 10m depth) | C11: nr | D11: 79.1 | E11: 20 | F11: =IFERROR(IF(ISNUMBER(D11),D11*E11,"-"),"") -> 1582
A12: E7 | B12: Piston sample (0 to 10m depth) | C12: nr | D12: 40 | E12: 40 | F12: =IFERROR(IF(ISNUMBER(D12),D12*E12,"-"),"") -> 1600
A13: E8.1 | B13: Extra over rate for item E5 in depth range 10m to 20m | C13: sum | D13: 10 | E13: 5 | F13: =IFERROR(IF(ISNUMBER(D13),D13*E13,"-"),"") -> 50
A14: E8.2 | B14: Extra over rate for item E6 in depth range 10m to 20m | C14: sum | D14: 10 | E14: 5 | F14: =IFERROR(IF(ISNUMBER(D14),D14*E14,"-"),"") -> 50
A15: E8.3 | B15: Extra over rate for item E7 in depth range 20m to 30m | C15: sum | D15: Not Required | E15: 5 | F15: =IFERROR(IF(ISNUMBER(D15),D15*E15,"-"),"") -> -
A16: E9 | B16: Groundwater sample | C16: nr | D16: 50 | E16: 5 | F16: =IFERROR(IF(ISNUMBER(D16),D16*E16,"-"),"") -> 250
A17: E10 | B17: Ground Gas sample | C17: nr | D17: Not Required | E17: =IF(ISNUMBER(D17),"","N/A") -> N/A | F17: =IFERROR(IF(ISNUMBER(D17),D17*E17,"-"),"") -> -
A18: E11 | B18: Cut, prepare and protect core sub-sample | C18: nr | D18: 50 | E18: 5 | F18: =IFERROR(IF(ISNUMBER(D18),D18*E18,"-"),"") -> 250
B19: Samples for environmental / contamination analysis
A20: E12 | B20: Environmental / contamination sample for Suite E | C20: nr | D20: 280 | E20: 5 | F20: =IFERROR(IF(ISNUMBER(D20),D20*E20,"-"),"") -> 1400
A21: E13 | B21: Environmental / contamination sample for Suite F | C21: nr | D21: Not Required | E21: =IF(ISNUMBER(D21),"","N/A") -> N/A | F21: =IFERROR(IF(ISNUMBER(D21),D21*E21,"-"),"") -> -
A22: E14 | B22: Ground gas sample for Suite G | C22: nr | D22: Not Required | E22: N/A | F22: =IFERROR(IF(ISNUMBER(D22),D22*E22,"-"),"") -> -
A23: E15 | B23: Environmental / contamination sample for Suite H | C23: nr | D23: 10 | E23: 5 | F23: =IFERROR(IF(ISNUMBER(D23),D23*E23,"-"),"") -> 50
A24: E16 | B24: Environmental / contamination sample for Suite I | C24: nr | D24: 280 | E24: 5 | F24: =IFERROR(IF(ISNUMBER(D24),D24*E24,"-"),"") -> 1400
A25: E17 | B25: Other specialist environmental / contamination sampling as specified by Investigation Supervisor (Suite J) | C25: nr | D25: Not Required | E25: 5 | F25: =IFERROR(IF(ISNUMBER(D25),D25*E25,"-"),"") -> -
B27: (Note sample rate includes provision of specialist containers)
B28: Total Section E carried to summary: | F28: =IF(SUM(F6:F25)=0,"",SUM(F6:F27)) -> 34606

Sheet Section F
A2: Number | B2: Item description | C2: Unit | D2: Quantity | E2: Rate | F2: Amount
B3: On Track Works | E3: € | F3: €
A4: F | B4: Probing and cone penetration testing
B5: Dynamic probing (DPH)
A6: F1 | B6: Bring dynamic probe (DPH) equipment on-track to the site of each test location | C6: nr | D6: 95 | E6: 500 | F6: =IFERROR(IF(ISNUMBER(D6),D6*E6,"-"),"") -> 47500
A7: F2 | B7: Extra over Item F1 for setting up on a slope of gradient greater than 20% | C7: nr | D7: Not Required | E7: =IF(ISNUMBER(D7),"","N/A") -> N/A | F7: =IFERROR(IF(ISNUMBER(D7),D7*E7,"-"),"") -> -
A8: F3 | B8: Carry out dynamic probe test from existing ground level to 5m depth | C8: m | D8: 475 | E8: 10 | F8: =IFERROR(IF(ISNUMBER(D8),D8*E8,"-"),"") -> 4750
A9: F4 | B9: As Item F3 but between 5 and 10m depth | C9: m | D9: 50 | E9: 20 | F9: =IFERROR(IF(ISNUMBER(D9),D9*E9,"-"),"") -> 1000
A10: F5 | B10: As Item F3 but between 10 and 15m depth | C10: m | D10: Not Required | E10: =IF(ISNUMBER(D10),"","N/A") -> N/A | F10: =IFERROR(IF(ISNUMBER(D10),D10*E10,"-"),"") -> -
A11: F6 | B11: Standing time for dynamic probe test equipment and crew (excl briefings and setup/dismantling of equipment) | C11: h | D11: 10 | E11: 150 | F11: =IFERROR(IF(ISNUMBER(D11),D11*E11,"-"),"") -> 1500
A12: F7 | B12: Provision of dynamic probing equipment and crew for probing as directed by the Investigation Supervisor; maximum depth 10m | C12: day | D12: Not Required | E12: =IF(ISNUMBER(D12),"","N/A") -> N/A | F12: =IFERROR(IF(ISNUMBER(D12),D12*E12,"-"),"") -> -
B13: Cone penetration testing
A14: F8 | B14: Bring static cone penetration test equipment to the site of each test location | C14: nr | D14: Not Required | E14: =IF(ISNUMBER(D14),"","N/A") -> N/A | F14: =IFERROR(IF(ISNUMBER(D14),D14*E14,"-"),"") -> -
A15: F9 | B15: Extra over Item F8 for setting up on a slope of gradient greater than 20% | C15: nr | D15: Not Required | E15: =IF(ISNUMBER(D15),"","N/A") -> N/A | F15: =IFERROR(IF(ISNUMBER(D15),D15*E15,"-"),"") -> -
A16: F10 | B16: Carry out static cone penetration test measuring both cone and sleeve resistance from existing ground level to 10m depth | C16: m | D16: Not Required | E16: =IF(ISNUMBER(D16),"","N/A") -> N/A | F16: =IFERROR(IF(ISNUMBER(D16),D16*E16,"-"),"") -> -
A17: F11 | B17: As Item F10 but between 10 and 20m depth | C17: m | D17: Not Required | E17: =IF(ISNUMBER(D17),"","N/A") -> N/A | F17: =IFERROR(IF(ISNUMBER(D17),D17*E17,"-"),"") -> -
A18: F12 | B18: As Item F10 but between 20 and 30m depth | C18: m | D18: Not Required | E18: =IF(ISNUMBER(D18),"","N/A") -> N/A | F18: =IFERROR(IF(ISNUMBER(D18),D18*E18,"-"),"") -> -
A19: F13 | B19: As Item F10 but between 30 and 40m depth | C19: m | D19: Not Required | E19: =IF(ISNUMBER(D19),"","N/A") -> N/A | F19: =IFERROR(IF(ISNUMBER(D19),D19*E19,"-"),"") -> -
A20: F14 | B20: Extra over Items F10 to F13 for use of piezocone | C20: m | D20: Not Required | E20: =IF(ISNUMBER(D20),"","N/A") -> N/A | F20: =IFERROR(IF(ISNUMBER(D20),D20*E20,"-"),"") -> -
A21: F15 | B21: Extra over Items F10 to F13 for interpretation of CPT/CPTU data | C21: m | D21: Not Required | E21: =IF(ISNUMBER(D21),"","N/A") -> N/A | F21: =IFERROR(IF(ISNUMBER(D21),D21*E21,"-"),"") -> -
A22: F16 | B22: Carry out dissipation test up to 1 hour duration | C22: nr | D22: Not Required | E22: =IF(ISNUMBER(D22),"","N/A") -> N/A | F22: =IFERROR(IF(ISNUMBER(D22),D22*E22,"-"),"") -> -
A23: F17 | B23: Extra over Item F16 for test duration exceeding 1 hour | C23: h | D23: Not Required | E23: =IF(ISNUMBER(D23),"","N/A") -> N/A | F23: =IFERROR(IF(ISNUMBER(D23),D23*E23,"-"),"") -> -
A24: F18 | B24: Standing time for static cone penetration test equipment and crew | C24: h | D24: Not Required | E24: =IF(ISNUMBER(D24),"","N/A") -> N/A | F24: =IFERROR(IF(ISNUMBER(D24),D24*E24,"-"),"") -> -
A25: F19 | B25: Extra over Items F10 to F13 for use of seismic cone | C25: m | D25: Not Required | E25: =IF(ISNUMBER(D25),"","N/A") -> N/A | F25: =IFERROR(IF(ISNUMBER(D25),D25*E25,"-"),"") -> -
... A28: F22 | B28: Standing time for seismic cone test equipment and crew (excl briefings and setup/dismantling of equipment) | C28: h | D28: Not Required | E28: =IF(ISNUMBER(D28),"","N/A") -> N/A | F28: =IFERROR(IF(ISNUMBER(D28),D28*E28,"-"),"") -> -
B29: Total Section F carried to summary: | F29: =IF(SUM(F6:F28)=0,"",SUM(F6:F28)) -> 54750

Sheet Section G
A2: Number | B2: Item description | C2: Unit | D2: Quantity | E2: Rate | F2: Amount
B3: On Track Works | E3: € | F3: €
A4: G | B4: Geophysical testing
B5: Land-based mapping techniques
A6: G1 | B6: Conduct and process Ground Penetrating Radar (GPR) profiles to PAS 128 QL B1P as per the specification | C6: m² | D6: Not Required | E6: =IF(ISNUMBER(D6),"","N/A") -> N/A | F6: =IFERROR(IF(ISNUMBER(D6),D6*E6,"-"),"") -> -
A7: G2 | B7: Conduct and process electro magnetic conductivity (EMC) profiles | C7: ln m | D7: Not Required | E7: =IF(ISNUMBER(D7),"","N/A") -> N/A | F7: =IFERROR(IF(ISNUMBER(D7),D7*E7,"-"),"") -> -
A8: G3 | B8: Conduct and process electrical resistivity tomography (ERT) profiles | C8: ln m | D8: 6150 | E8: 25 | F8: =IFERROR(IF(ISNUMBER(D8),D8*E8,"-"),"") -> 153750
A9: G4 | B9: Conduct and process seismic refraction spreads (P or S wave) | C9: ln m | D9: 6150 | E9: 25 | F9: =IFERROR(IF(ISNUMBER(D9),D9*E9,"-"),"") -> 153750
A10: G5 | B10: Conduct and [rocess surface wave spreads (1D or 2D MASW) | C10: ln m | D10: Not Required | E10: =IF(ISNUMBER(D10),"","N/A") -> N/A | F10: =IFERROR(IF(ISNUMBER(D10),D10*E10,"-"),"") -> -
B11: Borehole geophysical surveying | D11: Not Required | E11: =IF(ISNUMBER(D11),"","N/A") -> N/A | F11: =IFERROR(IF(ISNUMBER(D11),D11*E11,"-"),"") -> -
A12: G6 | B12: Establish down-hole geophysical logging equipment and personnel to the site of each exploratory hole and set up at each location | C12: sum | D12: Not Required | E12: =IF(ISNUMBER(D12),"","N/A") -> N/A | F12: =IFERROR(IF(ISNUMBER(D12),D12*E12,"-"),"") -> -
A13: G7 | B13: Conduct and process down the hole calliper, natural gamma, resistivity, sonic, fluid, temperature, conductivity, and fluid flow logging | C13: m | D13: Not Required | E13: =IF(ISNUMBER(D13),"","N/A") -> N/A | F13: =IFERROR(IF(ISNUMBER(D13),D13*E13,"-"),"") -> -
A14: G8 | B14: Conduct and process cross-hole seismic readings at specified intervals | C14: nr | D14: Not Required | E14: =IF(ISNUMBER(D14),"","N/A") -> N/A | F14: =IFERROR(IF(ISNUMBER(D14),D14*E14,"-"),"") -> -
B15: Marine (overwater) geophysical surveying
A16: G9 | B16: Establish geophysical personnel and field equipment and demobilisation on completion | C16: sum | D16: Not Required | E16: =IF(ISNUMBER(D16),"","N/A") -> N/A | F16: =IFERROR(IF(ISNUMBER(D16),D16*E16,"-"),"") -> -
A17: G10 | B17: conduct and process echo sounding, side scan sonar, magnetic, sub-bottom profile surveying | C17: day | D17: Not Required | E17: =IF(ISNUMBER(D17),"","N/A") -> N/A | F17: =IFERROR(IF(ISNUMBER(D17),D17*E17,"-"),"") -> -
A18: Contract specific additional bill items
C19: day | D19: Not Required | E19: =IF(ISNUMBER(D19),"","N/A") -> N/A | F19: =IFERROR(IF(ISNUMBER(D19),D19*E19,"-"),"") -> -
B20: Total Section G carried to summary: | F20: =IF(SUM(F6:F19)=0,"",SUM(F6:F19)) -> 307500

Sheet Section H
A2: Number | B2: Item description | C2: Unit | D2: Quantity | E2: Rate | F2: Amount
E3: € | F3: €
A4: H | B4: In situ testing
A5: H1.1 | B5: Standard penetration test in percussive borehole, depth range 0 to 10m | C5: nr | D5: 540 | E5: 20 | F5: =IFERROR(IF(ISNUMBER(D5),D5*E5,"-"),"") -> 10800
A6: H1.2 | B6: Standard penetration test in percussive borehole, depth range 10 to 20m | C6: nr | D6: 190 | E6: 25 | F6: =IFERROR(IF(ISNUMBER(D6),D6*E6,"-"),"") -> 4750
A7: H1.3 | B7: Standard penetration test in percussive borehole, depth range 20 to 30m | C7: nr | D7: 55 | E7: 30 | F7: =IFERROR(IF(ISNUMBER(D7),D7*E7,"-"),"") -> 1650
A8: H1.4 | B8: Standard penetration test in percussive borehole, depth range 30 to 40m | C8: nr | D8: Not Required | E8: =IF(ISNUMBER(D8),"","N/A") -> N/A | F8: =IFERROR(IF(ISNUMBER(D8),D8*E8,"-"),"") -> -
A9: H1.5 | B9: Standard penetration test in Dynamic sampling (Window and Windowless Sampling), depth range 0 to 10m | C9: nr | D9: 950 | E9: 20 | F9: =IFERROR(IF(ISNUMBER(D9),D9*E9,"-"),"") -> 19000
A10: H2.1 | B10: Standard penetration test in rotary drillhole, depth range 0 to 10m | C10: nr | D10: 35 | E10: 30 | F10: =IFERROR(IF(ISNUMBER(D10),D10*E10,"-"),"") -> 1050
A11: H2.2 | B11: Standard penetration test in rotary drillhole, depth range 10 to 20m | C11: nr | D11: 280 | E11: 35 | F11: =IFERROR(IF(ISNUMBER(D11),D11*E11,"-"),"") -> 9800
A12: H2.3 | B12: Standard penetration test in rotary drillhole, depth range 20 to 30m | C12: nr | D12: 165 | E12: 40 | F12: =IFERROR(IF(ISNUMBER(D12),D12*E12,"-"),"") -> 6600
A13: H2.4 | B13: Standard penetration test in rotary drillhole, depth range 30 to 40m | C13: nr | D13: Not Required | E13: 50 | F13: =IFERROR(IF(ISNUMBER(D13),D13*E13,"-"),"") -> -
A14: H3 | B14: In-situ density testing | C14: nr | D14: Not Required | E14: =IF(ISNUMBER(D14),"","N/A") -> N/A | F14: =IFERROR(IF(ISNUMBER(D14),D14*E14,"-"),"") -> -
A15: H3.1 | B15: Small pouring cylinder method | C15: nr | D15: Not Required | E15: =IF(ISNUMBER(D15),"","N/A") -> N/A | F15: =IFERROR(IF(ISNUMBER(D15),D15*E15,"-"),"") -> -
A16: H3.2 | B16: Large pouring cylinder method | C16: nr | D16: Not Required | E16: =IF(ISNUMBER(D16),"","N/A") -> N/A | F16: =IFERROR(IF(ISNUMBER(D16),D16*E16,"-"),"") -> -
A17: H3.3 | B17: Water replacement method | C17: nr | D17: Not Required | E17: =IF(ISNUMBER(D17),"","N/A") -> N/A | F17: =IFERROR(IF(ISNUMBER(D17),D17*E17,"-"),"") -> -
A18: H3.4 | B18: Core cutter method | C18: nr | D18: Not Required | E18: =IF(ISNUMBER(D18),"","N/A") -> N/A | F18: =IFERROR(IF(ISNUMBER(D18),D18*E18,"-"),"") -> -
A19: H3.5 | B19: Nuclear gauge method | C19: day | D19: Not Required | E19: =IF(ISNUMBER(D19),"","N/A") -> N/A | F19: =IFERROR(IF(ISNUMBER(D19),D19*E19,"-"),"") -> -
A20: H4 | B20: California Bearing Ratio by plate bearing test by plunger method | C20: nr | D20: Not Required | E20: =IF(ISNUMBER(D20),"","N/A") -> N/A | F20: =IFERROR(IF(ISNUMBER(D20),D20*E20,"-"),"") -> -
A21: H4.1 | B21: California Bearing Ratio by Handheld TRL DCP method | C21: nr | D21: 263 | E21: 25 | F21: =IFERROR(IF(ISNUMBER(D21),D21*E21,"-"),"") -> 6575
A22: H5 | B22: Vane shear strength test in borehole / trial pit / trench | C22: nr | D22: Not Required | E22: =IF(ISNUMBER(D22),"","N/A") -> N/A | F22: =IFERROR(IF(ISNUMBER(D22),D22*E22,"-"),"") -> -
A23: H7 | B23: Hand penetrometer test (set of 3 readings) | C23: nr | D23: Not Required | E23: =IF(ISNUMBER(D23),"","N/A") -> N/A | F23: =IFERROR(IF(ISNUMBER(D23),D23*E23,"-"),"") -> -
